Workbook

Sheet Overview

Sheet Category-Details

Sheet Totals
A3: Total Value | D3: CHANGE DATES HERE
B4: 44331 | C4: 44332 | D4: 44334 | E4: 44336 | F4: 44337 | G4: 44338 | H4: 44339 | I4: 44340 | J4: 44341 | K4: 44342 | L4: 44343 | M4: 44344 | N4: 44345 | O4: 44346 | P4: 44347 | Q4: 44348 | R4: 44349 | S4: 44350 | T4: 44351 | U4: 44352 | V4: 44353 | W4: 44354 | X4: 44355 | Y4: 44356 | Z4: 44357 | AA4: 44358 | AB4: 44359 | AC4: 44360 | AD4: 44361 | AE4: 44362 | AF4: 44363 | AG4: 44364 | AH4: 44365 | AI4: 44366 | AJ4: 44367 | AK4: 44368 | AL4: 44369 | AM4: 44370 | AN4: 44371 | AO4: 44372 | AP4: 44373 | AQ4: 44374 | AR4: 44375 | AS4: 44376 | AT4: 44377 | AU4: 44378 | AV4: 44379 | AW4: 44380 | AX4: 44381 | AY4: 44382 | AZ4: 44383 | BA4: 44384 | BB4: 44385 | BC4: 44386 | BD4: 44387 | BE4: 44388 | BF4: 44389 | BG4: 44390 | BH4: 44391 | BI4: 44392 | BJ4: 44393 | BK4: 44394 | BL4: 44395 | BM4: 44396 | BN4: 44397 | BO4: 44398 | BP4: 44399 | BQ4: 44400 | BR4: 44401 | BS4: 44402 | BT4: 44403 | BU4: 44404 | BV4: 44405 | BW4: 44406 | BX4: 44407 | BY4: 44408
A5: Investments | B5: =Investments!C135 -> 758.47 | C5: =Investments!D135 -> 748.99 | D5: =Investments!E135 -> 775.47 | E5: =Investments!F135 -> 836.84 | F5: =Investments!G135 -> 844.7 | G5: =Investments!H135 -> 993.97 | H5: =Investments!I135 -> 976 | I5: =Investments!J135 -> 1035.16 | ... AA5: =Investments!AB135 -> 1532.28
A6: Knives | B6: =Knives!B10 -> 1973.04 | C6: =Knives!C10 -> 1981.9 | D6: =Knives!D10 -> 2000.11 | E6: =Knives!E10 -> 2012.33 | F6: =Knives!F10 -> 2033.07 | G6: =Knives!G10 -> 1997.22 | H6: =Knives!H10 -> 2013.88 | I6: =Knives!I10 -> 2043.27 | ... AA6: =Knives!AA10 -> 2249.76
A7: AWP | B7: =AWP!B13 -> 195.47 | C7: =AWP!C13 -> 190.54 | D7: =AWP!D13 -> 199.99 | E7: =AWP!E13 -> 193.31 | F7: =AWP!F13 -> 193.19 | G7: =AWP!G13 -> 185.44 | H7: =AWP!H13 -> 198.11 | I7: =AWP!I13 -> 199.2 | ... AA7: =AWP!AA13 -> 199.41
A8: M4A4 | B8: =M4A4!B14 -> 178.95 | C8: =M4A4!C14 -> 175.29 | D8: =M4A4!D14 -> 172.94 | E8: =M4A4!E14 -> 175.82 | F8: =M4A4!F14 -> 175.51 | G8: =M4A4!G14 -> 177.33 | H8: =M4A4!H14 -> 173.11 | I8: =M4A4!I14 -> 171.3 | ... AA8: =M4A4!AA14 -> 173.67
A9: M4A1-S | B9: ='M4A1-S'!B10 -> 76.64 | C9: ='M4A1-S'!C10 -> 74.11 | D9: ='M4A1-S'!D10 -> 72.6 | E9: ='M4A1-S'!E10 -> 70.94 | F9: ='M4A1-S'!F10 -> 74.35 | G9: ='M4A1-S'!G10 -> 72.74 | H9: ='M4A1-S'!H10 -> 70.75 | I9: ='M4A1-S'!I10 -> 72.7 | ... AA9: ='M4A1-S'!AA10 -> 72.04
A10: AK-47 | B10: ='AK47'!B12 -> 385.2 | C10: ='AK47'!C12 -> 398.33 | D10: ='AK47'!D12 -> 408.55 | E10: ='AK47'!E12 -> 396.45 | F10: ='AK47'!F12 -> 401.81 | G10: ='AK47'!G12 -> 389.48 | H10: ='AK47'!H12 -> 389.59 | I10: ='AK47'!I12 -> 395.05 | ... AA10: ='AK47'!AA12 -> 424.18
A11: SMG | B11: =SMG!B20 -> 66.95 | C11: =SMG!C20 -> 67.2 | D11: =SMG!D20 -> 63.86 | E11: =SMG!E20 -> 63.06 | F11: =SMG!F20 -> 66.27 | G11: =SMG!G20 -> 67.62 | H11: =SMG!H20 -> 66.72 | I11: =SMG!I20 -> 66.37 | ... AA11: =SMG!AA20 -> 65.44
A12: Heavy | B12: =Heavy!B16 -> 23.47 | C12: =Heavy!C16 -> 23.17 | D12: =Heavy!D16 -> 22.01 | E12: =Heavy!E16 -> 22.6 | F12: =Heavy!F16 -> 22.22 | G12: =Heavy!G16 -> 22.89 | H12: =Heavy!H16 -> 21.77 | I12: =Heavy!I16 -> 22.73 | ... AA12: =Heavy!AA16 -> 22.91
A13: Pistols | B13: =Pistol!B37 -> 346.62 | C13: =Pistol!C37 -> 340.68 | D13: =Pistol!D37 -> 342.52 | E13: =Pistol!E37 -> 349.93 | F13: =Pistol!F37 -> 345.59 | G13: =Pistol!G37 -> 347.57 | H13: =Pistol!H37 -> 350.87 | I13: =Pistol!I37 -> 349.74 | ... AA13: =Pistol!AA37 -> 399.5
A14: Other Rifles | H14: ='Other Rifles'!H23 -> 102.48 | I14: ='Other Rifles'!I23 -> 98.56 | J14: ='Other Rifles'!J23 -> 101.13 | K14: ='Other Rifles'!K23 -> 103.97 | L14: ='Other Rifles'!L23 -> 106.05 | M14: ='Other Rifles'!M23 -> 105.24 | N14: ='Other Rifles'!N23 -> 103.05 | O14: ='Other Rifles'!O23 -> 105.64 | ... AA14: ='Other Rifles'!AA23 -> 106.53
B15: =SUM(B5:B14) -> 4004.81 | C15: =SUM(C5:C14) -> 4000.21 | D15: =SUM(D5:D14) -> 4058.05 | E15: =SUM(E5:E14) -> 4121.28 | F15: =SUM(F5:F14) -> 4156.71 | G15: =SUM(G5:G14) -> 4254.26 | H15: =SUM(H5:H14) -> 4363.28 | I15: =SUM(I5:I14) -> 4454.08 | ... AA15: =SUM(AA5:AA14) -> 5245.72
A17: Total Sale Value
B18: =B4 -> 44331 | C18: =C4 -> 44332 | D18: =D4 -> 44334 | E18: =E4 -> 44336 | F18: =F4 -> 44337 | G18: =G4 -> 44338 | H18: =H4 -> 44339 | I18: =I4 -> 44340 | ... BY18: =BY4 -> 44408
A19: Investments | B19: =Investments!C181 -> 525.4 | C19: =Investments!D181 -> 518.91 | D19: =Investments!E181 -> 537.07 | E19: =Investments!F181 -> 582.99 | F19: =Investments!G181 -> 589.27 | G19: =Investments!H181 -> 691.93 | H19: =Investments!I181 -> 672.61 | I19: =Investments!J181 -> 719.01 | ... AA19: =Investments!AB181 -> 1100.54
A20: Knives | B20: =Knives!B25 -> 1341.61 | C20: =Knives!C25 -> 1347.64 | D20: =Knives!D25 -> 1360.04 | E20: =Knives!E25 -> 1368.34 | F20: =Knives!F25 -> 1382.44 | G20: =Knives!G25 -> 1358.07 | H20: =Knives!H25 -> 1369.4 | I20: =Knives!I25 -> 1389.4 | ... AA20: =Knives!AA25 -> 1529.8
A21: AWP | B21: =AWP!B30 -> 132.84 | C21: =AWP!C30 -> 129.48 | D21: =AWP!D30 -> 135.92 | E21: =AWP!E30 -> 131.34 | F21: =AWP!F30 -> 131.3 | G21: =AWP!G30 -> 126.01 | H21: =AWP!H30 -> 134.62 | I21: =AWP!I30 -> 135.38 | ... AA21: =AWP!AA30 -> 135.51
A22: M4A4 | B22: =M4A4!B31 -> 121.59 | C22: =M4A4!C31 -> 119.11 | D22: =M4A4!D31 -> 117.54 | E22: =M4A4!E31 -> 119.46 | F22: =M4A4!F31 -> 119.24 | G22: =M4A4!G31 -> 120.49 | H22: =M4A4!H31 -> 117.64 | I22: =M4A4!I31 -> 116.39 | ... AA22: =M4A4!AA31 -> 118
A23: M4A1-S | B23: ='M4A1-S'!B25 -> 52.08 | C23: ='M4A1-S'!C25 -> 50.35 | D23: ='M4A1-S'!D25 -> 49.31 | E23: ='M4A1-S'!E25 -> 48.19 | F23: ='M4A1-S'!F25 -> 50.5 | G23: ='M4A1-S'!G25 -> 49.41 | H23: ='M4A1-S'!H25 -> 48.07 | I23: ='M4A1-S'!I25 -> 49.4 | ... AA23: ='M4A1-S'!AA25 -> 48.94
A24: AK-47 | B24: ='AK47'!B27 -> 261.87 | C24: ='AK47'!C27 -> 270.81 | D24: ='AK47'!D27 -> 277.74 | E24: ='AK47'!E27 -> 269.5 | F24: ='AK47'!F27 -> 273.16 | G24: ='AK47'!G27 -> 264.77 | H24: ='AK47'!H27 -> 264.83 | I24: ='AK47'!I27 -> 268.57 | ... AA24: ='AK47'!AA27 -> 288.37
A25: SMG | B25: =SMG!B43 -> 45.37 | C25: =SMG!C43 -> 45.5 | D25: =SMG!D43 -> 43.26 | E25: =SMG!E43 -> 42.75 | F25: =SMG!F43 -> 44.91 | G25: =SMG!G43 -> 45.81 | H25: =SMG!H43 -> 45.22 | I25: =SMG!I43 -> 45 | ... AA25: =SMG!AA43 -> 44.36
A26: Heavy | B26: =Heavy!B35 -> 15.85 | C26: =Heavy!C35 -> 15.66 | D26: =Heavy!D35 -> 14.86 | E26: =Heavy!E35 -> 15.25 | F26: =Heavy!F35 -> 15.02 | G26: =Heavy!G35 -> 15.45 | H26: =Heavy!H35 -> 14.7 | I26: =Heavy!I35 -> 15.33 | ... AA26: =Heavy!AA35 -> 15.48
A27: Pistols | B27: =Pistol!B77 -> 235.34 | C27: =Pistol!C77 -> 231.31 | D27: =Pistol!D77 -> 232.52 | E27: =Pistol!E77 -> 237.59 | F27: =Pistol!F77 -> 234.61 | G27: =Pistol!G77 -> 235.99 | H27: =Pistol!H77 -> 238.27 | I27: =Pistol!I77 -> 237.48 | ... AA27: =Pistol!AA77 -> 271.34
A28: Other Rifles | H28: ='Other Rifles'!H48 -> 69.47 | I28: ='Other Rifles'!I48 -> 66.84 | J28: ='Other Rifles'!J48 -> 68.57 | K28: ='Other Rifles'!K48 -> 70.5 | L28: ='Other Rifles'!L48 -> 71.9 | M28: ='Other Rifles'!M48 -> 71.35 | N28: ='Other Rifles'!N48 -> 69.9 | O28: ='Other Rifles'!O48 -> 71.65 | ... AA28: ='Other Rifles'!AA48 -> 72.29
B29: =SUM(B19:B28) -> 2731.95 | C29: =SUM(C19:C28) -> 2728.77 | D29: =SUM(D19:D28) -> 2768.26 | E29: =SUM(E19:E28) -> 2815.41 | F29: =SUM(F19:F28) -> 2840.45 | G29: =SUM(G19:G28) -> 2907.93 | H29: =SUM(H19:H28) -> 2974.83 | I29: =SUM(I19:I28) -> 3042.8 | ... AA29: =SUM(AA19:AA28) -> 3624.63
B33: =B4 -> 44331 | C33: =C4 -> 44332 | D33: =D4 -> 44334 | E33: =E4 -> 44336 | F33: =F4 -> 44337 | G33: =G4 -> 44338 | H33: =H4 -> 44339 | I33: =I4 -> 44340 | ... BY33: =BY4 -> 44408
A34: Raw Value | B34: =B15 -> 4004.81 | C34: =C15 -> 4000.21 | D34: =D15 -> 4058.05 | E34: =E15 -> 4121.28 | F34: =F15 -> 4156.71 | G34: =G15 -> 4254.26 | H34: =H15 -> 4363.28 | I34: =I15 -> 4454.08 | ... AA34: =AA15 -> 5245.72
A35: Sale-Revenue | B35: =B29 -> 2731.95 | C35: =C29 -> 2728.77 | D35: =D29 -> 2768.26 | E35: =E29 -> 2815.41 | F35: =F29 -> 2840.45 | G35: =G29 -> 2907.93 | H35: =H29 -> 2974.83 | I35: =I29 -> 3042.8 | ... AA35: =AA29 -> 3624.63

Sheet Investments
A1: Investments
A2: Amount | B2: Name
C3: =Totals!B4 -> 44331 | D3: =Totals!C4 -> 44332 | E3: =Totals!D4 -> 44334 | F3: =Totals!E4 -> 44336 | G3: =Totals!F4 -> 44337 | H3: =Totals!G4 -> 44338 | I3: =Totals!H4 -> 44339 | J3: =Totals!I4 -> 44340 | ... BZ3: =Totals!BY4 -> 44408
A4: 1000 | B4: Danger Zone Cases | C4: 0.07 | D4: 0.07 | E4: 0.07 | F4: 0.07 | G4: 0.07 | H4: 0.07 | I4: 0.07 | J4: 0.07 | K4: 0.07 | L4: 0.07 | M4: 0.07 | N4: 0.06 | O4: 0.06 | P4: 0.07 | Q4: 0.07 | R4: 0.07 | S4: 0.07 | T4: 0.07 | U4: 0.08 | V4: 0.09 | W4: 0.08 | X4: 0.09 | Y4: 0.09 | Z4: 0.08 | AA4: 0.09 | AB4: 0.09
A5: 2000 | B5: Horizon Cases | C5: 0.07 | D5: 0.07 | E5: 0.07 | F5: 0.07 | G5: 0.07 | H5: 0.07 | I5: 0.07 | J5: 0.07 | K5: 0.07 | L5: 0.07 | M5: 0.07 | N5: 0.07 | O5: 0.07 | P5: 0.07 | Q5: 0.07 | R5: 0.07 | S5: 0.07 | T5: 0.07 | U5: 0.12 | V5: 0.14 | W5: 0.11 | X5: 0.12 | Y5: 0.12 | Z5: 0.12 | AA5: 0.12 | AB5: 0.13
A6: 2000 | B6: Prisma 2 Cases | C6: 0.05 | D6: 0.05 | E6: 0.05 | F6: 0.06 | G6: 0.06 | H6: 0.06 | I6: 0.05 | J6: 0.06 | K6: 0.06 | L6: 0.06 | M6: 0.06 | N6: 0.06 | O6: 0.06 | P6: 0.05 | Q6: 0.06 | R6: 0.06 | S6: 0.06 | T6: 0.06 | U6: 0.07 | V6: 0.08 | W6: 0.07 | X6: 0.08 | Y6: 0.08 | Z6: 0.08 | AA6: 0.08 | AB6: 0.08
A7: 215 | B7: CS20-Cases | C7: 0.08 | D7: 0.08 | E7: 0.08 | F7: 0.08 | G7: 0.08 | H7: 0.08 | I7: 0.08 | J7: 0.08 | K7: 0.08 | L7: 0.08 | M7: 0.08 | N7: 0.08 | O7: 0.08 | P7: 0.08 | Q7: 0.08 | R7: 0.08 | S7: 0.08 | T7: 0.08 | U7: 0.16 | V7: 0.21 | W7: 0.17 | X7: 0.18 | Y7: 0.18 | Z7: 0.2 | AA7: 0.23 | AB7: 0.24
A8: 150 | B8: Fracture Cases | C8: 0.35 | D8: 0.35 | E8: 0.35 | F8: 0.31 | G8: 0.3 | H8: 0.34 | I8: 0.3 | J8: 0.3 | K8: 0.31 | L8: 0.3 | M8: 0.31 | N8: 0.3 | O8: 0.32 | P8: 0.32 | Q8: 0.34 | R8: 0.3 | S8: 0.32 | T8: 0.3 | U8: 0.35 | V8: 0.35 | W8: 0.32 | X8: 0.32 | Y8: 0.3 | Z8: 0.31 | AA8: 0.3 | AB8: 0.3
A12: Ingame Drops
A13: Amount | B13: Name
C14: =C3 -> 44331 | D14: =D3 -> 44332 | E14: =E3 -> 44334 | F14: =F3 -> 44336 | G14: =G3 -> 44337 | H14: =H3 -> 44338 | I14: =I3 -> 44339 | J14: =J3 -> 44340 | ... BZ14: =BZ3 -> 44408
A15: 5 | B15: Prisma 2 Case | C15: 0.05 | D15: 0.05 | E15: 0.05 | F15: 0.06 | G15: 0.06 | H15: 0.06 | I15: 0.05 | J15: 0.06 | K15: 0.06 | L15: 0.06 | M15: 0.06 | N15: 0.06 | O15: 0.06 | P15: 0.05 | Q15: 0.06 | R15: 0.06 | S15: 0.06 | T15: 0.06 | U15: 0.07 | V15: 0.08 | W15: 0.07 | X15: 0.08 | Y15: 0.08 | Z15: 0.08 | AA15: 0.08 | AB15: 0.08
A16: 16 | B16: Prisma Case | C16: 0.07 | D16: 0.07 | E16: 0.07 | F16: 0.07 | G16: 0.07 | H16: 0.07 | I16: 0.07 | J16: 0.07 | K16: 0.07 | L16: 0.07 | M16: 0.07 | N16: 0.07 | O16: 0.07 | P16: 0.07 | Q16: 0.07 | R16: 0.08 | S16: 0.08 | T16: 0.08 | U16: 0.09 | V16: 0.12 | W16: 0.1 | X16: 0.1 | Y16: 0.09 | Z16: 0.1 | AA16: 0.09 | AB16: 0.09
A17: 4 | B17: Fracture Case | C17: 0.35 | D17: 0.35 | E17: 0.35 | F17: 0.31 | G17: 0.3 | H17: 0.34 | I17: 0.3 | J17: 0.3 | K17: 0.31 | L17: 0.3 | M17: 0.31 | N17: 0.3 | O17: 0.32 | P17: 0.32 | Q17: 0.34 | R17: 0.3 | S17: 0.32 | T17: 0.3 | U17: 0.35 | V17: 0.35 | W17: 0.32 | X17: 0.32 | Y17: 0.3 | Z17: 0.31 | AA17: 0.3 | AB17: 0.3
A18: 16 | B18: Danger Zone Case | C18: 0.07 | D18: 0.07 | E18: 0.07 | F18: 0.07 | G18: 0.07 | H18: 0.07 | I18: 0.07 | J18: 0.07 | K18: 0.07 | L18: 0.07 | M18: 0.07 | N18: 0.06 | O18: 0.06 | P18: 0.07 | Q18: 0.07 | R18: 0.07 | S18: 0.07 | T18: 0.07 | U18: 0.08 | V18: 0.09 | W18: 0.08 | X18: 0.09 | Y18: 0.09 | Z18: 0.08 | AA18: 0.09 | AB18: 0.09
A19: 19 | B19: Clutch Case | C19: 0.21 | D19: 0.21 | E19: 0.21 | F19: 0.21 | G19: 0.21 | H19: 0.21 | I19: 0.21 | J19: 0.21 | K19: 0.21 | L19: 0.2 | M19: 0.2 | N19: 0.21 | O19: 0.21 | P19: 0.24 | Q19: 0.24 | R19: 0.24 | S19: 0.26 | T19: 0.27 | U19: 0.34 | V19: 0.43 | W19: 0.3 | X19: 0.31 | Y19: 0.34 | Z19: 0.31 | AA19: 0.36 | AB19: 0.38
A20: 6 | B20: CS20 Case | C20: 0.08 | D20: 0.08 | E20: 0.08 | F20: 0.08 | G20: 0.08 | H20: 0.08 | I20: 0.08 | J20: 0.08 | K20: 0.08 | L20: 0.08 | M20: 0.08 | N20: 0.08 | O20: 0.08 | P20: 0.08 | Q20: 0.08 | R20: 0.08 | S20: 0.08 | T20: 0.08 | U20: 0.16 | V20: 0.21 | W20: 0.17 | X20: 0.18 | Y20: 0.18 | Z20: 0.2 | AA20: 0.23 | AB20: 0.24
A21: 7 | B21: Shattered Web Case | C21: 1.12 | D21: 1.12 | E21: 1.2 | F21: 1.24 | G21: 1.21 | H21: 1.26 | I21: 1.27 | J21: 1.31 | K21: 1.53 | L21: 1.45 | M21: 1.51 | N21: 1.49 | O21: 1.41 | P21: 1.39 | Q21: 1.31 | R21: 1.34 | S21: 1.31 | T21: 1.35 | U21: 1.35 | V21: 1.35 | W21: 1.46 | X21: 1.46 | Y21: 1.42 | Z21: 1.49 | AA21: 1.33 | AB21: 1.41
A22: 4 | B22: Spectrum 2 Case | C22: 0.17 | D22: 0.17 | E22: 0.19 | F22: 0.19 | G22: 0.17 | H22: 0.18 | I22: 0.18 | J22: 0.17 | K22: 0.17 | L22: 0.18 | M22: 0.18 | N22: 0.19 | O22: 0.2 | P22: 0.21 | Q22: 0.21 | R22: 0.24 | S22: 0.24 | T22: 0.23 | U22: 0.34 | V22: 0.39 | W22: 0.34 | X22: 0.36 | Y22: 0.36 | Z22: 0.37 | AA22: 0.36 | AB22: 0.38
A23: 4 | B23: Horizon Case | C23: 0.07 | D23: 0.07 | E23: 0.07 | F23: 0.07 | G23: 0.07 | H23: 0.07 | I23: 0.07 | J23: 0.07 | K23: 0.07 | L23: 0.07 | M23: 0.07 | N23: 0.07 | O23: 0.07 | P23: 0.07 | Q23: 0.07 | R23: 0.07 | S23: 0.07 | T23: 0.07 | U23: 0.12 | V23: 0.14 | W23: 0.11 | X23: 0.12 | Y23: 0.12 | Z23: 0.12 | AA23: 0.12 | AB23: 0.13
A24: 1 | B24: Spectrum Case | C24: 0.59 | D24: 0.58 | E24: 0.55 | F24: 0.53 | G24: 0.6 | H24: 0.6 | I24: 0.6 | J24: 0.61 | K24: 0.58 | L24: 0.61 | M24: 0.58 | N24: 0.62 | O24: 0.65 | P24: 0.66 | Q24: 0.65 | R24: 0.66 | S24: 0.64 | T24: 0.64 | U24: 0.72 | V24: 0.86 | W24: 0.73 | X24: 0.64 | Y24: 0.65 | Z24: 0.74 | AA24: 0.71 | AB24: 0.72
A28: Weapon Skin Inventory
A29: Amount | B29: Name
C30: =C14 -> 44331 | D30: =D14 -> 44332 | E30: =E14 -> 44334 | F30: =F14 -> 44336 | G30: =G14 -> 44337 | H30: =H14 -> 44338 | I30: =I14 -> 44339 | J30: =J14 -> 44340 | ... BZ30: =BZ14 -> 44408
A31: 48 | B31: M4A4 Dark Blossom FN | C31: 3.88 | D31: 3.68 | E31: 3.95 | F31: 4.45 | G31: 4.41 | H31: 5.99 | I31: 5.89 | J31: 6.51 | K31: 6.53 | L31: 7.68 | M31: 8.69 | N31: 8.59 | O31: 7.72 | P31: 7.24 | Q31: 6.86 | R31: 7.73 | S31: 8.58 | T31: 9.05 | U31: 9.33 | V31: 10.95 | W31: 9.56 | X31: 9.48 | Y31: 9.57 | Z31: 9.52 | AA31: 9.51 | AB31: 9.25
A32: 10 | B32: M4A4 Dark Blossom MW | C32: 3.48 | D32: 3.52 | E32: 3.93 | F32: 4.28 | G32: 4.5 | H32: 5.8 | I32: 5.7 | J32: 6.3 | K32: 6.26 | L32: 7.32 | M32: 7.99 | N32: 8.44 | O32: 8.14 | P32: 7.19 | Q32: 6.37 | R32: 6.86 | S32: 8.05 | T32: 8.85 | U32: 9.02 | V32: 9.75 | W32: 9.83 | X32: 8.81 | Y32: 9.03 | Z32: 9.28 | AA32: 9.13 | AB32: 9.23
A33: 6 | B33: XM1014 Banana Leaf MW | C33: 3.55 | D33: 3.44 | E33: 3.96 | F33: 4.43 | G33: 4.51 | H33: 6.71 | I33: 7.22 | J33: 6.07 | K33: 6.58 | L33: 7.49 | M33: 8.13 | N33: 8.51 | O33: 7.87 | P33: 7.56 | Q33: 6.94 | R33: 7.04 | S33: 7.9 | T33: 9.69 | U33: 9.72 | V33: 11.1 | W33: 9.54 | X33: 9.28 | Y33: 9.11 | Z33: 9.44 | AA33: 9.55 | AB33: 9.57
A34: 10 | B34: XM1014 Banana Leaf FN | C34: 4.14 | D34: 3.9 | E34: 3.9 | F34: 4.72 | G34: 5.1 | H34: 5.9 | I34: 6.56 | J34: 7.13 | K34: 7.19 | L34: 7.96 | M34: 8.54 | N34: 8.32 | O34: 8.2 | P34: 7.6 | Q34: 7.55 | R34: 7.85 | S34: 8.78 | T34: 9.06 | U34: 10.08 | V34: 10.84 | W34: 10.4 | X34: 9.62 | Y34: 10.18 | Z34: 10.04 | AA34: 10.04 | AB34: 9.82
A35: 10 | B35: Tec-9 Rust Leaf MW | C35: 3.57 | D35: 3.56 | E35: 3.84 | F35: 4.29 | G35: 4.4 | H35: 5.67 | I35: 5.87 | J35: 6.3 | K35: 6.23 | L35: 7.42 | M35: 7.86 | N35: 8.21 | O35: 8.05 | P35: 7.96 | Q35: 7.24 | R35: 6.93 | S35: 7.97 | T35: 8.89 | U35: 9.69 | V35: 11.46 | W35: 9.69 | X35: 9.33 | Y35: 9.28 | Z35: 9.34 | AA35: 9.26 | AB35: 9.15
A36: 7 | B36: Tec-9 Rust Leaf FN | C36: 3.49 | D36: 3.76 | E36: 4.03 | F36: 4.41 | G36: 4.76 | H36: 6.12 | I36: 6.58 | J36: 6.58 | K36: 6.57 | L36: 7.69 | M36: 8.53 | N36: 8.46 | O36: 8.48 | P36: 7.97 | Q36: 7.9 | R36: 7.89 | S36: 8.59 | T36: 9.37 | U36: 11.08 | V36: 10.94 | W36: 9.91 | X36: 9.39 | Y36: 9.71 | Z36: 9.38 | AA36: 9.84 | AB36: 9.82
A37: 5 | B37: P90 Sunset Lily FN | C37: 3.5 | D37: 3.7 | E37: 3.9 | F37: 4.2 | G37: 4.5 | H37: 6.6 | I37: 6.41 | J37: 6.41 | K37: 6.56 | L37: 8.83 | M37: 9.61 | N37: 9.02 | O37: 8.69 | P37: 8.19 | Q37: 7.37 | R37: 7.63 | S37: 8.23 | T37: 9.16 | U37: 9.89 | V37: 11.16 | W37: 11.16 | X37: 10.03 | Y37: 9.81 | Z37: 9.52 | AA37: 9.67 | AB37: 9.61
A48: Sale-Value
A51: Investments
A52: Amount | B52: Name
C53: =C30 -> 44331 | D53: =D30 -> 44332 | E53: =E30 -> 44334 | F53: =F30 -> 44336 | G53: =G30 -> 44337 | H53: =H30 -> 44338 | I53: =I30 -> 44339 | J53: =J30 -> 44340 | ... BZ53: =BZ30 -> 44408
A54: 1000 | B54: Danger Zone Cases | C54: =C4-ROUNDUP(C4*0.1,2)-ROUNDUP(C4*0.05,2) -> 0.05 | D54: =D4-ROUNDUP(D4*0.1,2)-ROUNDUP(D4*0.05,2) -> 0.05 | E54: =E4-ROUNDUP(E4*0.1,2)-ROUNDUP(E4*0.05,2) -> 0.05 | F54: =F4-ROUNDUP(F4*0.1,2)-ROUNDUP(F4*0.05,2) -> 0.05 | G54: =G4-ROUNDUP(G4*0.1,2)-ROUNDUP(G4*0.05,2) -> 0.05 | H54: =H4-ROUNDUP(H4*0.1,2)-ROUNDUP(H4*0.05,2) -> 0.05 | I54: =I4-ROUNDUP(I4*0.1,2)-ROUNDUP(I4*0.05,2) -> 0.05 | J54: =J4-ROUNDUP(J4*0.1,2)-ROUNDUP(J4*0.05,2) -> 0.05 | ... BZ54: =BZ4-ROUNDUP(BZ4*0.1,2)-ROUNDUP(BZ4*0.05,2) -> 0
A55: 2000 | B55: Horizon Cases | C55: =C5-ROUNDUP(C5*0.1,2)-ROUNDUP(C5*0.05,2) -> 0.05 | D55: =D5-ROUNDUP(D5*0.1,2)-ROUNDUP(D5*0.05,2) -> 0.05 | E55: =E5-ROUNDUP(E5*0.1,2)-ROUNDUP(E5*0.05,2) -> 0.05 | F55: =F5-ROUNDUP(F5*0.1,2)-ROUNDUP(F5*0.05,2) -> 0.05 | G55: =G5-ROUNDUP(G5*0.1,2)-ROUNDUP(G5*0.05,2) -> 0.05 | H55: =H5-ROUNDUP(H5*0.1,2)-ROUNDUP(H5*0.05,2) -> 0.05 | I55: =I5-ROUNDUP(I5*0.1,2)-ROUNDUP(I5*0.05,2) -> 0.05 | J55: =J5-ROUNDUP(J5*0.1,2)-ROUNDUP(J5*0.05,2) -> 0.05 | ... BZ55: =BZ5-ROUNDUP(BZ5*0.1,2)-ROUNDUP(BZ5*0.05,2) -> 0
A56: 2000 | B56: Prisma 2 Cases | C56: =C6-ROUNDUP(C6*0.1,2)-ROUNDUP(C6*0.05,2) -> 0.03 | D56: =D6-ROUNDUP(D6*0.1,2)-ROUNDUP(D6*0.05,2) -> 0.03 | E56: =E6-ROUNDUP(E6*0.1,2)-ROUNDUP(E6*0.05,2) -> 0.03 | F56: =F6-ROUNDUP(F6*0.1,2)-ROUNDUP(F6*0.05,2) -> 0.04 | G56: =G6-ROUNDUP(G6*0.1,2)-ROUNDUP(G6*0.05,2) -> 0.04 | H56: =H6-ROUNDUP(H6*0.1,2)-ROUNDUP(H6*0.05,2) -> 0.04 | I56: =I6-ROUNDUP(I6*0.1,2)-ROUNDUP(I6*0.05,2) -> 0.03 | J56: =J6-ROUNDUP(J6*0.1,2)-ROUNDUP(J6*0.05,2) -> 0.04 | ... BZ56: =BZ6-ROUNDUP(BZ6*0.1,2)-ROUNDUP(BZ6*0.05,2) -> 0
A57: 215 | B57: CS20-Cases | C57: =C7-ROUNDUP(C7*0.1,2)-ROUNDUP(C7*0.05,2) -> 0.06 | D57: =D7-ROUNDUP(D7*0.1,2)-ROUNDUP(D7*0.05,2) -> 0.06 | E57: =E7-ROUNDUP(E7*0.1,2)-ROUNDUP(E7*0.05,2) -> 0.06 | F57: =F7-ROUNDUP(F7*0.1,2)-ROUNDUP(F7*0.05,2) -> 0.06 | G57: =G7-ROUNDUP(G7*0.1,2)-ROUNDUP(G7*0.05,2) -> 0.06 | H57: =H7-ROUNDUP(H7*0.1,2)-ROUNDUP(H7*0.05,2) -> 0.06 | I57: =I7-ROUNDUP(I7*0.1,2)-ROUNDUP(I7*0.05,2) -> 0.06 | J57: =J7-ROUNDUP(J7*0.1,2)-ROUNDUP(J7*0.05,2) -> 0.06 | ... BZ57: =BZ7-ROUNDUP(BZ7*0.1,2)-ROUNDUP(BZ7*0.05,2) -> 0
A58: 150 | B58: Fracture Cases | C58: =C8-ROUNDUP(C8*0.1,2)-ROUNDUP(C8*0.05,2) -> 0.29 | D58: =D8-ROUNDUP(D8*0.1,2)-ROUNDUP(D8*0.05,2) -> 0.29 | E58: =E8-ROUNDUP(E8*0.1,2)-ROUNDUP(E8*0.05,2) -> 0.29 | F58: =F8-ROUNDUP(F8*0.1,2)-ROUNDUP(F8*0.05,2) -> 0.25 | G58: =G8-ROUNDUP(G8*0.1,2)-ROUNDUP(G8*0.05,2) -> 0.25 | H58: =H8-ROUNDUP(H8*0.1,2)-ROUNDUP(H8*0.05,2) -> 0.28 | I58: =I8-ROUNDUP(I8*0.1,2)-ROUNDUP(I8*0.05,2) -> 0.25 | J58: =J8-ROUNDUP(J8*0.1,2)-ROUNDUP(J8*0.05,2) -> 0.25 | ... BZ58: =BZ8-ROUNDUP(BZ8*0.1,2)-ROUNDUP(BZ8*0.05,2) -> 0
...

Sheet Knives
A1: Knives
A3: Name
B4: =Totals!B4 -> 44331 | C4: =Totals!C4 -> 44332 | D4: =Totals!D4 -> 44334 | E4: =Totals!E4 -> 44336 | F4: =Totals!F4 -> 44337 | G4: =Totals!G4 -> 44338 | H4: =Totals!H4 -> 44339 | I4: =Totals!I4 -> 44340 | ... BY4: =Totals!BY4 -> 44408
A5: Bayonet Rust Coat BS | B5: 196.27 | C5: 201.82 | D5: 197 | E5: 196.88 | F5: 207.18 | G5: 209.46 | H5: 201.89 | I5: 202.48 | J5: 196.23 | K5: 204.01 | L5: 206.61 | M5: 209.15 | N5: 207.58 | O5: 207.32 | P5: 202.17 | Q5: 201.3 | R5: 201.79 | S5: 203.29 | T5: 201.2 | U5: 207 | V5: 207.01 | W5: 197.73 | X5: 197.35 | Y5: 177 | Z5: 187.92 | AA5: 200.49
A6: Butterfly Knife Tiger Tooth FN | B6: 1201.6 | C6: 1205.46 | D6: 1261.1 | E6: 1261.06 | F6: 1261.06 | G6: 1230.57 | H6: 1294.36 | I6: 1294.36 | J6: 1290.31 | K6: 1427.45 | L6: 1391 | M6: 1383.65 | N6: 1363.98 | O6: 1354.05 | P6: 1341.3 | Q6: 1341.3 | R6: 1354.94 | S6: 1364.6 | T6: 1349.99 | U6: 1413.09 | V6: 1484.68 | W6: 1478.37 | X6: 1473.65 | Y6: 1480.13 | Z6: 1494.04 | AA6: 1483.36
A7: Flip Knife Freehand FN | B7: 194.62 | C7: 191.6 | D7: 180.11 | E7: 192.42 | F7: 192.42 | G7: 191.29 | H7: 183.02 | I7: 190.84 | J7: 183.2 | K7: 188.79 | L7: 188.98 | M7: 181.09 | N7: 190.1 | O7: 189.75 | P7: 180.74 | Q7: 189.61 | R7: 186.36 | S7: 180.21 | T7: 164.58 | U7: 169.76 | V7: 185.28 | W7: 178.84 | X7: 182.71 | Y7: 183 | Z7: 180.69 | AA7: 181.39
A8: Karambit Ultraviolet FT | B8: 380.55 | C8: 383.02 | D8: 361.9 | E8: 361.97 | F8: 372.41 | G8: 365.9 | H8: 334.61 | I8: 355.59 | J8: 350.79 | K8: 385.29 | L8: 391.15 | M8: 391.41 | N8: 370.36 | O8: 386.6 | P8: 386.45 | Q8: 382.76 | R8: 397.01 | S8: 406.58 | T8: 384.98 | U8: 385.96 | V8: 424.73 | W8: 394.27 | X8: 404.05 | Y8: 403.38 | Z8: 361.27 | AA8: 384.52
B10: =SUM(B5:B8) -> 1973.04 | C10: =SUM(C5:C8) -> 1981.9 | D10: =SUM(D5:D8) -> 2000.11 | E10: =SUM(E5:E8) -> 2012.33 | F10: =SUM(F5:F8) -> 2033.07 | G10: =SUM(G5:G8) -> 1997.22 | H10: =SUM(H5:H8) -> 2013.88 | I10: =SUM(I5:I8) -> 2043.27 | ... BY10: =SUM(BY5:BY8) -> 0
A16: Sale-Value
A18: Name
B19: =B4 -> 44331 | C19: =C4 -> 44332 | D19: =D4 -> 44334 | E19: =E4 -> 44336 | F19: =F4 -> 44337 | G19: =G4 -> 44338 | H19: =H4 -> 44339 | I19: =I4 -> 44340 | ... BY19: =BY4 -> 44408
A20: Bayonet Rust Coat BS | B20: =ROUNDDOWN((B5-ROUNDUP(B5*0.1,2)-ROUNDUP(B5*0.05,2))*0.8,2) -> 133.45 | C20: =ROUNDDOWN((C5-ROUNDUP(C5*0.1,2)-ROUNDUP(C5*0.05,2))*0.8,2) -> 137.22 | D20: =ROUNDDOWN((D5-ROUNDUP(D5*0.1,2)-ROUNDUP(D5*0.05,2))*0.8,2) -> 133.96 | E20: =ROUNDDOWN((E5-ROUNDUP(E5*0.1,2)-ROUNDUP(E5*0.05,2))*0.8,2) -> 133.87 | F20: =ROUNDDOWN((F5-ROUNDUP(F5*0.1,2)-ROUNDUP(F5*0.05,2))*0.8,2) -> 140.88 | G20: =ROUNDDOWN((G5-ROUNDUP(G5*0.1,2)-ROUNDUP(G5*0.05,2))*0.8,2) -> 142.42 | H20: =ROUNDDOWN((H5-ROUNDUP(H5*0.1,2)-ROUNDUP(H5*0.05,2))*0.8,2) -> 137.28 | I20: =ROUNDDOWN((I5-ROUNDUP(I5*0.1,2)-ROUNDUP(I5*0.05,2))*0.8,2) -> 137.68 | ... BY20: =ROUNDDOWN((BY5-ROUNDUP(BY5*0.1,2)-ROUNDUP(BY5*0.05,2))*0.8,2) -> 0
A21: Butterfly Knife Tiger Tooth FN | B21: =ROUNDDOWN((B6-ROUNDUP(B6*0.1,2)-ROUNDUP(B6*0.05,2))*0.8,2) -> 817.08 | C21: =ROUNDDOWN((C6-ROUNDUP(C6*0.1,2)-ROUNDUP(C6*0.05,2))*0.8,2) -> 819.7 | D21: =ROUNDDOWN((D6-ROUNDUP(D6*0.1,2)-ROUNDUP(D6*0.05,2))*0.8,2) -> 857.54 | E21: =ROUNDDOWN((E6-ROUNDUP(E6*0.1,2)-ROUNDUP(E6*0.05,2))*0.8,2) -> 857.51 | F21: =ROUNDDOWN((F6-ROUNDUP(F6*0.1,2)-ROUNDUP(F6*0.05,2))*0.8,2) -> 857.51 | G21: =ROUNDDOWN((G6-ROUNDUP(G6*0.1,2)-ROUNDUP(G6*0.05,2))*0.8,2) -> 836.78 | H21: =ROUNDDOWN((H6-ROUNDUP(H6*0.1,2)-ROUNDUP(H6*0.05,2))*0.8,2) -> 880.16 | I21: =ROUNDDOWN((I6-ROUNDUP(I6*0.1,2)-ROUNDUP(I6*0.05,2))*0.8,2) -> 880.16 | ... BY21: =ROUNDDOWN((BY6-ROUNDUP(BY6*0.1,2)-ROUNDUP(BY6*0.05,2))*0.8,2) -> 0
A22: Flip Knife Freehand FN | B22: =ROUNDDOWN((B7-ROUNDUP(B7*0.1,2)-ROUNDUP(B7*0.05,2))*0.8,2) -> 132.32 | C22: =ROUNDDOWN((C7-ROUNDUP(C7*0.1,2)-ROUNDUP(C7*0.05,2))*0.8,2) -> 130.28 | D22: =ROUNDDOWN((D7-ROUNDUP(D7*0.1,2)-ROUNDUP(D7*0.05,2))*0.8,2) -> 122.46 | E22: =ROUNDDOWN((E7-ROUNDUP(E7*0.1,2)-ROUNDUP(E7*0.05,2))*0.8,2) -> 130.83 | F22: =ROUNDDOWN((F7-ROUNDUP(F7*0.1,2)-ROUNDUP(F7*0.05,2))*0.8,2) -> 130.83 | G22: =ROUNDDOWN((G7-ROUNDUP(G7*0.1,2)-ROUNDUP(G7*0.05,2))*0.8,2) -> 130.07 | H22: =ROUNDDOWN((H7-ROUNDUP(H7*0.1,2)-ROUNDUP(H7*0.05,2))*0.8,2) -> 124.44 | I22: =ROUNDDOWN((I7-ROUNDUP(I7*0.1,2)-ROUNDUP(I7*0.05,2))*0.8,2) -> 129.76 | ... BY22: =ROUNDDOWN((BY7-ROUNDUP(BY7*0.1,2)-ROUNDUP(BY7*0.05,2))*0.8,2) -> 0
A23: Karambit Ultraviolet FT | B23: =ROUNDDOWN((B8-ROUNDUP(B8*0.1,2)-ROUNDUP(B8*0.05,2))*0.8,2) -> 258.76 | C23: =ROUNDDOWN((C8-ROUNDUP(C8*0.1,2)-ROUNDUP(C8*0.05,2))*0.8,2) -> 260.44 | D23: =ROUNDDOWN((D8-ROUNDUP(D8*0.1,2)-ROUNDUP(D8*0.05,2))*0.8,2) -> 246.08 | E23: =ROUNDDOWN((E8-ROUNDUP(E8*0.1,2)-ROUNDUP(E8*0.05,2))*0.8,2) -> 246.13 | F23: =ROUNDDOWN((F8-ROUNDUP(F8*0.1,2)-ROUNDUP(F8*0.05,2))*0.8,2) -> 253.22 | G23: =ROUNDDOWN((G8-ROUNDUP(G8*0.1,2)-ROUNDUP(G8*0.05,2))*0.8,2) -> 248.8 | H23: =ROUNDDOWN((H8-ROUNDUP(H8*0.1,2)-ROUNDUP(H8*0.05,2))*0.8,2) -> 227.52 | I23: =ROUNDDOWN((I8-ROUNDUP(I8*0.1,2)-ROUNDUP(I8*0.05,2))*0.8,2) -> 241.8 | ... BY23: =ROUNDDOWN((BY8-ROUNDUP(BY8*0.1,2)-ROUNDUP(BY8*0.05,2))*0.8,2) -> 0
B25: =SUM(B20:B23) -> 1341.61 | C25: =SUM(C20:C23) -> 1347.64 | D25: =SUM(D20:D23) -> 1360.04 | E25: =SUM(E20:E23) -> 1368.34 | F25: =SUM(F20:F23) -> 1382.44 | G25: =SUM(G20:G23) -> 1358.07 | H25: =SUM(H20:H23) -> 1369.4 | I25: =SUM(I20:I23) -> 1389.4 | ... BY25: =SUM(BY20:BY23) -> 0

Sheet AWP
A1: AWP
A3: Name
B4: =Knives!B4 -> 44331 | C4: =Knives!C4 -> 44332 | D4: =Knives!D4 -> 44334 | E4: =Knives!E4 -> 44336 | F4: =Knives!F4 -> 44337 | G4: =Knives!G4 -> 44338 | H4: =Knives!H4 -> 44339 | I4: =Knives!I4 -> 44340 | ... BY4: =Knives!BY4 -> 44408
A5: Fewer Dream MW | B5: 7.47 | C5: 7.52 | D5: 7.36 | E5: 7.24 | F5: 7.42 | G5: 7.21 | H5: 7.03 | I5: 7.44 | J5: 7.33 | K5: 6.98 | L5: 6.95 | M5: 6.92 | N5: 7.05 | O5: 6.62 | P5: 6.71 | Q5: 7.14 | R5: 6.86 | S5: 7.3 | T5: 7.04 | U5: 6.9 | V5: 7.02 | W5: 7.37 | X5: 7.3 | Y5: 7.22 | Z5: 6.99 | AA5: 6.85
A6: Elite Build FT | B6: 6.81 | C6: 7.26 | D6: 7.22 | E6: 6.73 | F6: 6.71 | G6: 6.73 | H6: 6.97 | I6: 7.34 | J6: 7.18 | K6: 6.93 | L6: 6.5 | M6: 6.4 | N6: 7.28 | O6: 7.32 | P6: 7.71 | Q6: 7.27 | R6: 7.36 | S6: 7.14 | T6: 7.32 | U6: 7.2 | V6: 7.6 | W6: 7.54 | X6: 7.66 | Y6: 7.49 | Z6: 7.08 | AA6: 7.24
A7: Stattrak Hyper Beast FT | B7: 74.08 | C7: 71.31 | D7: 71.88 | E7: 71.23 | F7: 70.58 | G7: 65.36 | H7: 73.31 | I7: 73.31 | J7: 72.87 | K7: 84.58 | L7: 84.44 | M7: 75.84 | N7: 76.16 | O7: 69.57 | P7: 74.78 | Q7: 75.67 | R7: 83.34 | S7: 78.56 | T7: 78.23 | U7: 78.48 | V7: 76.79 | W7: 79.09 | X7: 85.65 | Y7: 78.77 | Z7: 75 | AA7: 74.31
A8: Mortis MW | B8: 3.23 | C8: 3.14 | D8: 3.5 | E8: 3.27 | F8: 3.28 | G8: 3.41 | H8: 3.47 | I8: 3.16 | J8: 3.26 | K8: 3.28 | L8: 3.29 | M8: 3.38 | N8: 3.25 | O8: 3.26 | P8: 3.19 | Q8: 3.39 | R8: 3.14 | S8: 3.14 | T8: 3.13 | U8: 2.92 | V8: 3.15 | W8: 2.99 | X8: 2.89 | Y8: 3.17 | Z8: 3.17 | AA8: 3.26
A9: Boom MW | B9: 52.57 | C9: 50.84 | D9: 61.12 | E9: 54.92 | F9: 54.99 | G9: 52.25 | H9: 56.03 | I9: 55.57 | J9: 54.76 | K9: 54.99 | L9: 54.7 | M9: 52.32 | N9: 54.62 | O9: 55.38 | P9: 53.77 | Q9: 56.08 | R9: 56.08 | S9: 57.36 | T9: 55.4 | U9: 55.27 | V9: 54.17 | W9: 54.77 | X9: 55.31 | Y9: 55.82 | Z9: 55.54 | AA9: 56.84
A10: Neo-Noir FN | B10: 47 | C10: 45.93 | D10: 44.54 | E10: 45.51 | F10: 46.05 | G10: 46.08 | H10: 46.57 | I10: 47.69 | J10: 44.11 | K10: 44.01 | L10: 45.22 | M10: 46.55 | N10: 46.98 | O10: 43.94 | P10: 46.39 | Q10: 46.37 | R10: 47.84 | S10: 44.88 | T10: 48.07 | U10: 48.33 | V10: 47.69 | W10: 46.01 | X10: 47.06 | Y10: 45.28 | Z10: 42.61 | AA10: 46.48
A11: Atheris MW | B11: 4.31 | C11: 4.54 | D11: 4.37 | E11: 4.41 | F11: 4.16 | G11: 4.4 | H11: 4.73 | I11: 4.69 | J11: 4.54 | K11: 4.53 | L11: 4.55 | M11: 4.22 | N11: 4.39 | O11: 4.23 | P11: 4.06 | Q11: 4.23 | R11: 4.62 | S11: 4.07 | T11: 4.3 | U11: 4.23 | V11: 4.21 | W11: 4.25 | X11: 4.25 | Y11: 4.22 | Z11: 4.27 | AA11: 4.43
B13: =SUM(B5:B11) -> 195.47 | C13: =SUM(C5:C11) -> 190.54 | D13: =SUM(D5:D11) -> 199.99 | E13: =SUM(E5:E11) -> 193.31 | F13: =SUM(F5:F11) -> 193.19 | G13: =SUM(G5:G11) -> 185.44 | H13: =SUM(H5:H11) -> 198.11 | I13: =SUM(I5:I11) -> 199.2 | ... BY13: =SUM(BY5:BY11) -> 0
A18: Sale-Value
A20: Name
B21: =B4 -> 44331 | C21: =C4 -> 44332 | D21: =D4 -> 44334 | E21: =E4 -> 44336 | F21: =F4 -> 44337 | G21: =G4 -> 44338 | H21: =H4 -> 44339 | I21: =I4 -> 44340 | ... BY21: =BY4 -> 44408
A22: Fewer Dream MW | B22: =ROUNDDOWN((B5-ROUNDUP(B5*0.1,2)-ROUNDUP(B5*0.05,2))*0.8,2) -> 5.07 | C22: =ROUNDDOWN((C5-ROUNDUP(C5*0.1,2)-ROUNDUP(C5*0.05,2))*0.8,2) -> 5.1 | D22: =ROUNDDOWN((D5-ROUNDUP(D5*0.1,2)-ROUNDUP(D5*0.05,2))*0.8,2) -> 5 | E22: =ROUNDDOWN((E5-ROUNDUP(E5*0.1,2)-ROUNDUP(E5*0.05,2))*0.8,2) -> 4.91 | F22: =ROUNDDOWN((F5-ROUNDUP(F5*0.1,2)-ROUNDUP(F5*0.05,2))*0.8,2) -> 5.03 | G22: =ROUNDDOWN((G5-ROUNDUP(G5*0.1,2)-ROUNDUP(G5*0.05,2))*0.8,2) -> 4.88 | H22: =ROUNDDOWN((H5-ROUNDUP(H5*0.1,2)-ROUNDUP(H5*0.05,2))*0.8,2) -> 4.76 | I22: =ROUNDDOWN((I5-ROUNDUP(I5*0.1,2)-ROUNDUP(I5*0.05,2))*0.8,2) -> 5.04 | ... BY22: =ROUNDDOWN((BY5-ROUNDUP(BY5*0.1,2)-ROUNDUP(BY5*0.05,2))*0.8,2) -> 0
A23: Elite Build FT | B23: =ROUNDDOWN((B6-ROUNDUP(B6*0.1,2)-ROUNDUP(B6*0.05,2))*0.8,2) -> 4.61 | C23: =ROUNDDOWN((C6-ROUNDUP(C6*0.1,2)-ROUNDUP(C6*0.05,2))*0.8,2) -> 4.92 | D23: =ROUNDDOWN((D6-ROUNDUP(D6*0.1,2)-ROUNDUP(D6*0.05,2))*0.8,2) -> 4.89 | E23: =ROUNDDOWN((E6-ROUNDUP(E6*0.1,2)-ROUNDUP(E6*0.05,2))*0.8,2) -> 4.56 | F23: =ROUNDDOWN((F6-ROUNDUP(F6*0.1,2)-ROUNDUP(F6*0.05,2))*0.8,2) -> 4.55 | G23: =ROUNDDOWN((G6-ROUNDUP(G6*0.1,2)-ROUNDUP(G6*0.05,2))*0.8,2) -> 4.56 | H23: =ROUNDDOWN((H6-ROUNDUP(H6*0.1,2)-ROUNDUP(H6*0.05,2))*0.8,2) -> 4.73 | I23: =ROUNDDOWN((I6-ROUNDUP(I6*0.1,2)-ROUNDUP(I6*0.05,2))*0.8,2) -> 4.98 | ... BY23: =ROUNDDOWN((BY6-ROUNDUP(BY6*0.1,2)-ROUNDUP(BY6*0.05,2))*0.8,2) -> 0
A24: Stattrak Hyper Beast FT | B24: =ROUNDDOWN((B7-ROUNDUP(B7*0.1,2)-ROUNDUP(B7*0.05,2))*0.8,2) -> 50.36 | C24: =ROUNDDOWN((C7-ROUNDUP(C7*0.1,2)-ROUNDUP(C7*0.05,2))*0.8,2) -> 48.48 | D24: =ROUNDDOWN((D7-ROUNDUP(D7*0.1,2)-ROUNDUP(D7*0.05,2))*0.8,2) -> 48.87 | E24: =ROUNDDOWN((E7-ROUNDUP(E7*0.1,2)-ROUNDUP(E7*0.05,2))*0.8,2) -> 48.42 | F24: =ROUNDDOWN((F7-ROUNDUP(F7*0.1,2)-ROUNDUP(F7*0.05,2))*0.8,2) -> 47.99 | G24: =ROUNDDOWN((G7-ROUNDUP(G7*0.1,2)-ROUNDUP(G7*0.05,2))*0.8,2) -> 44.44 | H24: =ROUNDDOWN((H7-ROUNDUP(H7*0.1,2)-ROUNDUP(H7*0.05,2))*0.8,2) -> 49.84 | I24: =ROUNDDOWN((I7-ROUNDUP(I7*0.1,2)-ROUNDUP(I7*0.05,2))*0.8,2) -> 49.84 | ... BY24: =ROUNDDOWN((BY7-ROUNDUP(BY7*0.1,2)-ROUNDUP(BY7*0.05,2))*0.8,2) -> 0
A25: Mortis MW | B25: =ROUNDDOWN((B8-ROUNDUP(B8*0.1,2)-ROUNDUP(B8*0.05,2))*0.8,2) -> 2.18 | C25: =ROUNDDOWN((C8-ROUNDUP(C8*0.1,2)-ROUNDUP(C8*0.05,2))*0.8,2) -> 2.12 | D25: =ROUNDDOWN((D8-ROUNDUP(D8*0.1,2)-ROUNDUP(D8*0.05,2))*0.8,2) -> 2.37 | E25: =ROUNDDOWN((E8-ROUNDUP(E8*0.1,2)-ROUNDUP(E8*0.05,2))*0.8,2) -> 2.21 | F25: =ROUNDDOWN((F8-ROUNDUP(F8*0.1,2)-ROUNDUP(F8*0.05,2))*0.8,2) -> 2.22 | G25: =ROUNDDOWN((G8-ROUNDUP(G8*0.1,2)-ROUNDUP(G8*0.05,2))*0.8,2) -> 2.3 | H25: =ROUNDDOWN((H8-ROUNDUP(H8*0.1,2)-ROUNDUP(H8*0.05,2))*0.8,2) -> 2.35 | I25: =ROUNDDOWN((I8-ROUNDUP(I8*0.1,2)-ROUNDUP(I8*0.05,2))*0.8,2) -> 2.14 | ... BY25: =ROUNDDOWN((BY8-ROUNDUP(BY8*0.1,2)-ROUNDUP(BY8*0.05,2))*0.8,2) -> 0
A26: Boom MW | B26: =ROUNDDOWN((B9-ROUNDUP(B9*0.1,2)-ROUNDUP(B9*0.05,2))*0.8,2) -> 35.74 | C26: =ROUNDDOWN((C9-ROUNDUP(C9*0.1,2)-ROUNDUP(C9*0.05,2))*0.8,2) -> 34.56 | D26: =ROUNDDOWN((D9-ROUNDUP(D9*0.1,2)-ROUNDUP(D9*0.05,2))*0.8,2) -> 41.55 | E26: =ROUNDDOWN((E9-ROUNDUP(E9*0.1,2)-ROUNDUP(E9*0.05,2))*0.8,2) -> 37.33 | F26: =ROUNDDOWN((F9-ROUNDUP(F9*0.1,2)-ROUNDUP(F9*0.05,2))*0.8,2) -> 37.39 | G26: =ROUNDDOWN((G9-ROUNDUP(G9*0.1,2)-ROUNDUP(G9*0.05,2))*0.8,2) -> 35.52 | H26: =ROUNDDOWN((H9-ROUNDUP(H9*0.1,2)-ROUNDUP(H9*0.05,2))*0.8,2) -> 38.08 | I26: =ROUNDDOWN((I9-ROUNDUP(I9*0.1,2)-ROUNDUP(I9*0.05,2))*0.8,2) -> 37.78 | ... BY26: =ROUNDDOWN((BY9-ROUNDUP(BY9*0.1,2)-ROUNDUP(BY9*0.05,2))*0.8,2) -> 0
A27: Neo-Noir FN | B27: =ROUNDDOWN((B10-ROUNDUP(B10*0.1,2)-ROUNDUP(B10*0.05,2))*0.8,2) -> 31.96 | C27: =ROUNDDOWN((C10-ROUNDUP(C10*0.1,2)-ROUNDUP(C10*0.05,2))*0.8,2) -> 31.22 | D27: =ROUNDDOWN((D10-ROUNDUP(D10*0.1,2)-ROUNDUP(D10*0.05,2))*0.8,2) -> 30.28 | E27: =ROUNDDOWN((E10-ROUNDUP(E10*0.1,2)-ROUNDUP(E10*0.05,2))*0.8,2) -> 30.93 | F27: =ROUNDDOWN((F10-ROUNDUP(F10*0.1,2)-ROUNDUP(F10*0.05,2))*0.8,2) -> 31.3 | G27: =ROUNDDOWN((G10-ROUNDUP(G10*0.1,2)-ROUNDUP(G10*0.05,2))*0.8,2) -> 31.32 | H27: =ROUNDDOWN((H10-ROUNDUP(H10*0.1,2)-ROUNDUP(H10*0.05,2))*0.8,2) -> 31.66 | I27: =ROUNDDOWN((I10-ROUNDUP(I10*0.1,2)-ROUNDUP(I10*0.05,2))*0.8,2) -> 32.42 | ... BY27: =ROUNDDOWN((BY10-ROUNDUP(BY10*0.1,2)-ROUNDUP(BY10*0.05,2))*0.8,2) -> 0
A28: Atheris MW | B28: =ROUNDDOWN((B11-ROUNDUP(B11*0.1,2)-ROUNDUP(B11*0.05,2))*0.8,2) -> 2.92 | C28: =ROUNDDOWN((C11-ROUNDUP(C11*0.1,2)-ROUNDUP(C11*0.05,2))*0.8,2) -> 3.08 | D28: =ROUNDDOWN((D11-ROUNDUP(D11*0.1,2)-ROUNDUP(D11*0.05,2))*0.8,2) -> 2.96 | E28: =ROUNDDOWN((E11-ROUNDUP(E11*0.1,2)-ROUNDUP(E11*0.05,2))*0.8,2) -> 2.98 | F28: =ROUNDDOWN((F11-ROUNDUP(F11*0.1,2)-ROUNDUP(F11*0.05,2))*0.8,2) -> 2.82 | G28: =ROUNDDOWN((G11-ROUNDUP(G11*0.1,2)-ROUNDUP(G11*0.05,2))*0.8,2) -> 2.99 | H28: =ROUNDDOWN((H11-ROUNDUP(H11*0.1,2)-ROUNDUP(H11*0.05,2))*0.8,2) -> 3.2 | I28: =ROUNDDOWN((I11-ROUNDUP(I11*0.1,2)-ROUNDUP(I11*0.05,2))*0.8,2) -> 3.18 | ... BY28: =ROUNDDOWN((BY11-ROUNDUP(BY11*0.1,2)-ROUNDUP(BY11*0.05,2))*0.8,2) -> 0
B30: =SUM(B22:B28) -> 132.84 | C30: =SUM(C22:C28) -> 129.48 | D30: =SUM(D22:D28) -> 135.92 | E30: =SUM(E22:E28) -> 131.34 | F30: =SUM(F22:F28) -> 131.3 | G30: =SUM(G22:G28) -> 126.01 | H30: =SUM(H22:H28) -> 134.62 | I30: =SUM(I22:I28) -> 135.38 | ... BY30: =SUM(BY22:BY28) -> 0

Sheet M4A4
A1: M4A4
A3: Name
B4: =Knives!B4 -> 44331 | C4: =Knives!C4 -> 44332 | D4: =Knives!D4 -> 44334 | E4: =Knives!E4 -> 44336 | F4: =Knives!F4 -> 44337 | G4: =Knives!G4 -> 44338 | H4: =Knives!H4 -> 44339 | I4: =Knives!I4 -> 44340 | ... BY4: =Knives!BY4 -> 44408
A5: Stattrak Dragon King MW | B5: 37.31 | C5: 36.88 | D5: 38.8 | E5: 37.92 | F5: 39.03 | G5: 38.35 | H5: 37.8 | I5: 36.91 | J5: 35.35 | K5: 38.06 | L5: 35.93 | M5: 36.22 | N5: 35.09 | O5: 36.14 | P5: 36.81 | Q5: 37.95 | R5: 39.41 | S5: 37.04 | T5: 39.44 | U5: 37.85 | V5: 36.15 | W5: 36.14 | X5: 36.14 | Y5: 37.04 | Z5: 36.04 | AA5: 38.33
A6: Desolate Space MW | B6: 13.77 | C6: 14.43 | D6: 13.96 | E6: 13.19 | F6: 14.41 | G6: 14.08 | H6: 14.66 | I6: 13.65 | J6: 13.29 | K6: 13.64 | L6: 13.24 | M6: 13.22 | N6: 13.98 | O6: 13.53 | P6: 13.74 | Q6: 13.68 | R6: 13.85 | S6: 12.95 | T6: 13.12 | U6: 13.6 | V6: 13.04 | W6: 14 | X6: 13.51 | Y6: 13.59 | Z6: 13.03 | AA6: 12.55
A7: Bullet Rain MW | B7: 17.31 | C7: 16.39 | D7: 18.76 | E7: 18.24 | F7: 18.28 | G7: 17.51 | H7: 17.17 | I7: 18.43 | J7: 17.95 | K7: 18.69 | L7: 17.26 | M7: 18.41 | N7: 18.35 | O7: 18.91 | P7: 17.68 | Q7: 18.25 | R7: 18.32 | S7: 18.26 | T7: 17.87 | U7: 18.21 | V7: 18.78 | W7: 17.96 | X7: 16.98 | Y7: 17.06 | Z7: 17.26 | AA7: 17.79
A8: Evil Daimyo FN | B8: 6.9 | C8: 7.37 | D8: 6.99 | E8: 6.87 | F8: 6.82 | G8: 7.06 | H8: 6.74 | I8: 7.04 | J8: 6.99 | K8: 7.14 | L8: 6.68 | M8: 6.85 | N8: 6.98 | O8: 7.03 | P8: 6.48 | Q8: 6.63 | R8: 6.64 | S8: 7.06 | T8: 6.58 | U8: 6.51 | V8: 6.59 | W8: 7.03 | X8: 6.6 | Y8: 6.98 | Z8: 6.76 | AA8: 6.75
A9: Hellfire MW | B9: 26.86 | C9: 25.93 | D9: 25.2 | E9: 26.25 | F9: 26.3 | G9: 26.9 | H9: 24.86 | I9: 27.3 | J9: 25.21 | K9: 26.11 | L9: 27.42 | M9: 27.34 | N9: 27.33 | O9: 28.52 | P9: 28.58 | Q9: 29.09 | R9: 29.49 | S9: 28.06 | T9: 32.92 | U9: 38.33 | V9: 35.7 | W9: 31.47 | X9: 31.14 | Y9: 31.54 | Z9: 31.16 | AA9: 30.56
A10: Neo-Noir MW | B10: 29.07 | C10: 29.37 | D10: 26.79 | E10: 27.5 | F10: 27.26 | G10: 28.86 | H10: 27.29 | I10: 25.83 | J10: 26.17 | K10: 25.72 | L10: 27.42 | M10: 25.94 | N10: 26.04 | O10: 25.26 | P10: 27.4 | Q10: 27.17 | R10: 26.02 | S10: 26.27 | T10: 27.83 | U10: 26.99 | V10: 25.85 | W10: 28.1 | X10: 26.37 | Y10: 26.59 | Z10: 25.22 | AA10: 24.19
A11: The Battlestar FN | B11: 14.52 | C11: 13.27 | D11: 13.26 | E11: 14.11 | F11: 14.06 | G11: 14.27 | H11: 13.84 | I11: 13.34 | J11: 12.49 | K11: 12.85 | L11: 12.48 | M11: 13.5 | N11: 13.54 | O11: 13.54 | P11: 14.22 | Q11: 13.54 | R11: 13.19 | S11: 13.66 | T11: 12.69 | U11: 13.66 | V11: 13.27 | W11: 13.63 | X11: 13.64 | Y11: 13.66 | Z11: 13.69 | AA11: 13.68
A12: Stattrak Cyber Security MW | B12: 33.21 | C12: 31.65 | D12: 29.18 | E12: 31.74 | F12: 29.35 | G12: 30.3 | H12: 30.75 | I12: 28.8 | J12: 30.22 | K12: 28.81 | L12: 28.69 | M12: 27.92 | N12: 28.87 | O12: 29.99 | P12: 28.9 | Q12: 29.12 | R12: 29.62 | S12: 28.55 | T12: 29.16 | U12: 29.07 | V12: 29.04 | W12: 30.67 | X12: 28.92 | Y12: 29.44 | Z12: 30.41 | AA12: 29.82
B14: =SUM(B5:B12) -> 178.95 | C14: =SUM(C5:C12) -> 175.29 | D14: =SUM(D5:D12) -> 172.94 | E14: =SUM(E5:E12) -> 175.82 | F14: =SUM(F5:F12) -> 175.51 | G14: =SUM(G5:G12) -> 177.33 | H14: =SUM(H5:H12) -> 173.11 | I14: =SUM(I5:I12) -> 171.3 | ... BY14: =SUM(BY5:BY12) -> 0
A18: Sale-Value
A20: Name
B21: =B4 -> 44331 | C21: =C4 -> 44332 | D21: =D4 -> 44334 | E21: =E4 -> 44336 | F21: =F4 -> 44337 | G21: =G4 -> 44338 | H21: =H4 -> 44339 | I21: =I4 -> 44340 | ... BY21: =BY4 -> 44408
A22: Stattrak Dragon King MW | B22: =ROUNDDOWN((B5-ROUNDUP(B5*0.1,2)-ROUNDUP(B5*0.05,2))*0.8,2) -> 25.36 | C22: =ROUNDDOWN((C5-ROUNDUP(C5*0.1,2)-ROUNDUP(C5*0.05,2))*0.8,2) -> 25.07 | D22: =ROUNDDOWN((D5-ROUNDUP(D5*0.1,2)-ROUNDUP(D5*0.05,2))*0.8,2) -> 26.38 | E22: =ROUNDDOWN((E5-ROUNDUP(E5*0.1,2)-ROUNDUP(E5*0.05,2))*0.8,2) -> 25.77 | F22: =ROUNDDOWN((F5-ROUNDUP(F5*0.1,2)-ROUNDUP(F5*0.05,2))*0.8,2) -> 26.52 | G22: =ROUNDDOWN((G5-ROUNDUP(G5*0.1,2)-ROUNDUP(G5*0.05,2))*0.8,2) -> 26.07 | H22: =ROUNDDOWN((H5-ROUNDUP(H5*0.1,2)-ROUNDUP(H5*0.05,2))*0.8,2) -> 25.7 | I22: =ROUNDDOWN((I5-ROUNDUP(I5*0.1,2)-ROUNDUP(I5*0.05,2))*0.8,2) -> 25.08 | ... BY22: =ROUNDDOWN((BY5-ROUNDUP(BY5*0.1,2)-ROUNDUP(BY5*0.05,2))*0.8,2) -> 0
A23: Desolate Space MW | B23: =ROUNDDOWN((B6-ROUNDUP(B6*0.1,2)-ROUNDUP(B6*0.05,2))*0.8,2) -> 9.36 | C23: =ROUNDDOWN((C6-ROUNDUP(C6*0.1,2)-ROUNDUP(C6*0.05,2))*0.8,2) -> 9.8 | D23: =ROUNDDOWN((D6-ROUNDUP(D6*0.1,2)-ROUNDUP(D6*0.05,2))*0.8,2) -> 9.48 | E23: =ROUNDDOWN((E6-ROUNDUP(E6*0.1,2)-ROUNDUP(E6*0.05,2))*0.8,2) -> 8.96 | F23: =ROUNDDOWN((F6-ROUNDUP(F6*0.1,2)-ROUNDUP(F6*0.05,2))*0.8,2) -> 9.78 | G23: =ROUNDDOWN((G6-ROUNDUP(G6*0.1,2)-ROUNDUP(G6*0.05,2))*0.8,2) -> 9.56 | H23: =ROUNDDOWN((H6-ROUNDUP(H6*0.1,2)-ROUNDUP(H6*0.05,2))*0.8,2) -> 9.96 | I23: =ROUNDDOWN((I6-ROUNDUP(I6*0.1,2)-ROUNDUP(I6*0.05,2))*0.8,2) -> 9.27 | ... BY23: =ROUNDDOWN((BY6-ROUNDUP(BY6*0.1,2)-ROUNDUP(BY6*0.05,2))*0.8,2) -> 0
A24: Bullet Rain MW | B24: =ROUNDDOWN((B7-ROUNDUP(B7*0.1,2)-ROUNDUP(B7*0.05,2))*0.8,2) -> 11.76 | C24: =ROUNDDOWN((C7-ROUNDUP(C7*0.1,2)-ROUNDUP(C7*0.05,2))*0.8,2) -> 11.14 | D24: =ROUNDDOWN((D7-ROUNDUP(D7*0.1,2)-ROUNDUP(D7*0.05,2))*0.8,2) -> 12.75 | E24: =ROUNDDOWN((E7-ROUNDUP(E7*0.1,2)-ROUNDUP(E7*0.05,2))*0.8,2) -> 12.39 | F24: =ROUNDDOWN((F7-ROUNDUP(F7*0.1,2)-ROUNDUP(F7*0.05,2))*0.8,2) -> 12.42 | G24: =ROUNDDOWN((G7-ROUNDUP(G7*0.1,2)-ROUNDUP(G7*0.05,2))*0.8,2) -> 11.89 | H24: =ROUNDDOWN((H7-ROUNDUP(H7*0.1,2)-ROUNDUP(H7*0.05,2))*0.8,2) -> 11.67 | I24: =ROUNDDOWN((I7-ROUNDUP(I7*0.1,2)-ROUNDUP(I7*0.05,2))*0.8,2) -> 12.52 | ... BY24: =ROUNDDOWN((BY7-ROUNDUP(BY7*0.1,2)-ROUNDUP(BY7*0.05,2))*0.8,2) -> 0
A25: Evil Daimyo FN | B25: =ROUNDDOWN((B8-ROUNDUP(B8*0.1,2)-ROUNDUP(B8*0.05,2))*0.8,2) -> 4.68 | C25: =ROUNDDOWN((C8-ROUNDUP(C8*0.1,2)-ROUNDUP(C8*0.05,2))*0.8,2) -> 5 | D25: =ROUNDDOWN((D8-ROUNDUP(D8*0.1,2)-ROUNDUP(D8*0.05,2))*0.8,2) -> 4.75 | E25: =ROUNDDOWN((E8-ROUNDUP(E8*0.1,2)-ROUNDUP(E8*0.05,2))*0.8,2) -> 4.66 | F25: =ROUNDDOWN((F8-ROUNDUP(F8*0.1,2)-ROUNDUP(F8*0.05,2))*0.8,2) -> 4.62 | G25: =ROUNDDOWN((G8-ROUNDUP(G8*0.1,2)-ROUNDUP(G8*0.05,2))*0.8,2) -> 4.79 | H25: =ROUNDDOWN((H8-ROUNDUP(H8*0.1,2)-ROUNDUP(H8*0.05,2))*0.8,2) -> 4.57 | I25: =ROUNDDOWN((I8-ROUNDUP(I8*0.1,2)-ROUNDUP(I8*0.05,2))*0.8,2) -> 4.77 | ... BY25: =ROUNDDOWN((BY8-ROUNDUP(BY8*0.1,2)-ROUNDUP(BY8*0.05,2))*0.8,2) -> 0
A26: Hellfire MW | B26: =ROUNDDOWN((B9-ROUNDUP(B9*0.1,2)-ROUNDUP(B9*0.05,2))*0.8,2) -> 18.25 | C26: =ROUNDDOWN((C9-ROUNDUP(C9*0.1,2)-ROUNDUP(C9*0.05,2))*0.8,2) -> 17.62 | D26: =ROUNDDOWN((D9-ROUNDUP(D9*0.1,2)-ROUNDUP(D9*0.05,2))*0.8,2) -> 17.13 | E26: =ROUNDDOWN((E9-ROUNDUP(E9*0.1,2)-ROUNDUP(E9*0.05,2))*0.8,2) -> 17.84 | F26: =ROUNDDOWN((F9-ROUNDUP(F9*0.1,2)-ROUNDUP(F9*0.05,2))*0.8,2) -> 17.88 | G26: =ROUNDDOWN((G9-ROUNDUP(G9*0.1,2)-ROUNDUP(G9*0.05,2))*0.8,2) -> 18.28 | H26: =ROUNDDOWN((H9-ROUNDUP(H9*0.1,2)-ROUNDUP(H9*0.05,2))*0.8,2) -> 16.89 | I26: =ROUNDDOWN((I9-ROUNDUP(I9*0.1,2)-ROUNDUP(I9*0.05,2))*0.8,2) -> 18.56 | ... BY26: =ROUNDDOWN((BY9-ROUNDUP(BY9*0.1,2)-ROUNDUP(BY9*0.05,2))*0.8,2) -> 0
A27: Neo-Noir MW | B27: =ROUNDDOWN((B10-ROUNDUP(B10*0.1,2)-ROUNDUP(B10*0.05,2))*0.8,2) -> 19.76 | C27: =ROUNDDOWN((C10-ROUNDUP(C10*0.1,2)-ROUNDUP(C10*0.05,2))*0.8,2) -> 19.96 | D27: =ROUNDDOWN((D10-ROUNDUP(D10*0.1,2)-ROUNDUP(D10*0.05,2))*0.8,2) -> 18.21 | E27: =ROUNDDOWN((E10-ROUNDUP(E10*0.1,2)-ROUNDUP(E10*0.05,2))*0.8,2) -> 18.69 | F27: =ROUNDDOWN((F10-ROUNDUP(F10*0.1,2)-ROUNDUP(F10*0.05,2))*0.8,2) -> 18.52 | G27: =ROUNDDOWN((G10-ROUNDUP(G10*0.1,2)-ROUNDUP(G10*0.05,2))*0.8,2) -> 19.61 | H27: =ROUNDDOWN((H10-ROUNDUP(H10*0.1,2)-ROUNDUP(H10*0.05,2))*0.8,2) -> 18.55 | I27: =ROUNDDOWN((I10-ROUNDUP(I10*0.1,2)-ROUNDUP(I10*0.05,2))*0.8,2) -> 17.55 | ... BY27: =ROUNDDOWN((BY10-ROUNDUP(BY10*0.1,2)-ROUNDUP(BY10*0.05,2))*0.8,2) -> 0
A28: The Battlestar FN | B28: =ROUNDDOWN((B11-ROUNDUP(B11*0.1,2)-ROUNDUP(B11*0.05,2))*0.8,2) -> 9.86 | C28: =ROUNDDOWN((C11-ROUNDUP(C11*0.1,2)-ROUNDUP(C11*0.05,2))*0.8,2) -> 9.01 | D28: =ROUNDDOWN((D11-ROUNDUP(D11*0.1,2)-ROUNDUP(D11*0.05,2))*0.8,2) -> 9 | E28: =ROUNDDOWN((E11-ROUNDUP(E11*0.1,2)-ROUNDUP(E11*0.05,2))*0.8,2) -> 9.58 | F28: =ROUNDDOWN((F11-ROUNDUP(F11*0.1,2)-ROUNDUP(F11*0.05,2))*0.8,2) -> 9.55 | G28: =ROUNDDOWN((G11-ROUNDUP(G11*0.1,2)-ROUNDUP(G11*0.05,2))*0.8,2) -> 9.69 | H28: =ROUNDDOWN((H11-ROUNDUP(H11*0.1,2)-ROUNDUP(H11*0.05,2))*0.8,2) -> 9.4 | I28: =ROUNDDOWN((I11-ROUNDUP(I11*0.1,2)-ROUNDUP(I11*0.05,2))*0.8,2) -> 9.06 | ... BY28: =ROUNDDOWN((BY11-ROUNDUP(BY11*0.1,2)-ROUNDUP(BY11*0.05,2))*0.8,2) -> 0
A29: Stattrak Cyber Security MW | B29: =ROUNDDOWN((B12-ROUNDUP(B12*0.1,2)-ROUNDUP(B12*0.05,2))*0.8,2) -> 22.56 | C29: =ROUNDDOWN((C12-ROUNDUP(C12*0.1,2)-ROUNDUP(C12*0.05,2))*0.8,2) -> 21.51 | D29: =ROUNDDOWN((D12-ROUNDUP(D12*0.1,2)-ROUNDUP(D12*0.05,2))*0.8,2) -> 19.84 | E29: =ROUNDDOWN((E12-ROUNDUP(E12*0.1,2)-ROUNDUP(E12*0.05,2))*0.8,2) -> 21.57 | F29: =ROUNDDOWN((F12-ROUNDUP(F12*0.1,2)-ROUNDUP(F12*0.05,2))*0.8,2) -> 19.95 | G29: =ROUNDDOWN((G12-ROUNDUP(G12*0.1,2)-ROUNDUP(G12*0.05,2))*0.8,2) -> 20.6 | H29: =ROUNDDOWN((H12-ROUNDUP(H12*0.1,2)-ROUNDUP(H12*0.05,2))*0.8,2) -> 20.9 | I29: =ROUNDDOWN((I12-ROUNDUP(I12*0.1,2)-ROUNDUP(I12*0.05,2))*0.8,2) -> 19.58 | ... BY29: =ROUNDDOWN((BY12-ROUNDUP(BY12*0.1,2)-ROUNDUP(BY12*0.05,2))*0.8,2) -> 0
B31: =SUM(B22:B29) -> 121.59 | C31: =SUM(C22:C29) -> 119.11 | D31: =SUM(D22:D29) -> 117.54 | E31: =SUM(E22:E29) -> 119.46 | F31: =SUM(F22:F29) -> 119.24 | G31: =SUM(G22:G29) -> 120.49 | H31: =SUM(H22:H29) -> 117.64 | I31: =SUM(I22:I29) -> 116.39 | ... BY31: =SUM(BY22:BY29) -> 0

Sheet M4A1-S
A1: M4A1-S
A3: Name
B4: =Totals!B4 -> 44331 | C4: =Totals!C4 -> 44332 | D4: =Totals!D4 -> 44334 | E4: =Totals!E4 -> 44336 | F4: =Totals!F4 -> 44337 | G4: =Totals!G4 -> 44338 | H4: =Totals!H4 -> 44339 | I4: =Totals!I4 -> 44340 | ... BY4: =Totals!BY4 -> 44408
A5: Golden Coil FT | B5: 15.54 | C5: 15.25 | D5: 15.81 | E5: 15.02 | F5: 15.8 | G5: 15.47 | H5: 15.35 | I5: 15.48 | J5: 15.22 | K5: 14.51 | L5: 15.48 | M5: 14.67 | N5: 14.07 | O5: 14.65 | P5: 14.89 | Q5: 14.91 | R5: 15.3 | S5: 15.45 | T5: 14.51 | U5: 14.75 | V5: 15.68 | W5: 15.31 | X5: 14.89 | Y5: 14.49 | Z5: 15.93 | AA5: 14.09
A6: Hyper Beast MW | B6: 21.98 | C6: 21.05 | D6: 20.67 | E6: 19.8 | F6: 21.22 | G6: 21.31 | H6: 21.25 | I6: 21.06 | J6: 20.42 | K6: 20.03 | L6: 20.1 | M6: 19.74 | N6: 20.52 | O6: 21.08 | P6: 21.17 | Q6: 21.44 | R6: 19.41 | S6: 19.41 | T6: 20.84 | U6: 20.7 | V6: 21.47 | W6: 20.06 | X6: 19.81 | Y6: 20.55 | Z6: 20.6 | AA6: 20.93
A7: Stattrak Cyrex MW | B7: 36.2 | C7: 34.8 | D7: 33.23 | E7: 33.31 | F7: 34.51 | G7: 33.05 | H7: 31.31 | I7: 33.38 | J7: 33.38 | K7: 33.01 | L7: 30.97 | M7: 34.41 | N7: 34.11 | O7: 41.12 | P7: 36.27 | Q7: 35.09 | R7: 35.93 | S7: 33.97 | T7: 35.33 | U7: 32.56 | V7: 31.05 | W7: 31.98 | X7: 32.85 | Y7: 33.24 | Z7: 33.86 | AA7: 34.56
A8: Flashback FN | B8: 2.92 | C8: 3.01 | D8: 2.89 | E8: 2.81 | F8: 2.82 | G8: 2.91 | H8: 2.84 | I8: 2.78 | J8: 2.71 | K8: 2.68 | L8: 2.81 | M8: 2.54 | N8: 2.64 | O8: 2.77 | P8: 2.5 | Q8: 2.53 | R8: 2.45 | S8: 2.5 | T8: 2.45 | U8: 2.47 | V8: 2.53 | W8: 2.36 | X8: 2.53 | Y8: 2.5 | Z8: 2.53 | AA8: 2.46
B10: =SUM(B5:B8) -> 76.64 | C10: =SUM(C5:C8) -> 74.11 | D10: =SUM(D5:D8) -> 72.6 | E10: =SUM(E5:E8) -> 70.94 | F10: =SUM(F5:F8) -> 74.35 | G10: =SUM(G5:G8) -> 72.74 | H10: =SUM(H5:H8) -> 70.75 | I10: =SUM(I5:I8) -> 72.7 | ... BY10: =SUM(BY5:BY8) -> 0
A16: Sale-Value
A18: Name
B19: =B4 -> 44331 | C19: =C4 -> 44332 | D19: =D4 -> 44334 | E19: =E4 -> 44336 | F19: =F4 -> 44337 | G19: =G4 -> 44338 | H19: =H4 -> 44339 | I19: =I4 -> 44340 | ... BY19: =BY4 -> 44408
A20: Golden Coil FT | B20: =ROUNDDOWN((B5-ROUNDUP(B5*0.1,2)-ROUNDUP(B5*0.05,2))*0.8,2) -> 10.56 | C20: =ROUNDDOWN((C5-ROUNDUP(C5*0.1,2)-ROUNDUP(C5*0.05,2))*0.8,2) -> 10.36 | D20: =ROUNDDOWN((D5-ROUNDUP(D5*0.1,2)-ROUNDUP(D5*0.05,2))*0.8,2) -> 10.73 | E20: =ROUNDDOWN((E5-ROUNDUP(E5*0.1,2)-ROUNDUP(E5*0.05,2))*0.8,2) -> 10.2 | F20: =ROUNDDOWN((F5-ROUNDUP(F5*0.1,2)-ROUNDUP(F5*0.05,2))*0.8,2) -> 10.74 | G20: =ROUNDDOWN((G5-ROUNDUP(G5*0.1,2)-ROUNDUP(G5*0.05,2))*0.8,2) -> 10.51 | H20: =ROUNDDOWN((H5-ROUNDUP(H5*0.1,2)-ROUNDUP(H5*0.05,2))*0.8,2) -> 10.43 | I20: =ROUNDDOWN((I5-ROUNDUP(I5*0.1,2)-ROUNDUP(I5*0.05,2))*0.8,2) -> 10.52 | ... BY20: =ROUNDDOWN((BY5-ROUNDUP(BY5*0.1,2)-ROUNDUP(BY5*0.05,2))*0.8,2) -> 0
A21: Hyper Beast MW | B21: =ROUNDDOWN((B6-ROUNDUP(B6*0.1,2)-ROUNDUP(B6*0.05,2))*0.8,2) -> 14.94 | C21: =ROUNDDOWN((C6-ROUNDUP(C6*0.1,2)-ROUNDUP(C6*0.05,2))*0.8,2) -> 14.3 | D21: =ROUNDDOWN((D6-ROUNDUP(D6*0.1,2)-ROUNDUP(D6*0.05,2))*0.8,2) -> 14.04 | E21: =ROUNDDOWN((E6-ROUNDUP(E6*0.1,2)-ROUNDUP(E6*0.05,2))*0.8,2) -> 13.46 | F21: =ROUNDDOWN((F6-ROUNDUP(F6*0.1,2)-ROUNDUP(F6*0.05,2))*0.8,2) -> 14.41 | G21: =ROUNDDOWN((G6-ROUNDUP(G6*0.1,2)-ROUNDUP(G6*0.05,2))*0.8,2) -> 14.48 | H21: =ROUNDDOWN((H6-ROUNDUP(H6*0.1,2)-ROUNDUP(H6*0.05,2))*0.8,2) -> 14.44 | I21: =ROUNDDOWN((I6-ROUNDUP(I6*0.1,2)-ROUNDUP(I6*0.05,2))*0.8,2) -> 14.31 | ... BY21: =ROUNDDOWN((BY6-ROUNDUP(BY6*0.1,2)-ROUNDUP(BY6*0.05,2))*0.8,2) -> 0
A22: Stattrak Cyrex MW | B22: =ROUNDDOWN((B7-ROUNDUP(B7*0.1,2)-ROUNDUP(B7*0.05,2))*0.8,2) -> 24.61 | C22: =ROUNDDOWN((C7-ROUNDUP(C7*0.1,2)-ROUNDUP(C7*0.05,2))*0.8,2) -> 23.66 | D22: =ROUNDDOWN((D7-ROUNDUP(D7*0.1,2)-ROUNDUP(D7*0.05,2))*0.8,2) -> 22.58 | E22: =ROUNDDOWN((E7-ROUNDUP(E7*0.1,2)-ROUNDUP(E7*0.05,2))*0.8,2) -> 22.64 | F22: =ROUNDDOWN((F7-ROUNDUP(F7*0.1,2)-ROUNDUP(F7*0.05,2))*0.8,2) -> 23.45 | G22: =ROUNDDOWN((G7-ROUNDUP(G7*0.1,2)-ROUNDUP(G7*0.05,2))*0.8,2) -> 22.46 | H22: =ROUNDDOWN((H7-ROUNDUP(H7*0.1,2)-ROUNDUP(H7*0.05,2))*0.8,2) -> 21.28 | I22: =ROUNDDOWN((I7-ROUNDUP(I7*0.1,2)-ROUNDUP(I7*0.05,2))*0.8,2) -> 22.69 | ... BY22: =ROUNDDOWN((BY7-ROUNDUP(BY7*0.1,2)-ROUNDUP(BY7*0.05,2))*0.8,2) -> 0
A23: Flashback FN | B23: =ROUNDDOWN((B8-ROUNDUP(B8*0.1,2)-ROUNDUP(B8*0.05,2))*0.8,2) -> 1.97 | C23: =ROUNDDOWN((C8-ROUNDUP(C8*0.1,2)-ROUNDUP(C8*0.05,2))*0.8,2) -> 2.03 | D23: =ROUNDDOWN((D8-ROUNDUP(D8*0.1,2)-ROUNDUP(D8*0.05,2))*0.8,2) -> 1.96 | E23: =ROUNDDOWN((E8-ROUNDUP(E8*0.1,2)-ROUNDUP(E8*0.05,2))*0.8,2) -> 1.89 | F23: =ROUNDDOWN((F8-ROUNDUP(F8*0.1,2)-ROUNDUP(F8*0.05,2))*0.8,2) -> 1.9 | G23: =ROUNDDOWN((G8-ROUNDUP(G8*0.1,2)-ROUNDUP(G8*0.05,2))*0.8,2) -> 1.96 | H23: =ROUNDDOWN((H8-ROUNDUP(H8*0.1,2)-ROUNDUP(H8*0.05,2))*0.8,2) -> 1.92 | I23: =ROUNDDOWN((I8-ROUNDUP(I8*0.1,2)-ROUNDUP(I8*0.05,2))*0.8,2) -> 1.88 | ... BY23: =ROUNDDOWN((BY8-ROUNDUP(BY8*0.1,2)-ROUNDUP(BY8*0.05,2))*0.8,2) -> 0
B25: =SUM(B20:B23) -> 52.08 | C25: =SUM(C20:C23) -> 50.35 | D25: =SUM(D20:D23) -> 49.31 | E25: =SUM(E20:E23) -> 48.19 | F25: =SUM(F20:F23) -> 50.5 | G25: =SUM(G20:G23) -> 49.41 | H25: =SUM(H20:H23) -> 48.07 | I25: =SUM(I20:I23) -> 49.4 | ... BY25: =SUM(BY20:BY23) -> 0

Sheet AK47
A1: AK47
A3: Name
B4: =Totals!B4 -> 44331 | C4: =Totals!C4 -> 44332 | D4: =Totals!D4 -> 44334 | E4: =Totals!E4 -> 44336 | F4: =Totals!F4 -> 44337 | G4: =Totals!G4 -> 44338 | H4: =Totals!H4 -> 44339 | I4: =Totals!I4 -> 44340 | ... BY4: =Totals!BY4 -> 44408
A5: Redline FT | B5: 18.21 | C5: 18.21 | D5: 18.36 | E5: 18.21 | F5: 18.2 | G5: 18.9 | H5: 17.9 | I5: 18.01 | J5: 18.05 | K5: 18.1 | L5: 18.11 | M5: 17.56 | N5: 18.05 | O5: 17.83 | P5: 17.53 | Q5: 17.33 | R5: 17.55 | S5: 17.43 | T5: 17.56 | U5: 17.63 | V5: 17.88 | W5: 17.63 | X5: 17.45 | Y5: 17.34 | Z5: 17.19 | AA5: 17.07
A6: Vulcan MW | B6: 192.99 | C6: 203.36 | D6: 210.82 | E6: 201.42 | F6: 212.4 | G6: 197.46 | H6: 200.73 | I6: 207.88 | J6: 194.84 | K6: 215.86 | L6: 215.62 | M6: 213.15 | N6: 195.27 | O6: 206.84 | P6: 206.2 | Q6: 217.85 | R6: 214.41 | S6: 219.34 | T6: 226.95 | U6: 265.85 | V6: 250.41 | W6: 246.91 | X6: 251.75 | Y6: 287.68 | Z6: 239.75 | AA6: 239.15
A7: Bloodsport MW | B7: 62.15 | C7: 61.77 | D7: 62.83 | E7: 62.69 | F7: 59.41 | G7: 62.97 | H7: 61.22 | I7: 59.28 | J7: 60 | K7: 61.12 | L7: 60.26 | M7: 60.03 | N7: 60.1 | O7: 61.83 | P7: 63.61 | Q7: 59.98 | R7: 60.1 | S7: 61.21 | T7: 60.3 | U7: 60 | V7: 61.55 | W7: 64.63 | X7: 60.98 | Y7: 60.11 | Z7: 58.2 | AA7: 59.95
A8: Stattrak Point Disarray FT | B8: 37.77 | C8: 40.4 | D8: 39.34 | E8: 38.5 | F8: 40.05 | G8: 39.93 | H8: 38.41 | I8: 38.11 | J8: 37.81 | K8: 37.83 | L8: 39.6 | M8: 39.72 | N8: 39.45 | O8: 35.37 | P8: 38.56 | Q8: 37.05 | R8: 38.83 | S8: 39.65 | T8: 35.33 | U8: 34.11 | V8: 35.04 | W8: 36.93 | X8: 35.82 | Y8: 36.63 | Z8: 37.69 | AA8: 36.58
A9: Frontside Misty MW | B9: 26.57 | C9: 27.42 | D9: 27.83 | E9: 27.26 | F9: 25.67 | G9: 25.26 | H9: 25.26 | I9: 25.88 | J9: 26.82 | K9: 25.54 | L9: 24.7 | M9: 25.46 | N9: 25.22 | O9: 25.89 | P9: 25.22 | Q9: 27.19 | R9: 26.35 | S9: 26 | T9: 25.71 | U9: 26.46 | V9: 26.13 | W9: 26.29 | X9: 27.39 | Y9: 26.62 | Z9: 26.37 | AA9: 25.81
A10: Aquamarine Revenge MW | B10: 47.51 | C10: 47.17 | D10: 49.37 | E10: 48.37 | F10: 46.08 | G10: 44.96 | H10: 46.07 | I10: 45.89 | J10: 44.94 | K10: 45.49 | L10: 46.09 | M10: 45.74 | N10: 45.73 | O10: 44.74 | P10: 44.91 | Q10: 46.13 | R10: 46.46 | S10: 45.58 | T10: 45.39 | U10: 43.55 | V10: 46.01 | W10: 44.97 | X10: 44.91 | Y10: 44.62 | Z10: 45.55 | AA10: 45.62
B12: =SUM(B5:B10) -> 385.2 | C12: =SUM(C5:C10) -> 398.33 | D12: =SUM(D5:D10) -> 408.55 | E12: =SUM(E5:E10) -> 396.45 | F12: =SUM(F5:F10) -> 401.81 | G12: =SUM(G5:G10) -> 389.48 | H12: =SUM(H5:H10) -> 389.59 | I12: =SUM(I5:I10) -> 395.05 | ... BY12: =SUM(BY5:BY10) -> 0
A16: Sale-Value
A18: Name
B19: =B4 -> 44331 | C19: =C4 -> 44332 | D19: =D4 -> 44334 | E19: =E4 -> 44336 | F19: =F4 -> 44337 | G19: =G4 -> 44338 | H19: =H4 -> 44339 | I19: =I4 -> 44340 | ... BY19: =BY4 -> 44408
A20: Redline FT | B20: =ROUNDDOWN((B5-ROUNDUP(B5*0.1,2)-ROUNDUP(B5*0.05,2))*0.8,2) -> 12.36 | C20: =ROUNDDOWN((C5-ROUNDUP(C5*0.1,2)-ROUNDUP(C5*0.05,2))*0.8,2) -> 12.36 | D20: =ROUNDDOWN((D5-ROUNDUP(D5*0.1,2)-ROUNDUP(D5*0.05,2))*0.8,2) -> 12.48 | E20: =ROUNDDOWN((E5-ROUNDUP(E5*0.1,2)-ROUNDUP(E5*0.05,2))*0.8,2) -> 12.36 | F20: =ROUNDDOWN((F5-ROUNDUP(F5*0.1,2)-ROUNDUP(F5*0.05,2))*0.8,2) -> 12.37 | G20: =ROUNDDOWN((G5-ROUNDUP(G5*0.1,2)-ROUNDUP(G5*0.05,2))*0.8,2) -> 12.84 | H20: =ROUNDDOWN((H5-ROUNDUP(H5*0.1,2)-ROUNDUP(H5*0.05,2))*0.8,2) -> 12.16 | I20: =ROUNDDOWN((I5-ROUNDUP(I5*0.1,2)-ROUNDUP(I5*0.05,2))*0.8,2) -> 12.23 | ... BY20: =ROUNDDOWN((BY5-ROUNDUP(BY5*0.1,2)-ROUNDUP(BY5*0.05,2))*0.8,2) -> 0
A21: Vulcan MW | B21: =ROUNDDOWN((B6-ROUNDUP(B6*0.1,2)-ROUNDUP(B6*0.05,2))*0.8,2) -> 131.23 | C21: =ROUNDDOWN((C6-ROUNDUP(C6*0.1,2)-ROUNDUP(C6*0.05,2))*0.8,2) -> 138.28 | D21: =ROUNDDOWN((D6-ROUNDUP(D6*0.1,2)-ROUNDUP(D6*0.05,2))*0.8,2) -> 143.34 | E21: =ROUNDDOWN((E6-ROUNDUP(E6*0.1,2)-ROUNDUP(E6*0.05,2))*0.8,2) -> 136.95 | F21: =ROUNDDOWN((F6-ROUNDUP(F6*0.1,2)-ROUNDUP(F6*0.05,2))*0.8,2) -> 144.43 | G21: =ROUNDDOWN((G6-ROUNDUP(G6*0.1,2)-ROUNDUP(G6*0.05,2))*0.8,2) -> 134.26 | H21: =ROUNDDOWN((H6-ROUNDUP(H6*0.1,2)-ROUNDUP(H6*0.05,2))*0.8,2) -> 136.48 | I21: =ROUNDDOWN((I6-ROUNDUP(I6*0.1,2)-ROUNDUP(I6*0.05,2))*0.8,2) -> 141.35 | ... BY21: =ROUNDDOWN((BY6-ROUNDUP(BY6*0.1,2)-ROUNDUP(BY6*0.05,2))*0.8,2) -> 0
A22: Bloodsport MW | B22: =ROUNDDOWN((B7-ROUNDUP(B7*0.1,2)-ROUNDUP(B7*0.05,2))*0.8,2) -> 42.25 | C22: =ROUNDDOWN((C7-ROUNDUP(C7*0.1,2)-ROUNDUP(C7*0.05,2))*0.8,2) -> 42 | D22: =ROUNDDOWN((D7-ROUNDUP(D7*0.1,2)-ROUNDUP(D7*0.05,2))*0.8,2) -> 42.71 | E22: =ROUNDDOWN((E7-ROUNDUP(E7*0.1,2)-ROUNDUP(E7*0.05,2))*0.8,2) -> 42.62 | F22: =ROUNDDOWN((F7-ROUNDUP(F7*0.1,2)-ROUNDUP(F7*0.05,2))*0.8,2) -> 40.38 | G22: =ROUNDDOWN((G7-ROUNDUP(G7*0.1,2)-ROUNDUP(G7*0.05,2))*0.8,2) -> 42.81 | H22: =ROUNDDOWN((H7-ROUNDUP(H7*0.1,2)-ROUNDUP(H7*0.05,2))*0.8,2) -> 41.61 | I22: =ROUNDDOWN((I7-ROUNDUP(I7*0.1,2)-ROUNDUP(I7*0.05,2))*0.8,2) -> 40.3 | ... BY22: =ROUNDDOWN((BY7-ROUNDUP(BY7*0.1,2)-ROUNDUP(BY7*0.05,2))*0.8,2) -> 0
A23: Stattrak Point Disarray FT | B23: =ROUNDDOWN((B8-ROUNDUP(B8*0.1,2)-ROUNDUP(B8*0.05,2))*0.8,2) -> 25.68 | C23: =ROUNDDOWN((C8-ROUNDUP(C8*0.1,2)-ROUNDUP(C8*0.05,2))*0.8,2) -> 27.47 | D23: =ROUNDDOWN((D8-ROUNDUP(D8*0.1,2)-ROUNDUP(D8*0.05,2))*0.8,2) -> 26.74 | E23: =ROUNDDOWN((E8-ROUNDUP(E8*0.1,2)-ROUNDUP(E8*0.05,2))*0.8,2) -> 26.17 | F23: =ROUNDDOWN((F8-ROUNDUP(F8*0.1,2)-ROUNDUP(F8*0.05,2))*0.8,2) -> 27.22 | G23: =ROUNDDOWN((G8-ROUNDUP(G8*0.1,2)-ROUNDUP(G8*0.05,2))*0.8,2) -> 27.14 | H23: =ROUNDDOWN((H8-ROUNDUP(H8*0.1,2)-ROUNDUP(H8*0.05,2))*0.8,2) -> 26.1 | I23: =ROUNDDOWN((I8-ROUNDUP(I8*0.1,2)-ROUNDUP(I8*0.05,2))*0.8,2) -> 25.9 | ... BY23: =ROUNDDOWN((BY8-ROUNDUP(BY8*0.1,2)-ROUNDUP(BY8*0.05,2))*0.8,2) -> 0
A24: Frontside Misty MW | B24: =ROUNDDOWN((B9-ROUNDUP(B9*0.1,2)-ROUNDUP(B9*0.05,2))*0.8,2) -> 18.06 | C24: =ROUNDDOWN((C9-ROUNDUP(C9*0.1,2)-ROUNDUP(C9*0.05,2))*0.8,2) -> 18.63 | D24: =ROUNDDOWN((D9-ROUNDUP(D9*0.1,2)-ROUNDUP(D9*0.05,2))*0.8,2) -> 18.91 | E24: =ROUNDDOWN((E9-ROUNDUP(E9*0.1,2)-ROUNDUP(E9*0.05,2))*0.8,2) -> 18.52 | F24: =ROUNDDOWN((F9-ROUNDUP(F9*0.1,2)-ROUNDUP(F9*0.05,2))*0.8,2) -> 17.44 | G24: =ROUNDDOWN((G9-ROUNDUP(G9*0.1,2)-ROUNDUP(G9*0.05,2))*0.8,2) -> 17.16 | H24: =ROUNDDOWN((H9-ROUNDUP(H9*0.1,2)-ROUNDUP(H9*0.05,2))*0.8,2) -> 17.16 | I24: =ROUNDDOWN((I9-ROUNDUP(I9*0.1,2)-ROUNDUP(I9*0.05,2))*0.8,2) -> 17.59 | ... BY24: =ROUNDDOWN((BY9-ROUNDUP(BY9*0.1,2)-ROUNDUP(BY9*0.05,2))*0.8,2) -> 0
A25: Aquamarine Revenge MW | B25: =ROUNDDOWN((B10-ROUNDUP(B10*0.1,2)-ROUNDUP(B10*0.05,2))*0.8,2) -> 32.29 | C25: =ROUNDDOWN((C10-ROUNDUP(C10*0.1,2)-ROUNDUP(C10*0.05,2))*0.8,2) -> 32.07 | D25: =ROUNDDOWN((D10-ROUNDUP(D10*0.1,2)-ROUNDUP(D10*0.05,2))*0.8,2) -> 33.56 | E25: =ROUNDDOWN((E10-ROUNDUP(E10*0.1,2)-ROUNDUP(E10*0.05,2))*0.8,2) -> 32.88 | F25: =ROUNDDOWN((F10-ROUNDUP(F10*0.1,2)-ROUNDUP(F10*0.05,2))*0.8,2) -> 31.32 | G25: =ROUNDDOWN((G10-ROUNDUP(G10*0.1,2)-ROUNDUP(G10*0.05,2))*0.8,2) -> 30.56 | H25: =ROUNDDOWN((H10-ROUNDUP(H10*0.1,2)-ROUNDUP(H10*0.05,2))*0.8,2) -> 31.32 | I25: =ROUNDDOWN((I10-ROUNDUP(I10*0.1,2)-ROUNDUP(I10*0.05,2))*0.8,2) -> 31.2 | ... BY25: =ROUNDDOWN((BY10-ROUNDUP(BY10*0.1,2)-ROUNDUP(BY10*0.05,2))*0.8,2) -> 0
B27: =SUM(B20:B25) -> 261.87 | C27: =SUM(C20:C25) -> 270.81 | D27: =SUM(D20:D25) -> 277.74 | E27: =SUM(E20:E25) -> 269.5 | F27: =SUM(F20:F25) -> 273.16 | G27: =SUM(G20:G25) -> 264.77 | H27: =SUM(H20:H25) -> 264.83 | I27: =SUM(I20:I25) -> 268.57 | ... BY27: =SUM(BY20:BY25) -> 0

Sheet SMG
A1: SMG
A3: Name
B4: =Totals!B4 -> 44331 | C4: =Totals!C4 -> 44332 | D4: =Totals!D4 -> 44334 | E4: =Totals!E4 -> 44336 | F4: =Totals!F4 -> 44337 | G4: =Totals!G4 -> 44338 | H4: =Totals!H4 -> 44339 | I4: =Totals!I4 -> 44340 | ... BY4: =Totals!BY4 -> 44408
A5: Stattrak PP-Bizon Osiris FT | B5: 1.46 | C5: 1.44 | D5: 1.44 | E5: 1.39 | F5: 1.47 | G5: 1.44 | H5: 1.43 | I5: 1.39 | J5: 1.43 | K5: 1.53 | L5: 1.54 | M5: 1.57 | N5: 1.65 | O5: 1.61 | P5: 1.61 | Q5: 1.65 | R5: 1.58 | S5: 1.49 | T5: 1.46 | U5: 1.44 | V5: 1.52 | W5: 1.44 | X5: 1.44 | Y5: 1.41 | Z5: 1.4 | AA5: 1.4
A6: P90 Asiimov Ft | B6: 8.36 | C6: 8.05 | D6: 7.84 | E6: 8.07 | F6: 8.7 | G6: 8.58 | H6: 8.42 | I6: 7.84 | J6: 8.1 | K6: 7.68 | L6: 8.07 | M6: 8.23 | N6: 8.78 | O6: 7.94 | P6: 8.46 | Q6: 8.58 | R6: 7.98 | S6: 8.35 | T6: 8.63 | U6: 7.56 | V6: 7.71 | W6: 8.59 | X6: 7.82 | Y6: 7.7 | Z6: 8.24 | AA6: 8.3
A7: Stattrak MP9 Dart MW | B7: 1.73 | C7: 1.74 | D7: 1.61 | E7: 1.72 | F7: 1.73 | G7: 1.65 | H7: 1.69 | I7: 1.75 | J7: 2.09 | K7: 1.77 | L7: 1.72 | M7: 1.69 | N7: 1.63 | O7: 1.49 | P7: 1.75 | Q7: 1.7 | R7: 1.69 | S7: 1.69 | T7: 1.72 | U7: 1.51 | V7: 1.76 | W7: 1.49 | X7: 1.74 | Y7: 1.66 | Z7: 1.67 | AA7: 1.66
A8: Stattrak UMP-45 Primal Saber FT | B8: 4.41 | C8: 4.16 | D8: 4.37 | E8: 4.34 | F8: 3.77 | G8: 4.34 | H8: 3.96 | I8: 4.27 | J8: 4.05 | K8: 3.79 | L8: 3.93 | M8: 3.88 | N8: 4.23 | O8: 3.91 | P8: 4.33 | Q8: 3.93 | R8: 4.08 | S8: 3.75 | T8: 4.19 | U8: 3.74 | V8: 3.62 | W8: 3.54 | X8: 3.74 | Y8: 3.72 | Z8: 3.8 | AA8: 3.88
A9: MP7 Nemesis MW | B9: 5.33 | C9: 5.67 | D9: 5.86 | E9: 5.63 | F9: 5.79 | G9: 5.22 | H9: 5.4 | I9: 5.59 | J9: 5.26 | K9: 6.57 | L9: 5.89 | M9: 5.25 | N9: 5.48 | O9: 5.58 | P9: 5.88 | Q9: 5.53 | R9: 5.66 | S9: 5.03 | T9: 5.91 | U9: 5.42 | V9: 5.63 | W9: 5.48 | X9: 5.52 | Y9: 5.61 | Z9: 5.48 | AA9: 5.46
A10: MP7 Bloodsport MW | B10: 3.63 | C10: 3.61 | D10: 3.63 | E10: 3.49 | F10: 3.84 | G10: 3.54 | H10: 3.57 | I10: 3.54 | J10: 3.75 | K10: 3.79 | L10: 3.49 | M10: 3.61 | N10: 3.39 | O10: 3.53 | P10: 3.4 | Q10: 3.49 | R10: 3.41 | S10: 3.64 | T10: 3.64 | U10: 3.23 | V10: 3.28 | W10: 3.5 | X10: 3.49 | Y10: 3.45 | Z10: 3.27 | AA10: 3.36
A11: UMP-45 Momentum FN | B11: 7.79 | C11: 8.19 | D11: 7.47 | E11: 7.59 | F11: 7.85 | G11: 7.68 | H11: 7.31 | I11: 7.53 | J11: 7.43 | K11: 7.4 | L11: 7.98 | M11: 7.1 | N11: 7.31 | O11: 7.64 | P11: 7.47 | Q11: 7.42 | R11: 7.47 | S11: 7.62 | T11: 7.9 | U11: 7.95 | V11: 7.67 | W11: 8.46 | X11: 7.47 | Y11: 7.65 | Z11: 7.15 | AA11: 8.16
A12: Stattrak MAC-10 Neon Rider MW | B12: 22.48 | C12: 23.47 | D12: 20.71 | E12: 19.8 | F12: 21.98 | G12: 23.47 | H12: 23.57 | I12: 22.65 | J12: 23.03 | K12: 23.07 | L12: 22.67 | M12: 22.71 | N12: 21.96 | O12: 21.29 | P12: 22.8 | Q12: 22.7 | R12: 22.81 | S12: 22.88 | T12: 21.67 | U12: 22.85 | V12: 21.98 | W12: 21.91 | X12: 20.52 | Y12: 21.57 | Z12: 20.88 | AA12: 21.27
A13: MP5-SD Bamboo Garden MW | B13: 0.52 | C13: 0.48 | D13: 0.54 | E13: 0.55 | F13: 0.53 | G13: 0.61 | H13: 0.76 | I13: 0.78 | J13: 0.83 | K13: 1.06 | L13: 1.29 | M13: 1.21 | N13: 1.09 | O13: 1.04 | P13: 0.98 | Q13: 0.93 | R13: 1.01 | S13: 1.08 | T13: 1.23 | U13: 1.41 | V13: 1.31 | W13: 1.18 | X13: 1.26 | Y13: 1.18 | Z13: 1.19 | AA13: 1.21
A14: MAC-10 Malachite MW | B14: 1.5 | C14: 1.45 | D14: 1.4 | E14: 1.39 | F14: 1.51 | G14: 1.54 | H14: 1.46 | I14: 1.55 | J14: 1.55 | K14: 1.51 | L14: 1.49 | M14: 1.5 | N14: 1.51 | O14: 1.54 | P14: 1.54 | Q14: 1.55 | R14: 1.56 | S14: 1.52 | T14: 1.46 | U14: 1.51 | V14: 1.52 | W14: 1.43 | X14: 1.46 | Y14: 1.43 | Z14: 1.45 | AA14: 1.44
A15: MP7 Impire MW | B15: 1.46 | C15: 1.44 | D15: 1.49 | E15: 1.46 | F15: 1.53 | G15: 1.53 | H15: 1.45 | I15: 1.53 | J15: 1.46 | K15: 1.49 | L15: 1.52 | M15: 1.51 | N15: 1.56 | O15: 1.54 | P15: 1.41 | Q15: 1.51 | R15: 1.45 | S15: 1.51 | T15: 1.41 | U15: 1.46 | V15: 1.38 | W15: 1.57 | X15: 1.67 | Y15: 1.64 | Z15: 1.65 | AA15: 1.68
A16: MP9 Hydra MW | B16: 6.38 | C16: 5.63 | D16: 5.7 | E16: 5.94 | F16: 5.87 | G16: 6.21 | H16: 5.92 | I16: 6.18 | J16: 5.84 | K16: 5.87 | L16: 6.07 | M16: 5.77 | N16: 5.94 | O16: 5.78 | P16: 6.27 | Q16: 6.04 | R16: 6.14 | S16: 5.75 | T16: 5.92 | U16: 5.93 | V16: 5.93 | W16: 6 | X16: 5.99 | Y16: 6.03 | Z16: 6.26 | AA16: 5.99
... A18: UMP-45 Plastique MW | B18: 0.8 | C18: 0.83 | D18: 0.82 | E18: 0.76 | F18: 0.82 | G18: 0.83 | H18: 0.84 | I18: 0.84 | J18: 0.84 | K18: 0.83 | L18: 0.85 | M18: 0.85 | N18: 0.87 | O18: 0.85 | P18: 0.83 | Q18: 0.84 | R18: 0.83 | S18: 0.75 | T18: 0.81 | U18: 0.82 | V18: 0.82 | W18: 0.82 | X18: 0.83 | Y18: 0.81 | Z18: 0.82 | AA18: 0.8
B20: =SUM(B5:B18) -> 66.95 | C20: =SUM(C5:C18) -> 67.2 | D20: =SUM(D5:D18) -> 63.86 | E20: =SUM(E5:E18) -> 63.06 | F20: =SUM(F5:F18) -> 66.27 | G20: =SUM(G5:G18) -> 67.62 | H20: =SUM(H5:H18) -> 66.72 | I20: =SUM(I5:I18) -> 66.37 | ... BY20: =SUM(BY5:BY18) -> 0
A24: Sale-Value
A26: Name
B27: =B4 -> 44331 | C27: =C4 -> 44332 | D27: =D4 -> 44334 | E27: =E4 -> 44336 | F27: =F4 -> 44337 | G27: =G4 -> 44338 | H27: =H4 -> 44339 | I27: =I4 -> 44340 | ... BY27: =BY4 -> 44408
