Workbook

Sheet Overview

Sheet Investments

Sheet Category
A1: Cases
A3: Name | B3: Amount | D3: Single Value | E3: Value | F3: Sale-Value | H3: 14-day | I3: Since May 15th 2021 | K3: Profit | L3: Profit/ Investment | N3: Profit/ Investement change last 14days
A4: Prisma | B4: 2000 | D4: =Cases!C36 -> 0.07 | E4: =Cases!C45 -> 140 | F4: =Cases!C62 -> 75 | H4: =Cases!G36 -> 0 | I4: =Cases!F36 -> 0.4 | K4: =Cases!C71 -> -45 | L4: =Cases!F71 -> -0.375 | N4: =Cases!G71 -> 0
A5: Danger Zone | B5: 1000 | D5: =Cases!C37 -> 0.08 | E5: =Cases!C46 -> 80 | F5: =Cases!C63 -> 45 | H5: =Cases!G37 -> 0 | I5: =Cases!F37 -> 0.14285714 | K5: =Cases!C72 -> -25 | L5: =Cases!F72 -> -0.35714286 | N5: =Cases!G72 -> 0
A6: Horizon | B6: 2000 | D6: =Cases!C38 -> 0.12 | E6: =Cases!C47 -> 240 | F6: =Cases!C64 -> 135 | H6: =Cases!G38 -> 0.090909091 | I6: =Cases!F38 -> 0.71428571 | K6: =Cases!C73 -> -65 | L6: =Cases!F73 -> -0.325 | N6: =Cases!G73 -> 0.075
A7: CS20 | B7: 215 | D7: =Cases!C39 -> 0.21 | E7: =Cases!C48 -> 45.15 | F7: =Cases!C65 -> 25.8 | H7: =Cases!G39 -> 0.23529412 | I7: =Cases!F39 -> 1.625 | K7: =Cases!C74 -> 0 | L7: =Cases!F74 -> 0 | N7: =Cases!G74 -> 0.1251938
A8: Fracture | B8: 150 | D8: =Cases!C40 -> 0.31 | E8: =Cases!C49 -> 46.5 | F8: =Cases!C66 -> 28.12 | H8: =Cases!G40 -> -0.03125 | I8: =Cases!F40 -> -0.11428571 | K8: =Cases!C75 -> -57.38 | L8: =Cases!F75 -> -0.67111111 | N8: =Cases!G75 -> -0.013216374
A10: Total | E10: =Cases!C82 -> 551.65 | F10: =Cases!C83 -> 308.92 | H10: =Cases!G82 -> 0.05166333 | I10: =Cases!F82 -> 0.45285752 | K10: =Cases!C86 -> -192.38 | L10: =Cases!F86 -> -0.38376222 | N10: =Cases!G86 -> 0.034111311
A13: Skins
A15: Name | B15: Amount | D15: Single Value | E15: Value | F15: Sale-Value | H15: 14-day | I15: Since May 15th 2021 | K15: Profit | L15: Profit/ Investment | N15: Profit/ Investement change last 14days
A16: M4 Dark Blossom FN | B16: ='Skin-Investments'!A26 -> 48 | D16: ='Skin-Investments'!C3 -> 8.8 | E16: ='Skin-Investments'!C26 -> 422.4 | F16: ='Skin-Investments'!C59 -> 316.8 | H16: ='Skin-Investments'!G15 -> -0.078817734 | I16: ='Skin-Investments'!F15 -> 1.2735562 | K16: ='Skin-Investments'!C70 -> 207.27 | L16: ='Skin-Investments'!F70 -> 1.8923583 | N16: ='Skin-Investments'!G70 -> -0.24979458
A17: M4 Dark Blossom MW | B17: ='Skin-Investments'!A27 -> 10 | D17: ='Skin-Investments'!C4 -> 8.92 | E17: ='Skin-Investments'!C27 -> 89.2 | F17: ='Skin-Investments'!C60 -> 66.9 | H17: ='Skin-Investments'!G16 -> -0.092326139 | I17: ='Skin-Investments'!F16 -> 1.5661017 | K17: ='Skin-Investments'!C71 -> 15.69 | L17: ='Skin-Investments'!F71 -> 0.30638547 | N17: ='Skin-Investments'!G71 -> -0.13278657
A18: P90 Sunset Lily FN | B18: ='Skin-Investments'!A28 -> 5 | D18: ='Skin-Investments'!C5 -> 9.84 | E18: ='Skin-Investments'!C28 -> 49.2 | F18: ='Skin-Investments'!C61 -> 36.9 | H18: ='Skin-Investments'!G17 -> -0.11919831 | I18: ='Skin-Investments'!F17 -> 1.8114478 | K18: ='Skin-Investments'!C72 -> 8.87 | L18: ='Skin-Investments'!F72 -> 0.31644666 | N18: ='Skin-Investments'!G72 -> -0.1765965
A19: Tec-9 Rust Leaf FN | B19: ='Skin-Investments'!A29 -> 7 | D19: ='Skin-Investments'!C6 -> 9.85 | E19: ='Skin-Investments'!C29 -> 68.95 | F19: ='Skin-Investments'!C62 -> 51.66 | H19: ='Skin-Investments'!G18 -> -0.0059453032 | I19: ='Skin-Investments'!F18 -> 1.8243243 | K19: ='Skin-Investments'!C73 -> 13.75 | L19: ='Skin-Investments'!F73 -> 0.36270113 | N19: ='Skin-Investments'!G73 -> -0.0092323925
A20: Tec-9 Rust Leaf MW | B20: ='Skin-Investments'!A30 -> 10 | D20: ='Skin-Investments'!C7 -> 9.11 | E20: ='Skin-Investments'!C30 -> 91.1 | F20: ='Skin-Investments'!C63 -> 68.3 | H20: ='Skin-Investments'!G19 -> -0.060753341 | I20: ='Skin-Investments'!F19 -> 1.5511551 | K20: ='Skin-Investments'!C74 -> 17.16 | L20: ='Skin-Investments'!F74 -> 0.33554947 | N20: ='Skin-Investments'!G74 -> -0.08408291
A21: XM1014 Banana Leaf FN | B21: ='Skin-Investments'!A31 -> 10 | D21: ='Skin-Investments'!C8 -> 10.02 | E21: ='Skin-Investments'!C31 -> 100.2 | F21: ='Skin-Investments'!C64 -> 75.1 | H21: ='Skin-Investments'!G20 -> -0.038461538 | I21: ='Skin-Investments'!F20 -> 1.4216524 | K21: ='Skin-Investments'!C75 -> 17.97 | L21: ='Skin-Investments'!F75 -> 0.31454577 | N21: ='Skin-Investments'!G75 -> -0.050761421
A22: XM1014 Banana Leaf MW | B22: ='Skin-Investments'!A32 -> 6 | D22: ='Skin-Investments'!C9 -> 9.22 | E22: ='Skin-Investments'!C32 -> 55.32 | F22: ='Skin-Investments'!C65 -> 41.46 | H22: ='Skin-Investments'!G21 -> -0.034567901 | I22: ='Skin-Investments'!F21 -> 1.5980066 | K22: ='Skin-Investments'!C76 -> 10.63 | L22: ='Skin-Investments'!F76 -> 0.34479403 | N22: ='Skin-Investments'!G76 -> -0.046707752
A24: Total | E24: ='Skin-Investments'!C79 -> 876.37 | F24: ='Skin-Investments'!C80 -> 657.12 | H24: ='Skin-Investments'!G79 -> -0.068177227 | I24: ='Skin-Investments'!F79 -> 1.4251321 | K24: ='Skin-Investments'!C84 -> 291.34 | L24: ='Skin-Investments'!F84 -> 0.79648969 | N24: ='Skin-Investments'!G84 -> -0.13149981

Sheet Cases
A1: Market Values
C2: Last value | D2: Row number | F2: Since start | G2: 14-day | I2: 44331 | J2: 44332 | K2: 44333 | L2: 44334 | M2: 44335 | N2: 44336 | O2: 44337 | P2: 44338 | Q2: 44339 | R2: 44340 | S2: 44341 | T2: 44342 | U2: 44343 | V2: 44344 | W2: 44345 | X2: 44346 | Y2: 44347 | Z2: 44348 | AA2: 44349 | AB2: 44350 | AC2: 44351 | AD2: 44352 | AE2: 44353 | AF2: 44354 | AG2: 44355 | AH2: 44356 | AI2: 44357 | AJ2: 44358 | AK2: 44359 | AL2: 44360 | AM2: 44361 | AN2: 44362 | AO2: 44363 | AP2: 44364 | AQ2: 44365 | AR2: 44366 | AS2: 44367 | AT2: 44368 | AU2: 44369 | AV2: 44370 | AW2: 44371 | AX2: 44372 | AY2: 44373 | AZ2: 44374 | BA2: 44375 | BB2: 44376 | BC2: 44377 | BD2: 44378 | BE2: 44379 | BF2: 44380 | BG2: 44381 | BH2: 44382 | BI2: 44383 | BJ2: 44384 | BK2: 44385 | BL2: 44386 | BM2: 44387 | BN2: 44388 | BO2: 44389 | BP2: 44390 | BQ2: 44391 | BR2: 44392 | BS2: 44393 | BT2: 44394 | BU2: 44395 | BV2: 44396 | BW2: 44397 | BX2: 44398 | BY2: 44399 | BZ2: 44400 | CA2: 44401 | CB2: 44402 | CC2: 44403 | CD2: 44404 | CE2: 44405 | CF2: 44406 | CG2: 44407 | CH2: 44408 | CI2: 44409 | CJ2: 44410 | CK2: 44411 | CL2: 44412 | CM2: 44413 | CN2: 44414 | CO2: 44415 | CP2: 44416 | CQ2: 44417 | CR2: 44418 | CS2: 44419 | CT2: 44420 | CU2: 44421 | CV2: 44422 | CW2: 44423 | CX2: 44424 | CY2: 44425 | CZ2: 44426 | DA2: 44427 | DB2: 44428 | DC2: 44429 | DD2: 44430 | DE2: 44431 | DF2: 44432 | DG2: 44433 | DH2: 44434 | DI2: 44435 | DJ2: 44436 | DK2: 44437 | DL2: 44438 | DM2: 44439 | DN2: 44440 | DO2: 44441 | DP2: 44442 | DQ2: 44443 | DR2: 44444 | DS2: 44445 | DT2: 44446 | DU2: 44447 | DV2: 44448 | DW2: 44449 | DX2: 44450 | DY2: 44451 | DZ2: 44452 | EA2: 44453 | EB2: 44454 | EC2: 44455 | ED2: 44456 | EE2: 44457 | EF2: 44458 | EG2: 44459 | EH2: 44460 | EI2: 44461 | EJ2: 44462 | EK2: 44463 | EL2: 44464 | EM2: 44465 | EN2: 44466 | EO2: 44467 | EP2: 44468 | EQ2: 44469 | ER2: 44470 | ES2: 44471 | ET2: 44472 | EU2: 44473 | EV2: 44474 | EW2: 44475 | EX2: 44476 | EY2: 44477 | EZ2: 44478 | FA2: 44479 | FB2: 44480 | FC2: 44481 | FD2: 44482 | FE2: 44483 | FF2: 44484 | FG2: 44485 | FH2: 44486 | FI2: 44487 | FJ2: 44488 | FK2: 44489 | FL2: 44490 | FM2: 44491 | FN2: 44492 | FO2: 44493 | FP2: 44494 | FQ2: 44495 | FR2: 44496 | FS2: 44497 | FT2: 44498 | FU2: 44499 | FV2: 44500 | FW2: 44501 | FX2: 44502 | FY2: 44503 | FZ2: 44504 | GA2: 44505
B3: Prisma 2 | C3: {=LOOKUP(2,1/(I3:GA3<>""),I3:GA3)} -> 0.07 | D3: {=SUMPRODUCT(MAX((I3:GA3<>"")*COLUMN(I3:GA3)))} -> 45 | F3: =(C3-I3)/I3 -> 0.4 | G3: {=(C3-IF(ISNA(INDEX(I3:GA3,D3-22)),INDEX(I3:GA3,D3-23),INDEX(I3:GA3,D3-22)))/IF(ISNA(INDEX(I3:GA3,D3-22)),INDEX(I3:GA3,D3-23),INDEX(I3:GA3,D3-22))} -> 0 | I3: 0.05 | J3: 0.05 | L3: 0.05 | N3: 0.06 | O3: 0.06 | P3: 0.06 | Q3: 0.05 | R3: 0.06 | S3: 0.06 | T3: 0.06 | U3: 0.06 | V3: 0.06 | W3: 0.06 | X3: 0.05 | Y3: 0.06 | Z3: 0.06 | AA3: 0.06 | AB3: 0.06 | AC3: 0.07 | AD3: 0.08 | AE3: 0.07 | AF3: 0.08 | AG3: 0.08 | AH3: 0.08 | AI3: 0.08 | AJ3: 0.08 | AK3: 0.08 | AL3: 0.08 | AM3: 0.07 | AO3: 0.07 | AP3: 0.07 | AQ3: 0.07 | AR3: 0.07 | AS3: 0.07
B4: Danger Zone | C4: {=LOOKUP(2,1/(I4:GA4<>""),I4:GA4)} -> 0.08 | D4: {=SUMPRODUCT(MAX((I4:GA4<>"")*COLUMN(I4:GA4)))} -> 45 | F4: =(C4-I4)/I4 -> 0.14285714 | G4: {=(C4-IF(ISNA(INDEX(I4:GA4,D4-22)),INDEX(I4:GA4,D4-23),INDEX(I4:GA4,D4-22)))/IF(ISNA(INDEX(I4:GA4,D4-22)),INDEX(I4:GA4,D4-23),INDEX(I4:GA4,D4-22))} -> 0 | I4: 0.07 | J4: 0.07 | L4: 0.07 | N4: 0.07 | O4: 0.07 | P4: 0.07 | Q4: 0.07 | R4: 0.07 | S4: 0.07 | T4: 0.07 | U4: 0.07 | V4: 0.06 | W4: 0.06 | X4: 0.07 | Y4: 0.07 | Z4: 0.07 | AA4: 0.07 | AB4: 0.07 | AC4: 0.08 | AD4: 0.09 | AE4: 0.08 | AF4: 0.09 | AG4: 0.09 | AH4: 0.08 | AI4: 0.09 | AJ4: 0.09 | AK4: 0.09 | AL4: 0.09 | AM4: 0.09 | AO4: 0.09 | AP4: 0.08 | AQ4: 0.08 | AR4: 0.08 | AS4: 0.08
B5: Prisma | C5: {=LOOKUP(2,1/(I5:GA5<>""),I5:GA5)} -> 0.08 | D5: {=SUMPRODUCT(MAX((I5:GA5<>"")*COLUMN(I5:GA5)))} -> 45 | F5: =(C5-I5)/I5 -> 0.14285714 | G5: {=(C5-IF(ISNA(INDEX(I5:GA5,D5-22)),INDEX(I5:GA5,D5-23),INDEX(I5:GA5,D5-22)))/IF(ISNA(INDEX(I5:GA5,D5-22)),INDEX(I5:GA5,D5-23),INDEX(I5:GA5,D5-22))} -> -0.2 | I5: 0.07 | J5: 0.07 | L5: 0.07 | N5: 0.07 | O5: 0.07 | P5: 0.07 | Q5: 0.07 | R5: 0.07 | S5: 0.07 | T5: 0.07 | U5: 0.07 | V5: 0.07 | W5: 0.07 | X5: 0.07 | Y5: 0.07 | Z5: 0.08 | AA5: 0.08 | AB5: 0.08 | AC5: 0.09 | AD5: 0.12 | AE5: 0.1 | AF5: 0.1 | AG5: 0.09 | AH5: 0.1 | AI5: 0.09 | AJ5: 0.09 | AK5: 0.09 | AL5: 0.09 | AM5: 0.09 | AO5: 0.08 | AP5: 0.08 | AQ5: 0.08 | AR5: 0.08 | AS5: 0.08
B6: Horizon | C6: {=LOOKUP(2,1/(I6:GA6<>""),I6:GA6)} -> 0.12 | D6: {=SUMPRODUCT(MAX((I6:GA6<>"")*COLUMN(I6:GA6)))} -> 45 | F6: =(C6-I6)/I6 -> 0.71428571 | G6: {=(C6-IF(ISNA(INDEX(I6:GA6,D6-22)),INDEX(I6:GA6,D6-23),INDEX(I6:GA6,D6-22)))/IF(ISNA(INDEX(I6:GA6,D6-22)),INDEX(I6:GA6,D6-23),INDEX(I6:GA6,D6-22))} -> 0.090909091 | I6: 0.07 | J6: 0.07 | L6: 0.07 | N6: 0.07 | O6: 0.07 | P6: 0.07 | Q6: 0.07 | R6: 0.07 | S6: 0.07 | T6: 0.07 | U6: 0.07 | V6: 0.07 | W6: 0.07 | X6: 0.07 | Y6: 0.07 | Z6: 0.07 | AA6: 0.07 | AB6: 0.07 | AC6: 0.12 | AD6: 0.14 | AE6: 0.11 | AF6: 0.12 | AG6: 0.12 | AH6: 0.12 | AI6: 0.12 | AJ6: 0.13 | AK6: 0.14 | AL6: 0.13 | AM6: 0.12 | AO6: 0.11 | AP6: 0.11 | AQ6: 0.11 | AR6: 0.12 | AS6: 0.12
B7: CS20 | C7: {=LOOKUP(2,1/(I7:GA7<>""),I7:GA7)} -> 0.21 | D7: {=SUMPRODUCT(MAX((I7:GA7<>"")*COLUMN(I7:GA7)))} -> 45 | F7: =(C7-I7)/I7 -> 1.625 | G7: {=(C7-IF(ISNA(INDEX(I7:GA7,D7-22)),INDEX(I7:GA7,D7-23),INDEX(I7:GA7,D7-22)))/IF(ISNA(INDEX(I7:GA7,D7-22)),INDEX(I7:GA7,D7-23),INDEX(I7:GA7,D7-22))} -> 0.23529412 | I7: 0.08 | J7: 0.08 | L7: 0.08 | N7: 0.08 | O7: 0.08 | P7: 0.08 | Q7: 0.08 | R7: 0.08 | S7: 0.08 | T7: 0.08 | U7: 0.08 | V7: 0.08 | W7: 0.08 | X7: 0.08 | Y7: 0.08 | Z7: 0.08 | AA7: 0.08 | AB7: 0.08 | AC7: 0.16 | AD7: 0.21 | AE7: 0.17 | AF7: 0.18 | AG7: 0.18 | AH7: 0.2 | AI7: 0.23 | AJ7: 0.24 | AK7: 0.28 | AL7: 0.28 | AM7: 0.27 | AO7: 0.23 | AP7: 0.23 | AQ7: 0.21 | AR7: 0.23 | AS7: 0.21
B8: Fracture | C8: {=LOOKUP(2,1/(I8:GA8<>""),I8:GA8)} -> 0.31 | D8: {=SUMPRODUCT(MAX((I8:GA8<>"")*COLUMN(I8:GA8)))} -> 45 | F8: =(C8-I8)/I8 -> -0.11428571 | G8: {=(C8-IF(ISNA(INDEX(I8:GA8,D8-22)),INDEX(I8:GA8,D8-23),INDEX(I8:GA8,D8-22)))/IF(ISNA(INDEX(I8:GA8,D8-22)),INDEX(I8:GA8,D8-23),INDEX(I8:GA8,D8-22))} -> -0.03125 | I8: 0.35 | J8: 0.35 | L8: 0.35 | N8: 0.31 | O8: 0.3 | P8: 0.34 | Q8: 0.3 | R8: 0.3 | S8: 0.31 | T8: 0.3 | U8: 0.31 | V8: 0.3 | W8: 0.32 | X8: 0.32 | Y8: 0.34 | Z8: 0.3 | AA8: 0.32 | AB8: 0.3 | AC8: 0.35 | AD8: 0.35 | AE8: 0.32 | AF8: 0.32 | AG8: 0.3 | AH8: 0.31 | AI8: 0.3 | AJ8: 0.3 | AK8: 0.3 | AL8: 0.31 | AM8: 0.32 | AO8: 0.31 | AP8: 0.29 | AQ8: 0.3 | AR8: 0.32 | AS8: 0.31
B9: Clutch | C9: {=LOOKUP(2,1/(I9:GA9<>""),I9:GA9)} -> 0.34 | D9: {=SUMPRODUCT(MAX((I9:GA9<>"")*COLUMN(I9:GA9)))} -> 45 | F9: =(C9-I9)/I9 -> 0.61904762 | G9: {=(C9-IF(ISNA(INDEX(I9:GA9,D9-22)),INDEX(I9:GA9,D9-23),INDEX(I9:GA9,D9-22)))/IF(ISNA(INDEX(I9:GA9,D9-22)),INDEX(I9:GA9,D9-23),INDEX(I9:GA9,D9-22))} -> 0.13333333 | I9: 0.21 | J9: 0.21 | L9: 0.21 | N9: 0.21 | O9: 0.21 | P9: 0.21 | Q9: 0.21 | R9: 0.21 | S9: 0.21 | T9: 0.2 | U9: 0.2 | V9: 0.21 | W9: 0.21 | X9: 0.24 | Y9: 0.24 | Z9: 0.24 | AA9: 0.26 | AB9: 0.27 | AC9: 0.34 | AD9: 0.43 | AE9: 0.3 | AF9: 0.31 | AG9: 0.34 | AH9: 0.31 | AI9: 0.36 | AJ9: 0.38 | AK9: 0.36 | AL9: 0.36 | AM9: 0.34 | AO9: 0.32 | AP9: 0.3 | AQ9: 0.31 | AR9: 0.34 | AS9: 0.34
B10: Spectrum 2 | C10: {=LOOKUP(2,1/(I10:GA10<>""),I10:GA10)} -> 0.37 | D10: {=SUMPRODUCT(MAX((I10:GA10<>"")*COLUMN(I10:GA10)))} -> 45 | F10: =(C10-I10)/I10 -> 1.1764706 | G10: {=(C10-IF(ISNA(INDEX(I10:GA10,D10-22)),INDEX(I10:GA10,D10-23),INDEX(I10:GA10,D10-22)))/IF(ISNA(INDEX(I10:GA10,D10-22)),INDEX(I10:GA10,D10-23),INDEX(I10:GA10,D10-22))} -> 0.088235294 | I10: 0.17 | J10: 0.17 | L10: 0.19 | N10: 0.19 | O10: 0.17 | P10: 0.18 | Q10: 0.18 | R10: 0.17 | S10: 0.17 | T10: 0.18 | U10: 0.18 | V10: 0.19 | W10: 0.2 | X10: 0.21 | Y10: 0.21 | Z10: 0.24 | AA10: 0.24 | AB10: 0.23 | AC10: 0.34 | AD10: 0.39 | AE10: 0.34 | AF10: 0.36 | AG10: 0.36 | AH10: 0.37 | AI10: 0.36 | AJ10: 0.38 | AK10: 0.4 | AL10: 0.39 | AM10: 0.37 | AO10: 0.36 | AP10: 0.37 | AQ10: 0.37 | AR10: 0.36 | AS10: 0.37
B11: Spectrum | C11: {=LOOKUP(2,1/(I11:GA11<>""),I11:GA11)} -> 0.7 | D11: {=SUMPRODUCT(MAX((I11:GA11<>"")*COLUMN(I11:GA11)))} -> 45 | F11: =(C11-I11)/I11 -> 0.18644068 | G11: {=(C11-IF(ISNA(INDEX(I11:GA11,D11-22)),INDEX(I11:GA11,D11-23),INDEX(I11:GA11,D11-22)))/IF(ISNA(INDEX(I11:GA11,D11-22)),INDEX(I11:GA11,D11-23),INDEX(I11:GA11,D11-22))} -> -0.04109589 | I11: 0.59 | J11: 0.58 | L11: 0.55 | N11: 0.53 | O11: 0.6 | P11: 0.6 | Q11: 0.6 | R11: 0.61 | S11: 0.58 | T11: 0.61 | U11: 0.58 | V11: 0.62 | W11: 0.65 | X11: 0.66 | Y11: 0.65 | Z11: 0.66 | AA11: 0.64 | AB11: 0.64 | AC11: 0.72 | AD11: 0.86 | AE11: 0.73 | AF11: 0.64 | AG11: 0.65 | AH11: 0.74 | AI11: 0.71 | AJ11: 0.72 | AK11: 0.72 | AL11: 0.73 | AM11: 0.66 | AO11: 0.62 | AP11: 0.63 | AQ11: 0.72 | AR11: 0.69 | AS11: 0.7
B12: Shattered Web | C12: {=LOOKUP(2,1/(I12:GA12<>""),I12:GA12)} -> 1.28 | D12: {=SUMPRODUCT(MAX((I12:GA12<>"")*COLUMN(I12:GA12)))} -> 45 | F12: =(C12-I12)/I12 -> 0.14285714 | G12: {=(C12-IF(ISNA(INDEX(I12:GA12,D12-22)),INDEX(I12:GA12,D12-23),INDEX(I12:GA12,D12-22)))/IF(ISNA(INDEX(I12:GA12,D12-22)),INDEX(I12:GA12,D12-23),INDEX(I12:GA12,D12-22))} -> -0.12328767 | I12: 1.12 | J12: 1.12 | L12: 1.2 | N12: 1.24 | O12: 1.21 | P12: 1.26 | Q12: 1.27 | R12: 1.31 | S12: 1.53 | T12: 1.45 | U12: 1.51 | V12: 1.49 | W12: 1.41 | X12: 1.39 | Y12: 1.31 | Z12: 1.34 | AA12: 1.31 | AB12: 1.35 | AC12: 1.35 | AD12: 1.35 | AE12: 1.46 | AF12: 1.46 | AG12: 1.42 | AH12: 1.49 | AI12: 1.33 | AJ12: 1.41 | AK12: 1.35 | AL12: 1.44 | AM12: 1.41 | AO12: 1.24 | AP12: 1.3 | AQ12: 1.35 | AR12: 1.32 | AS12: 1.28
A19: Sale Revenue
I20: =I2 -> 44331 | J20: =J2 -> 44332 | K20: =K2 -> 44333 | L20: =L2 -> 44334 | M20: =M2 -> 44335 | N20: =N2 -> 44336 | O20: =O2 -> 44337 | P20: =P2 -> 44338 | ... GA20: =GA2 -> 44505
B21: Prisma 2 | C21: {=LOOKUP(2,1/(I21:GA21<>""),I21:GA21)} -> 0.05 | D21: =D$12 -> 45 | F21: =(C21-I21)/I21 -> 0.66666667 | G21: {=(C21-IF(ISNA(INDEX(I21:GA21,D21-22)),INDEX(I21:GA21,D21-23),INDEX(I21:GA21,D21-22)))/IF(ISNA(INDEX(I21:GA21,D21-22)),INDEX(I21:GA21,D21-23),INDEX(I21:GA21,D21-22))} -> 0 | I21: =IF(I3=0,NA(),I3-ROUNDUP(I3*0.1,2)-ROUNDUP(I3*0.05,2)) -> 0.03 | J21: =IF(J3=0,NA(),J3-ROUNDUP(J3*0.1,2)-ROUNDUP(J3*0.05,2)) -> 0.03 | K21: =IF(K3=0,NA(),K3-ROUNDUP(K3*0.1,2)-ROUNDUP(K3*0.05,2)) -> #N/A | L21: =IF(L3=0,NA(),L3-ROUNDUP(L3*0.1,2)-ROUNDUP(L3*0.05,2)) -> 0.03 | M21: =IF(M3=0,NA(),M3-ROUNDUP(M3*0.1,2)-ROUNDUP(M3*0.05,2)) -> #N/A | N21: =IF(N3=0,NA(),N3-ROUNDUP(N3*0.1,2)-ROUNDUP(N3*0.05,2)) -> 0.04 | O21: =IF(O3=0,NA(),O3-ROUNDUP(O3*0.1,2)-ROUNDUP(O3*0.05,2)) -> 0.04 | P21: =IF(P3=0,NA(),P3-ROUNDUP(P3*0.1,2)-ROUNDUP(P3*0.05,2)) -> 0.04 | ... GA21: =IF(GA3=0,NA(),GA3-ROUNDUP(GA3*0.1,2)-ROUNDUP(GA3*0.05,2)) -> #N/A
B22: Danger Zone | C22: {=LOOKUP(2,1/(I22:GA22<>""),I22:GA22)} -> 0.06 | D22: =D$12 -> 45 | F22: =(C22-I22)/I22 -> 0.2 | G22: {=(C22-IF(ISNA(INDEX(I22:GA22,D22-22)),INDEX(I22:GA22,D22-23),INDEX(I22:GA22,D22-22)))/IF(ISNA(INDEX(I22:GA22,D22-22)),INDEX(I22:GA22,D22-23),INDEX(I22:GA22,D22-22))} -> 0 | I22: =IF(I4=0,NA(),I4-ROUNDUP(I4*0.1,2)-ROUNDUP(I4*0.05,2)) -> 0.05 | J22: =IF(J4=0,NA(),J4-ROUNDUP(J4*0.1,2)-ROUNDUP(J4*0.05,2)) -> 0.05 | K22: =IF(K4=0,NA(),K4-ROUNDUP(K4*0.1,2)-ROUNDUP(K4*0.05,2)) -> #N/A | L22: =IF(L4=0,NA(),L4-ROUNDUP(L4*0.1,2)-ROUNDUP(L4*0.05,2)) -> 0.05 | M22: =IF(M4=0,NA(),M4-ROUNDUP(M4*0.1,2)-ROUNDUP(M4*0.05,2)) -> #N/A | N22: =IF(N4=0,NA(),N4-ROUNDUP(N4*0.1,2)-ROUNDUP(N4*0.05,2)) -> 0.05 | O22: =IF(O4=0,NA(),O4-ROUNDUP(O4*0.1,2)-ROUNDUP(O4*0.05,2)) -> 0.05 | P22: =IF(P4=0,NA(),P4-ROUNDUP(P4*0.1,2)-ROUNDUP(P4*0.05,2)) -> 0.05 | ... GA22: =IF(GA4=0,NA(),GA4-ROUNDUP(GA4*0.1,2)-ROUNDUP(GA4*0.05,2)) -> #N/A
B23: Prisma | C23: {=LOOKUP(2,1/(I23:GA23<>""),I23:GA23)} -> 0.06 | D23: =D$12 -> 45 | F23: =(C23-I23)/I23 -> 0.2 | G23: {=(C23-IF(ISNA(INDEX(I23:GA23,D23-22)),INDEX(I23:GA23,D23-23),INDEX(I23:GA23,D23-22)))/IF(ISNA(INDEX(I23:GA23,D23-22)),INDEX(I23:GA23,D23-23),INDEX(I23:GA23,D23-22))} -> -0.25 | I23: =IF(I5=0,NA(),I5-ROUNDUP(I5*0.1,2)-ROUNDUP(I5*0.05,2)) -> 0.05 | J23: =IF(J5=0,NA(),J5-ROUNDUP(J5*0.1,2)-ROUNDUP(J5*0.05,2)) -> 0.05 | K23: =IF(K5=0,NA(),K5-ROUNDUP(K5*0.1,2)-ROUNDUP(K5*0.05,2)) -> #N/A | L23: =IF(L5=0,NA(),L5-ROUNDUP(L5*0.1,2)-ROUNDUP(L5*0.05,2)) -> 0.05 | M23: =IF(M5=0,NA(),M5-ROUNDUP(M5*0.1,2)-ROUNDUP(M5*0.05,2)) -> #N/A | N23: =IF(N5=0,NA(),N5-ROUNDUP(N5*0.1,2)-ROUNDUP(N5*0.05,2)) -> 0.05 | O23: =IF(O5=0,NA(),O5-ROUNDUP(O5*0.1,2)-ROUNDUP(O5*0.05,2)) -> 0.05 | P23: =IF(P5=0,NA(),P5-ROUNDUP(P5*0.1,2)-ROUNDUP(P5*0.05,2)) -> 0.05 | ... GA23: =IF(GA5=0,NA(),GA5-ROUNDUP(GA5*0.1,2)-ROUNDUP(GA5*0.05,2)) -> #N/A
B24: Horizon | C24: {=LOOKUP(2,1/(I24:GA24<>""),I24:GA24)} -> 0.09 | D24: =D$12 -> 45 | F24: =(C24-I24)/I24 -> 0.8 | G24: {=(C24-IF(ISNA(INDEX(I24:GA24,D24-22)),INDEX(I24:GA24,D24-23),INDEX(I24:GA24,D24-22)))/IF(ISNA(INDEX(I24:GA24,D24-22)),INDEX(I24:GA24,D24-23),INDEX(I24:GA24,D24-22))} -> 0.125 | I24: =IF(I6=0,NA(),I6-ROUNDUP(I6*0.1,2)-ROUNDUP(I6*0.05,2)) -> 0.05 | J24: =IF(J6=0,NA(),J6-ROUNDUP(J6*0.1,2)-ROUNDUP(J6*0.05,2)) -> 0.05 | K24: =IF(K6=0,NA(),K6-ROUNDUP(K6*0.1,2)-ROUNDUP(K6*0.05,2)) -> #N/A | L24: =IF(L6=0,NA(),L6-ROUNDUP(L6*0.1,2)-ROUNDUP(L6*0.05,2)) -> 0.05 | M24: =IF(M6=0,NA(),M6-ROUNDUP(M6*0.1,2)-ROUNDUP(M6*0.05,2)) -> #N/A | N24: =IF(N6=0,NA(),N6-ROUNDUP(N6*0.1,2)-ROUNDUP(N6*0.05,2)) -> 0.05 | O24: =IF(O6=0,NA(),O6-ROUNDUP(O6*0.1,2)-ROUNDUP(O6*0.05,2)) -> 0.05 | P24: =IF(P6=0,NA(),P6-ROUNDUP(P6*0.1,2)-ROUNDUP(P6*0.05,2)) -> 0.05 | ... GA24: =IF(GA6=0,NA(),GA6-ROUNDUP(GA6*0.1,2)-ROUNDUP(GA6*0.05,2)) -> #N/A
B25: CS20 | C25: {=LOOKUP(2,1/(I25:GA25<>""),I25:GA25)} -> 0.16 | D25: =D$12 -> 45 | F25: =(C25-I25)/I25 -> 1.6666667 | G25: {=(C25-IF(ISNA(INDEX(I25:GA25,D25-22)),INDEX(I25:GA25,D25-23),INDEX(I25:GA25,D25-22)))/IF(ISNA(INDEX(I25:GA25,D25-22)),INDEX(I25:GA25,D25-23),INDEX(I25:GA25,D25-22))} -> 0.14285714 | I25: =IF(I7=0,NA(),I7-ROUNDUP(I7*0.1,2)-ROUNDUP(I7*0.05,2)) -> 0.06 | J25: =IF(J7=0,NA(),J7-ROUNDUP(J7*0.1,2)-ROUNDUP(J7*0.05,2)) -> 0.06 | K25: =IF(K7=0,NA(),K7-ROUNDUP(K7*0.1,2)-ROUNDUP(K7*0.05,2)) -> #N/A | L25: =IF(L7=0,NA(),L7-ROUNDUP(L7*0.1,2)-ROUNDUP(L7*0.05,2)) -> 0.06 | M25: =IF(M7=0,NA(),M7-ROUNDUP(M7*0.1,2)-ROUNDUP(M7*0.05,2)) -> #N/A | N25: =IF(N7=0,NA(),N7-ROUNDUP(N7*0.1,2)-ROUNDUP(N7*0.05,2)) -> 0.06 | O25: =IF(O7=0,NA(),O7-ROUNDUP(O7*0.1,2)-ROUNDUP(O7*0.05,2)) -> 0.06 | P25: =IF(P7=0,NA(),P7-ROUNDUP(P7*0.1,2)-ROUNDUP(P7*0.05,2)) -> 0.06 | ... GA25: =IF(GA7=0,NA(),GA7-ROUNDUP(GA7*0.1,2)-ROUNDUP(GA7*0.05,2)) -> #N/A
B26: Fracture | C26: {=LOOKUP(2,1/(I26:GA26<>""),I26:GA26)} -> 0.25 | D26: =D$12 -> 45 | F26: =(C26-I26)/I26 -> -0.13793103 | G26: {=(C26-IF(ISNA(INDEX(I26:GA26,D26-22)),INDEX(I26:GA26,D26-23),INDEX(I26:GA26,D26-22)))/IF(ISNA(INDEX(I26:GA26,D26-22)),INDEX(I26:GA26,D26-23),INDEX(I26:GA26,D26-22))} -> -0.038461538 | I26: =IF(I8=0,NA(),I8-ROUNDUP(I8*0.1,2)-ROUNDUP(I8*0.05,2)) -> 0.29 | J26: =IF(J8=0,NA(),J8-ROUNDUP(J8*0.1,2)-ROUNDUP(J8*0.05,2)) -> 0.29 | K26: =IF(K8=0,NA(),K8-ROUNDUP(K8*0.1,2)-ROUNDUP(K8*0.05,2)) -> #N/A | L26: =IF(L8=0,NA(),L8-ROUNDUP(L8*0.1,2)-ROUNDUP(L8*0.05,2)) -> 0.29 | M26: =IF(M8=0,NA(),M8-ROUNDUP(M8*0.1,2)-ROUNDUP(M8*0.05,2)) -> #N/A | N26: =IF(N8=0,NA(),N8-ROUNDUP(N8*0.1,2)-ROUNDUP(N8*0.05,2)) -> 0.25 | O26: =IF(O8=0,NA(),O8-ROUNDUP(O8*0.1,2)-ROUNDUP(O8*0.05,2)) -> 0.25 | P26: =IF(P8=0,NA(),P8-ROUNDUP(P8*0.1,2)-ROUNDUP(P8*0.05,2)) -> 0.28 | ... GA26: =IF(GA8=0,NA(),GA8-ROUNDUP(GA8*0.1,2)-ROUNDUP(GA8*0.05,2)) -> #N/A
B27: Clutch | C27: {=LOOKUP(2,1/(I27:GA27<>""),I27:GA27)} -> 0.28 | D27: =D$12 -> 45 | F27: =(C27-I27)/I27 -> 0.75 | G27: {=(C27-IF(ISNA(INDEX(I27:GA27,D27-22)),INDEX(I27:GA27,D27-23),INDEX(I27:GA27,D27-22)))/IF(ISNA(INDEX(I27:GA27,D27-22)),INDEX(I27:GA27,D27-23),INDEX(I27:GA27,D27-22))} -> 0.12 | I27: =IF(I9=0,NA(),I9-ROUNDUP(I9*0.1,2)-ROUNDUP(I9*0.05,2)) -> 0.16 | J27: =IF(J9=0,NA(),J9-ROUNDUP(J9*0.1,2)-ROUNDUP(J9*0.05,2)) -> 0.16 | K27: =IF(K9=0,NA(),K9-ROUNDUP(K9*0.1,2)-ROUNDUP(K9*0.05,2)) -> #N/A | L27: =IF(L9=0,NA(),L9-ROUNDUP(L9*0.1,2)-ROUNDUP(L9*0.05,2)) -> 0.16 | M27: =IF(M9=0,NA(),M9-ROUNDUP(M9*0.1,2)-ROUNDUP(M9*0.05,2)) -> #N/A | N27: =IF(N9=0,NA(),N9-ROUNDUP(N9*0.1,2)-ROUNDUP(N9*0.05,2)) -> 0.16 | O27: =IF(O9=0,NA(),O9-ROUNDUP(O9*0.1,2)-ROUNDUP(O9*0.05,2)) -> 0.16 | P27: =IF(P9=0,NA(),P9-ROUNDUP(P9*0.1,2)-ROUNDUP(P9*0.05,2)) -> 0.16 | ... GA27: =IF(GA9=0,NA(),GA9-ROUNDUP(GA9*0.1,2)-ROUNDUP(GA9*0.05,2)) -> #N/A
B28: Spectrum 2 | C28: {=LOOKUP(2,1/(I28:GA28<>""),I28:GA28)} -> 0.31 | D28: =D$12 -> 45 | F28: =(C28-I28)/I28 -> 1.2142857 | G28: {=(C28-IF(ISNA(INDEX(I28:GA28,D28-22)),INDEX(I28:GA28,D28-23),INDEX(I28:GA28,D28-22)))/IF(ISNA(INDEX(I28:GA28,D28-22)),INDEX(I28:GA28,D28-23),INDEX(I28:GA28,D28-22))} -> 0.10714286 | I28: =IF(I10=0,NA(),I10-ROUNDUP(I10*0.1,2)-ROUNDUP(I10*0.05,2)) -> 0.14 | J28: =IF(J10=0,NA(),J10-ROUNDUP(J10*0.1,2)-ROUNDUP(J10*0.05,2)) -> 0.14 | K28: =IF(K10=0,NA(),K10-ROUNDUP(K10*0.1,2)-ROUNDUP(K10*0.05,2)) -> #N/A | L28: =IF(L10=0,NA(),L10-ROUNDUP(L10*0.1,2)-ROUNDUP(L10*0.05,2)) -> 0.16 | M28: =IF(M10=0,NA(),M10-ROUNDUP(M10*0.1,2)-ROUNDUP(M10*0.05,2)) -> #N/A | N28: =IF(N10=0,NA(),N10-ROUNDUP(N10*0.1,2)-ROUNDUP(N10*0.05,2)) -> 0.16 | O28: =IF(O10=0,NA(),O10-ROUNDUP(O10*0.1,2)-ROUNDUP(O10*0.05,2)) -> 0.14 | P28: =IF(P10=0,NA(),P10-ROUNDUP(P10*0.1,2)-ROUNDUP(P10*0.05,2)) -> 0.15 | ... GA28: =IF(GA10=0,NA(),GA10-ROUNDUP(GA10*0.1,2)-ROUNDUP(GA10*0.05,2)) -> #N/A
B29: Spectrum | C29: {=LOOKUP(2,1/(I29:GA29<>""),I29:GA29)} -> 0.59 | D29: =D$12 -> 45 | F29: =(C29-I29)/I29 -> 0.18 | G29: {=(C29-IF(ISNA(INDEX(I29:GA29,D29-22)),INDEX(I29:GA29,D29-23),INDEX(I29:GA29,D29-22)))/IF(ISNA(INDEX(I29:GA29,D29-22)),INDEX(I29:GA29,D29-23),INDEX(I29:GA29,D29-22))} -> -0.032786885 | I29: =IF(I11=0,NA(),I11-ROUNDUP(I11*0.1,2)-ROUNDUP(I11*0.05,2)) -> 0.5 | J29: =IF(J11=0,NA(),J11-ROUNDUP(J11*0.1,2)-ROUNDUP(J11*0.05,2)) -> 0.49 | K29: =IF(K11=0,NA(),K11-ROUNDUP(K11*0.1,2)-ROUNDUP(K11*0.05,2)) -> #N/A | L29: =IF(L11=0,NA(),L11-ROUNDUP(L11*0.1,2)-ROUNDUP(L11*0.05,2)) -> 0.46 | M29: =IF(M11=0,NA(),M11-ROUNDUP(M11*0.1,2)-ROUNDUP(M11*0.05,2)) -> #N/A | N29: =IF(N11=0,NA(),N11-ROUNDUP(N11*0.1,2)-ROUNDUP(N11*0.05,2)) -> 0.44 | O29: =IF(O11=0,NA(),O11-ROUNDUP(O11*0.1,2)-ROUNDUP(O11*0.05,2)) -> 0.51 | P29: =IF(P11=0,NA(),P11-ROUNDUP(P11*0.1,2)-ROUNDUP(P11*0.05,2)) -> 0.51 | ... GA29: =IF(GA11=0,NA(),GA11-ROUNDUP(GA11*0.1,2)-ROUNDUP(GA11*0.05,2)) -> #N/A
B30: Shattered Web | C30: {=LOOKUP(2,1/(I30:GA30<>""),I30:GA30)} -> 1.08 | D30: =D$12 -> 45 | F30: =(C30-I30)/I30 -> 0.14893617 | G30: {=(C30-IF(ISNA(INDEX(I30:GA30,D30-22)),INDEX(I30:GA30,D30-23),INDEX(I30:GA30,D30-22)))/IF(ISNA(INDEX(I30:GA30,D30-22)),INDEX(I30:GA30,D30-23),INDEX(I30:GA30,D30-22))} -> -0.12195122 | I30: =IF(I12=0,NA(),I12-ROUNDUP(I12*0.1,2)-ROUNDUP(I12*0.05,2)) -> 0.94 | J30: =IF(J12=0,NA(),J12-ROUNDUP(J12*0.1,2)-ROUNDUP(J12*0.05,2)) -> 0.94 | K30: =IF(K12=0,NA(),K12-ROUNDUP(K12*0.1,2)-ROUNDUP(K12*0.05,2)) -> #N/A | L30: =IF(L12=0,NA(),L12-ROUNDUP(L12*0.1,2)-ROUNDUP(L12*0.05,2)) -> 1.02 | M30: =IF(M12=0,NA(),M12-ROUNDUP(M12*0.1,2)-ROUNDUP(M12*0.05,2)) -> #N/A | N30: =IF(N12=0,NA(),N12-ROUNDUP(N12*0.1,2)-ROUNDUP(N12*0.05,2)) -> 1.04 | O30: =IF(O12=0,NA(),O12-ROUNDUP(O12*0.1,2)-ROUNDUP(O12*0.05,2)) -> 1.01 | P30: =IF(P12=0,NA(),P12-ROUNDUP(P12*0.1,2)-ROUNDUP(P12*0.05,2)) -> 1.06 | ... GA30: =IF(GA12=0,NA(),GA12-ROUNDUP(GA12*0.1,2)-ROUNDUP(GA12*0.05,2)) -> #N/A
A34: Investments
I35: =I20 -> 44331 | J35: =J20 -> 44332 | K35: =K20 -> 44333 | L35: =L20 -> 44334 | M35: =M20 -> 44335 | N35: =N20 -> 44336 | O35: =O20 -> 44337 | P35: =P20 -> 44338 | ... GA35: =GA20 -> 44505
A36: 2000 | B36: Prisma 2 | C36: {=LOOKUP(2,1/(I36:GA36<>""),I36:GA36)} -> 0.07 | D36: =D$12 -> 45 | F36: =(C36-I36)/I36 -> 0.4 | G36: {=(C36-IF(ISNA(INDEX(I36:GA36,D36-22)),INDEX(I36:GA36,D36-23),INDEX(I36:GA36,D36-22)))/IF(ISNA(INDEX(I36:GA36,D36-22)),INDEX(I36:GA36,D36-23),INDEX(I36:GA36,D36-22))} -> 0 | I36: =IF($B36=$B$3,IF(ISBLANK(I$3),NA(),I$3),IF($B36=$B$4,IF(ISBLANK(I$4),NA(),I$4),IF($B36=$B$5,IF(ISBLANK(I$5),NA(),I$5),IF($B36=$B$6,IF(ISBLANK(I$6),NA(),I$6),IF($B36=$B$7,IF(ISBLANK(I$7),NA(),I$7),IF($B36=$B$8,IF(ISBLANK(I$8),NA(),I$8),IF($B36=$B$9,IF(ISBLANK(I$9),NA(),I$9),IF($B36=$B$10,IF(ISBLANK(I$10),NA(),I$10),IF($B36=$B$11,IF(ISBLANK(I$11),NA(),I$11),IF($B36=$B$12,IF(ISBLANK(I$12),NA(),I$12),0)))))))))) -> 0.05 | J36: =IF($B36=$B$3,IF(ISBLANK(J$3),NA(),J$3),IF($B36=$B$4,IF(ISBLANK(J$4),NA(),J$4),IF($B36=$B$5,IF(ISBLANK(J$5),NA(),J$5),IF($B36=$B$6,IF(ISBLANK(J$6),NA(),J$6),IF($B36=$B$7,IF(ISBLANK(J$7),NA(),J$7),IF($B36=$B$8,IF(ISBLANK(J$8),NA(),J$8),IF($B36=$B$9,IF(ISBLANK(J$9),NA(),J$9),IF($B36=$B$10,IF(ISBLANK(J$10),NA(),J$10),IF($B36=$B$11,IF(ISBLANK(J$11),NA(),J$11),IF($B36=$B$12,IF(ISBLANK(J$12),NA(),J$12),0)))))))))) -> 0.05 | K36: =IF($B36=$B$3,IF(ISBLANK(K$3),NA(),K$3),IF($B36=$B$4,IF(ISBLANK(K$4),NA(),K$4),IF($B36=$B$5,IF(ISBLANK(K$5),NA(),K$5),IF($B36=$B$6,IF(ISBLANK(K$6),NA(),K$6),IF($B36=$B$7,IF(ISBLANK(K$7),NA(),K$7),IF($B36=$B$8,IF(ISBLANK(K$8),NA(),K$8),IF($B36=$B$9,IF(ISBLANK(K$9),NA(),K$9),IF($B36=$B$10,IF(ISBLANK(K$10),NA(),K$10),IF($B36=$B$11,IF(ISBLANK(K$11),NA(),K$11),IF($B36=$B$12,IF(ISBLANK(K$12),NA(),K$12),0)))))))))) -> #N/A | L36: =IF($B36=$B$3,IF(ISBLANK(L$3),NA(),L$3),IF($B36=$B$4,IF(ISBLANK(L$4),NA(),L$4),IF($B36=$B$5,IF(ISBLANK(L$5),NA(),L$5),IF($B36=$B$6,IF(ISBLANK(L$6),NA(),L$6),IF($B36=$B$7,IF(ISBLANK(L$7),NA(),L$7),IF($B36=$B$8,IF(ISBLANK(L$8),NA(),L$8),IF($B36=$B$9,IF(ISBLANK(L$9),NA(),L$9),IF($B36=$B$10,IF(ISBLANK(L$10),NA(),L$10),IF($B36=$B$11,IF(ISBLANK(L$11),NA(),L$11),IF($B36=$B$12,IF(ISBLANK(L$12),NA(),L$12),0)))))))))) -> 0.05 | M36: =IF($B36=$B$3,IF(ISBLANK(M$3),NA(),M$3),IF($B36=$B$4,IF(ISBLANK(M$4),NA(),M$4),IF($B36=$B$5,IF(ISBLANK(M$5),NA(),M$5),IF($B36=$B$6,IF(ISBLANK(M$6),NA(),M$6),IF($B36=$B$7,IF(ISBLANK(M$7),NA(),M$7),IF($B36=$B$8,IF(ISBLANK(M$8),NA(),M$8),IF($B36=$B$9,IF(ISBLANK(M$9),NA(),M$9),IF($B36=$B$10,IF(ISBLANK(M$10),NA(),M$10),IF($B36=$B$11,IF(ISBLANK(M$11),NA(),M$11),IF($B36=$B$12,IF(ISBLANK(M$12),NA(),M$12),0)))))))))) -> #N/A | N36: =IF($B36=$B$3,IF(ISBLANK(N$3),NA(),N$3),IF($B36=$B$4,IF(ISBLANK(N$4),NA(),N$4),IF($B36=$B$5,IF(ISBLANK(N$5),NA(),N$5),IF($B36=$B$6,IF(ISBLANK(N$6),NA(),N$6),IF($B36=$B$7,IF(ISBLANK(N$7),NA(),N$7),IF($B36=$B$8,IF(ISBLANK(N$8),NA(),N$8),IF($B36=$B$9,IF(ISBLANK(N$9),NA(),N$9),IF($B36=$B$10,IF(ISBLANK(N$10),NA(),N$10),IF($B36=$B$11,IF(ISBLANK(N$11),NA(),N$11),IF($B36=$B$12,IF(ISBLANK(N$12),NA(),N$12),0)))))))))) -> 0.06 | O36: =IF($B36=$B$3,IF(ISBLANK(O$3),NA(),O$3),IF($B36=$B$4,IF(ISBLANK(O$4),NA(),O$4),IF($B36=$B$5,IF(ISBLANK(O$5),NA(),O$5),IF($B36=$B$6,IF(ISBLANK(O$6),NA(),O$6),IF($B36=$B$7,IF(ISBLANK(O$7),NA(),O$7),IF($B36=$B$8,IF(ISBLANK(O$8),NA(),O$8),IF($B36=$B$9,IF(ISBLANK(O$9),NA(),O$9),IF($B36=$B$10,IF(ISBLANK(O$10),NA(),O$10),IF($B36=$B$11,IF(ISBLANK(O$11),NA(),O$11),IF($B36=$B$12,IF(ISBLANK(O$12),NA(),O$12),0)))))))))) -> 0.06 | P36: =IF($B36=$B$3,IF(ISBLANK(P$3),NA(),P$3),IF($B36=$B$4,IF(ISBLANK(P$4),NA(),P$4),IF($B36=$B$5,IF(ISBLANK(P$5),NA(),P$5),IF($B36=$B$6,IF(ISBLANK(P$6),NA(),P$6),IF($B36=$B$7,IF(ISBLANK(P$7),NA(),P$7),IF($B36=$B$8,IF(ISBLANK(P$8),NA(),P$8),IF($B36=$B$9,IF(ISBLANK(P$9),NA(),P$9),IF($B36=$B$10,IF(ISBLANK(P$10),NA(),P$10),IF($B36=$B$11,IF(ISBLANK(P$11),NA(),P$11),IF($B36=$B$12,IF(ISBLANK(P$12),NA(),P$12),0)))))))))) -> 0.06 | ... GA36: =IF($B36=$B$3,IF(ISBLANK(GA$3),NA(),GA$3),IF($B36=$B$4,IF(ISBLANK(GA$4),NA(),GA$4),IF($B36=$B$5,IF(ISBLANK(GA$5),NA(),GA$5),IF($B36=$B$6,IF(ISBLANK(GA$6),NA(),GA$6),IF($B36=$B$7,IF(ISBLANK(GA$7),NA(),GA$7),IF($B36=$B$8,IF(ISBLANK(GA$8),NA(),GA$8),IF($B36=$B$9,IF(ISBLANK(GA$9),NA(),GA$9),IF($B36=$B$10,IF(ISBLANK(GA$10),NA(),GA$10),IF($B36=$B$11,IF(ISBLANK(GA$11),NA(),GA$11),IF($B36=$B$12,IF(ISBLANK(GA$12),NA(),GA$12),0)))))))))) -> #N/A
A37: 1000 | B37: Danger Zone | C37: {=LOOKUP(2,1/(I37:GA37<>""),I37:GA37)} -> 0.08 | D37: =D$12 -> 45 | F37: =(C37-I37)/I37 -> 0.14285714 | G37: {=(C37-IF(ISNA(INDEX(I37:GA37,D37-22)),INDEX(I37:GA37,D37-23),INDEX(I37:GA37,D37-22)))/IF(ISNA(INDEX(I37:GA37,D37-22)),INDEX(I37:GA37,D37-23),INDEX(I37:GA37,D37-22))} -> 0 | I37: =IF($B37=$B$3,IF(ISBLANK(I$3),NA(),I$3),IF($B37=$B$4,IF(ISBLANK(I$4),NA(),I$4),IF($B37=$B$5,IF(ISBLANK(I$5),NA(),I$5),IF($B37=$B$6,IF(ISBLANK(I$6),NA(),I$6),IF($B37=$B$7,IF(ISBLANK(I$7),NA(),I$7),IF($B37=$B$8,IF(ISBLANK(I$8),NA(),I$8),IF($B37=$B$9,IF(ISBLANK(I$9),NA(),I$9),IF($B37=$B$10,IF(ISBLANK(I$10),NA(),I$10),IF($B37=$B$11,IF(ISBLANK(I$11),NA(),I$11),IF($B37=$B$12,IF(ISBLANK(I$12),NA(),I$12),0)))))))))) -> 0.07 | J37: =IF($B37=$B$3,IF(ISBLANK(J$3),NA(),J$3),IF($B37=$B$4,IF(ISBLANK(J$4),NA(),J$4),IF($B37=$B$5,IF(ISBLANK(J$5),NA(),J$5),IF($B37=$B$6,IF(ISBLANK(J$6),NA(),J$6),IF($B37=$B$7,IF(ISBLANK(J$7),NA(),J$7),IF($B37=$B$8,IF(ISBLANK(J$8),NA(),J$8),IF($B37=$B$9,IF(ISBLANK(J$9),NA(),J$9),IF($B37=$B$10,IF(ISBLANK(J$10),NA(),J$10),IF($B37=$B$11,IF(ISBLANK(J$11),NA(),J$11),IF($B37=$B$12,IF(ISBLANK(J$12),NA(),J$12),0)))))))))) -> 0.07 | K37: =IF($B37=$B$3,IF(ISBLANK(K$3),NA(),K$3),IF($B37=$B$4,IF(ISBLANK(K$4),NA(),K$4),IF($B37=$B$5,IF(ISBLANK(K$5),NA(),K$5),IF($B37=$B$6,IF(ISBLANK(K$6),NA(),K$6),IF($B37=$B$7,IF(ISBLANK(K$7),NA(),K$7),IF($B37=$B$8,IF(ISBLANK(K$8),NA(),K$8),IF($B37=$B$9,IF(ISBLANK(K$9),NA(),K$9),IF($B37=$B$10,IF(ISBLANK(K$10),NA(),K$10),IF($B37=$B$11,IF(ISBLANK(K$11),NA(),K$11),IF($B37=$B$12,IF(ISBLANK(K$12),NA(),K$12),0)))))))))) -> #N/A | L37: =IF($B37=$B$3,IF(ISBLANK(L$3),NA(),L$3),IF($B37=$B$4,IF(ISBLANK(L$4),NA(),L$4),IF($B37=$B$5,IF(ISBLANK(L$5),NA(),L$5),IF($B37=$B$6,IF(ISBLANK(L$6),NA(),L$6),IF($B37=$B$7,IF(ISBLANK(L$7),NA(),L$7),IF($B37=$B$8,IF(ISBLANK(L$8),NA(),L$8),IF($B37=$B$9,IF(ISBLANK(L$9),NA(),L$9),IF($B37=$B$10,IF(ISBLANK(L$10),NA(),L$10),IF($B37=$B$11,IF(ISBLANK(L$11),NA(),L$11),IF($B37=$B$12,IF(ISBLANK(L$12),NA(),L$12),0)))))))))) -> 0.07 | M37: =IF($B37=$B$3,IF(ISBLANK(M$3),NA(),M$3),IF($B37=$B$4,IF(ISBLANK(M$4),NA(),M$4),IF($B37=$B$5,IF(ISBLANK(M$5),NA(),M$5),IF($B37=$B$6,IF(ISBLANK(M$6),NA(),M$6),IF($B37=$B$7,IF(ISBLANK(M$7),NA(),M$7),IF($B37=$B$8,IF(ISBLANK(M$8),NA(),M$8),IF($B37=$B$9,IF(ISBLANK(M$9),NA(),M$9),IF($B37=$B$10,IF(ISBLANK(M$10),NA(),M$10),IF($B37=$B$11,IF(ISBLANK(M$11),NA(),M$11),IF($B37=$B$12,IF(ISBLANK(M$12),NA(),M$12),0)))))))))) -> #N/A | N37: =IF($B37=$B$3,IF(ISBLANK(N$3),NA(),N$3),IF($B37=$B$4,IF(ISBLANK(N$4),NA(),N$4),IF($B37=$B$5,IF(ISBLANK(N$5),NA(),N$5),IF($B37=$B$6,IF(ISBLANK(N$6),NA(),N$6),IF($B37=$B$7,IF(ISBLANK(N$7),NA(),N$7),IF($B37=$B$8,IF(ISBLANK(N$8),NA(),N$8),IF($B37=$B$9,IF(ISBLANK(N$9),NA(),N$9),IF($B37=$B$10,IF(ISBLANK(N$10),NA(),N$10),IF($B37=$B$11,IF(ISBLANK(N$11),NA(),N$11),IF($B37=$B$12,IF(ISBLANK(N$12),NA(),N$12),0)))))))))) -> 0.07 | O37: =IF($B37=$B$3,IF(ISBLANK(O$3),NA(),O$3),IF($B37=$B$4,IF(ISBLANK(O$4),NA(),O$4),IF($B37=$B$5,IF(ISBLANK(O$5),NA(),O$5),IF($B37=$B$6,IF(ISBLANK(O$6),NA(),O$6),IF($B37=$B$7,IF(ISBLANK(O$7),NA(),O$7),IF($B37=$B$8,IF(ISBLANK(O$8),NA(),O$8),IF($B37=$B$9,IF(ISBLANK(O$9),NA(),O$9),IF($B37=$B$10,IF(ISBLANK(O$10),NA(),O$10),IF($B37=$B$11,IF(ISBLANK(O$11),NA(),O$11),IF($B37=$B$12,IF(ISBLANK(O$12),NA(),O$12),0)))))))))) -> 0.07 | P37: =IF($B37=$B$3,IF(ISBLANK(P$3),NA(),P$3),IF($B37=$B$4,IF(ISBLANK(P$4),NA(),P$4),IF($B37=$B$5,IF(ISBLANK(P$5),NA(),P$5),IF($B37=$B$6,IF(ISBLANK(P$6),NA(),P$6),IF($B37=$B$7,IF(ISBLANK(P$7),NA(),P$7),IF($B37=$B$8,IF(ISBLANK(P$8),NA(),P$8),IF($B37=$B$9,IF(ISBLANK(P$9),NA(),P$9),IF($B37=$B$10,IF(ISBLANK(P$10),NA(),P$10),IF($B37=$B$11,IF(ISBLANK(P$11),NA(),P$11),IF($B37=$B$12,IF(ISBLANK(P$12),NA(),P$12),0)))))))))) -> 0.07 | ... GA37: =IF($B37=$B$3,IF(ISBLANK(GA$3),NA(),GA$3),IF($B37=$B$4,IF(ISBLANK(GA$4),NA(),GA$4),IF($B37=$B$5,IF(ISBLANK(GA$5),NA(),GA$5),IF($B37=$B$6,IF(ISBLANK(GA$6),NA(),GA$6),IF($B37=$B$7,IF(ISBLANK(GA$7),NA(),GA$7),IF($B37=$B$8,IF(ISBLANK(GA$8),NA(),GA$8),IF($B37=$B$9,IF(ISBLANK(GA$9),NA(),GA$9),IF($B37=$B$10,IF(ISBLANK(GA$10),NA(),GA$10),IF($B37=$B$11,IF(ISBLANK(GA$11),NA(),GA$11),IF($B37=$B$12,IF(ISBLANK(GA$12),NA(),GA$12),0)))))))))) -> #N/A
A38: 2000 | B38: Horizon | C38: {=LOOKUP(2,1/(I38:GA38<>""),I38:GA38)} -> 0.12 | D38: =D$12 -> 45 | F38: =(C38-I38)/I38 -> 0.71428571 | G38: {=(C38-IF(ISNA(INDEX(I38:GA38,D38-22)),INDEX(I38:GA38,D38-23),INDEX(I38:GA38,D38-22)))/IF(ISNA(INDEX(I38:GA38,D38-22)),INDEX(I38:GA38,D38-23),INDEX(I38:GA38,D38-22))} -> 0.090909091 | I38: =IF($B38=$B$3,IF(ISBLANK(I$3),NA(),I$3),IF($B38=$B$4,IF(ISBLANK(I$4),NA(),I$4),IF($B38=$B$5,IF(ISBLANK(I$5),NA(),I$5),IF($B38=$B$6,IF(ISBLANK(I$6),NA(),I$6),IF($B38=$B$7,IF(ISBLANK(I$7),NA(),I$7),IF($B38=$B$8,IF(ISBLANK(I$8),NA(),I$8),IF($B38=$B$9,IF(ISBLANK(I$9),NA(),I$9),IF($B38=$B$10,IF(ISBLANK(I$10),NA(),I$10),IF($B38=$B$11,IF(ISBLANK(I$11),NA(),I$11),IF($B38=$B$12,IF(ISBLANK(I$12),NA(),I$12),0)))))))))) -> 0.07 | J38: =IF($B38=$B$3,IF(ISBLANK(J$3),NA(),J$3),IF($B38=$B$4,IF(ISBLANK(J$4),NA(),J$4),IF($B38=$B$5,IF(ISBLANK(J$5),NA(),J$5),IF($B38=$B$6,IF(ISBLANK(J$6),NA(),J$6),IF($B38=$B$7,IF(ISBLANK(J$7),NA(),J$7),IF($B38=$B$8,IF(ISBLANK(J$8),NA(),J$8),IF($B38=$B$9,IF(ISBLANK(J$9),NA(),J$9),IF($B38=$B$10,IF(ISBLANK(J$10),NA(),J$10),IF($B38=$B$11,IF(ISBLANK(J$11),NA(),J$11),IF($B38=$B$12,IF(ISBLANK(J$12),NA(),J$12),0)))))))))) -> 0.07 | K38: =IF($B38=$B$3,IF(ISBLANK(K$3),NA(),K$3),IF($B38=$B$4,IF(ISBLANK(K$4),NA(),K$4),IF($B38=$B$5,IF(ISBLANK(K$5),NA(),K$5),IF($B38=$B$6,IF(ISBLANK(K$6),NA(),K$6),IF($B38=$B$7,IF(ISBLANK(K$7),NA(),K$7),IF($B38=$B$8,IF(ISBLANK(K$8),NA(),K$8),IF($B38=$B$9,IF(ISBLANK(K$9),NA(),K$9),IF($B38=$B$10,IF(ISBLANK(K$10),NA(),K$10),IF($B38=$B$11,IF(ISBLANK(K$11),NA(),K$11),IF($B38=$B$12,IF(ISBLANK(K$12),NA(),K$12),0)))))))))) -> #N/A | L38: =IF($B38=$B$3,IF(ISBLANK(L$3),NA(),L$3),IF($B38=$B$4,IF(ISBLANK(L$4),NA(),L$4),IF($B38=$B$5,IF(ISBLANK(L$5),NA(),L$5),IF($B38=$B$6,IF(ISBLANK(L$6),NA(),L$6),IF($B38=$B$7,IF(ISBLANK(L$7),NA(),L$7),IF($B38=$B$8,IF(ISBLANK(L$8),NA(),L$8),IF($B38=$B$9,IF(ISBLANK(L$9),NA(),L$9),IF($B38=$B$10,IF(ISBLANK(L$10),NA(),L$10),IF($B38=$B$11,IF(ISBLANK(L$11),NA(),L$11),IF($B38=$B$12,IF(ISBLANK(L$12),NA(),L$12),0)))))))))) -> 0.07 | M38: =IF($B38=$B$3,IF(ISBLANK(M$3),NA(),M$3),IF($B38=$B$4,IF(ISBLANK(M$4),NA(),M$4),IF($B38=$B$5,IF(ISBLANK(M$5),NA(),M$5),IF($B38=$B$6,IF(ISBLANK(M$6),NA(),M$6),IF($B38=$B$7,IF(ISBLANK(M$7),NA(),M$7),IF($B38=$B$8,IF(ISBLANK(M$8),NA(),M$8),IF($B38=$B$9,IF(ISBLANK(M$9),NA(),M$9),IF($B38=$B$10,IF(ISBLANK(M$10),NA(),M$10),IF($B38=$B$11,IF(ISBLANK(M$11),NA(),M$11),IF($B38=$B$12,IF(ISBLANK(M$12),NA(),M$12),0)))))))))) -> #N/A | N38: =IF($B38=$B$3,IF(ISBLANK(N$3),NA(),N$3),IF($B38=$B$4,IF(ISBLANK(N$4),NA(),N$4),IF($B38=$B$5,IF(ISBLANK(N$5),NA(),N$5),IF($B38=$B$6,IF(ISBLANK(N$6),NA(),N$6),IF($B38=$B$7,IF(ISBLANK(N$7),NA(),N$7),IF($B38=$B$8,IF(ISBLANK(N$8),NA(),N$8),IF($B38=$B$9,IF(ISBLANK(N$9),NA(),N$9),IF($B38=$B$10,IF(ISBLANK(N$10),NA(),N$10),IF($B38=$B$11,IF(ISBLANK(N$11),NA(),N$11),IF($B38=$B$12,IF(ISBLANK(N$12),NA(),N$12),0)))))))))) -> 0.07 | O38: =IF($B38=$B$3,IF(ISBLANK(O$3),NA(),O$3),IF($B38=$B$4,IF(ISBLANK(O$4),NA(),O$4),IF($B38=$B$5,IF(ISBLANK(O$5),NA(),O$5),IF($B38=$B$6,IF(ISBLANK(O$6),NA(),O$6),IF($B38=$B$7,IF(ISBLANK(O$7),NA(),O$7),IF($B38=$B$8,IF(ISBLANK(O$8),NA(),O$8),IF($B38=$B$9,IF(ISBLANK(O$9),NA(),O$9),IF($B38=$B$10,IF(ISBLANK(O$10),NA(),O$10),IF($B38=$B$11,IF(ISBLANK(O$11),NA(),O$11),IF($B38=$B$12,IF(ISBLANK(O$12),NA(),O$12),0)))))))))) -> 0.07 | P38: =IF($B38=$B$3,IF(ISBLANK(P$3),NA(),P$3),IF($B38=$B$4,IF(ISBLANK(P$4),NA(),P$4),IF($B38=$B$5,IF(ISBLANK(P$5),NA(),P$5),IF($B38=$B$6,IF(ISBLANK(P$6),NA(),P$6),IF($B38=$B$7,IF(ISBLANK(P$7),NA(),P$7),IF($B38=$B$8,IF(ISBLANK(P$8),NA(),P$8),IF($B38=$B$9,IF(ISBLANK(P$9),NA(),P$9),IF($B38=$B$10,IF(ISBLANK(P$10),NA(),P$10),IF($B38=$B$11,IF(ISBLANK(P$11),NA(),P$11),IF($B38=$B$12,IF(ISBLANK(P$12),NA(),P$12),0)))))))))) -> 0.07 | ... GA38: =IF($B38=$B$3,IF(ISBLANK(GA$3),NA(),GA$3),IF($B38=$B$4,IF(ISBLANK(GA$4),NA(),GA$4),IF($B38=$B$5,IF(ISBLANK(GA$5),NA(),GA$5),IF($B38=$B$6,IF(ISBLANK(GA$6),NA(),GA$6),IF($B38=$B$7,IF(ISBLANK(GA$7),NA(),GA$7),IF($B38=$B$8,IF(ISBLANK(GA$8),NA(),GA$8),IF($B38=$B$9,IF(ISBLANK(GA$9),NA(),GA$9),IF($B38=$B$10,IF(ISBLANK(GA$10),NA(),GA$10),IF($B38=$B$11,IF(ISBLANK(GA$11),NA(),GA$11),IF($B38=$B$12,IF(ISBLANK(GA$12),NA(),GA$12),0)))))))))) -> #N/A
A39: 215 | B39: CS20 | C39: {=LOOKUP(2,1/(I39:GA39<>""),I39:GA39)} -> 0.21 | D39: =D$12 -> 45 | F39: =(C39-I39)/I39 -> 1.625 | G39: {=(C39-IF(ISNA(INDEX(I39:GA39,D39-22)),INDEX(I39:GA39,D39-23),INDEX(I39:GA39,D39-22)))/IF(ISNA(INDEX(I39:GA39,D39-22)),INDEX(I39:GA39,D39-23),INDEX(I39:GA39,D39-22))} -> 0.23529412 | I39: =IF($B39=$B$3,IF(ISBLANK(I$3),NA(),I$3),IF($B39=$B$4,IF(ISBLANK(I$4),NA(),I$4),IF($B39=$B$5,IF(ISBLANK(I$5),NA(),I$5),IF($B39=$B$6,IF(ISBLANK(I$6),NA(),I$6),IF($B39=$B$7,IF(ISBLANK(I$7),NA(),I$7),IF($B39=$B$8,IF(ISBLANK(I$8),NA(),I$8),IF($B39=$B$9,IF(ISBLANK(I$9),NA(),I$9),IF($B39=$B$10,IF(ISBLANK(I$10),NA(),I$10),IF($B39=$B$11,IF(ISBLANK(I$11),NA(),I$11),IF($B39=$B$12,IF(ISBLANK(I$12),NA(),I$12),0)))))))))) -> 0.08 | J39: =IF($B39=$B$3,IF(ISBLANK(J$3),NA(),J$3),IF($B39=$B$4,IF(ISBLANK(J$4),NA(),J$4),IF($B39=$B$5,IF(ISBLANK(J$5),NA(),J$5),IF($B39=$B$6,IF(ISBLANK(J$6),NA(),J$6),IF($B39=$B$7,IF(ISBLANK(J$7),NA(),J$7),IF($B39=$B$8,IF(ISBLANK(J$8),NA(),J$8),IF($B39=$B$9,IF(ISBLANK(J$9),NA(),J$9),IF($B39=$B$10,IF(ISBLANK(J$10),NA(),J$10),IF($B39=$B$11,IF(ISBLANK(J$11),NA(),J$11),IF($B39=$B$12,IF(ISBLANK(J$12),NA(),J$12),0)))))))))) -> 0.08 | K39: =IF($B39=$B$3,IF(ISBLANK(K$3),NA(),K$3),IF($B39=$B$4,IF(ISBLANK(K$4),NA(),K$4),IF($B39=$B$5,IF(ISBLANK(K$5),NA(),K$5),IF($B39=$B$6,IF(ISBLANK(K$6),NA(),K$6),IF($B39=$B$7,IF(ISBLANK(K$7),NA(),K$7),IF($B39=$B$8,IF(ISBLANK(K$8),NA(),K$8),IF($B39=$B$9,IF(ISBLANK(K$9),NA(),K$9),IF($B39=$B$10,IF(ISBLANK(K$10),NA(),K$10),IF($B39=$B$11,IF(ISBLANK(K$11),NA(),K$11),IF($B39=$B$12,IF(ISBLANK(K$12),NA(),K$12),0)))))))))) -> #N/A | L39: =IF($B39=$B$3,IF(ISBLANK(L$3),NA(),L$3),IF($B39=$B$4,IF(ISBLANK(L$4),NA(),L$4),IF($B39=$B$5,IF(ISBLANK(L$5),NA(),L$5),IF($B39=$B$6,IF(ISBLANK(L$6),NA(),L$6),IF($B39=$B$7,IF(ISBLANK(L$7),NA(),L$7),IF($B39=$B$8,IF(ISBLANK(L$8),NA(),L$8),IF($B39=$B$9,IF(ISBLANK(L$9),NA(),L$9),IF($B39=$B$10,IF(ISBLANK(L$10),NA(),L$10),IF($B39=$B$11,IF(ISBLANK(L$11),NA(),L$11),IF($B39=$B$12,IF(ISBLANK(L$12),NA(),L$12),0)))))))))) -> 0.08 | M39: =IF($B39=$B$3,IF(ISBLANK(M$3),NA(),M$3),IF($B39=$B$4,IF(ISBLANK(M$4),NA(),M$4),IF($B39=$B$5,IF(ISBLANK(M$5),NA(),M$5),IF($B39=$B$6,IF(ISBLANK(M$6),NA(),M$6),IF($B39=$B$7,IF(ISBLANK(M$7),NA(),M$7),IF($B39=$B$8,IF(ISBLANK(M$8),NA(),M$8),IF($B39=$B$9,IF(ISBLANK(M$9),NA(),M$9),IF($B39=$B$10,IF(ISBLANK(M$10),NA(),M$10),IF($B39=$B$11,IF(ISBLANK(M$11),NA(),M$11),IF($B39=$B$12,IF(ISBLANK(M$12),NA(),M$12),0)))))))))) -> #N/A | N39: =IF($B39=$B$3,IF(ISBLANK(N$3),NA(),N$3),IF($B39=$B$4,IF(ISBLANK(N$4),NA(),N$4),IF($B39=$B$5,IF(ISBLANK(N$5),NA(),N$5),IF($B39=$B$6,IF(ISBLANK(N$6),NA(),N$6),IF($B39=$B$7,IF(ISBLANK(N$7),NA(),N$7),IF($B39=$B$8,IF(ISBLANK(N$8),NA(),N$8),IF($B39=$B$9,IF(ISBLANK(N$9),NA(),N$9),IF($B39=$B$10,IF(ISBLANK(N$10),NA(),N$10),IF($B39=$B$11,IF(ISBLANK(N$11),NA(),N$11),IF($B39=$B$12,IF(ISBLANK(N$12),NA(),N$12),0)))))))))) -> 0.08 | O39: =IF($B39=$B$3,IF(ISBLANK(O$3),NA(),O$3),IF($B39=$B$4,IF(ISBLANK(O$4),NA(),O$4),IF($B39=$B$5,IF(ISBLANK(O$5),NA(),O$5),IF($B39=$B$6,IF(ISBLANK(O$6),NA(),O$6),IF($B39=$B$7,IF(ISBLANK(O$7),NA(),O$7),IF($B39=$B$8,IF(ISBLANK(O$8),NA(),O$8),IF($B39=$B$9,IF(ISBLANK(O$9),NA(),O$9),IF($B39=$B$10,IF(ISBLANK(O$10),NA(),O$10),IF($B39=$B$11,IF(ISBLANK(O$11),NA(),O$11),IF($B39=$B$12,IF(ISBLANK(O$12),NA(),O$12),0)))))))))) -> 0.08 | P39: =IF($B39=$B$3,IF(ISBLANK(P$3),NA(),P$3),IF($B39=$B$4,IF(ISBLANK(P$4),NA(),P$4),IF($B39=$B$5,IF(ISBLANK(P$5),NA(),P$5),IF($B39=$B$6,IF(ISBLANK(P$6),NA(),P$6),IF($B39=$B$7,IF(ISBLANK(P$7),NA(),P$7),IF($B39=$B$8,IF(ISBLANK(P$8),NA(),P$8),IF($B39=$B$9,IF(ISBLANK(P$9),NA(),P$9),IF($B39=$B$10,IF(ISBLANK(P$10),NA(),P$10),IF($B39=$B$11,IF(ISBLANK(P$11),NA(),P$11),IF($B39=$B$12,IF(ISBLANK(P$12),NA(),P$12),0)))))))))) -> 0.08 | ... GA39: =IF($B39=$B$3,IF(ISBLANK(GA$3),NA(),GA$3),IF($B39=$B$4,IF(ISBLANK(GA$4),NA(),GA$4),IF($B39=$B$5,IF(ISBLANK(GA$5),NA(),GA$5),IF($B39=$B$6,IF(ISBLANK(GA$6),NA(),GA$6),IF($B39=$B$7,IF(ISBLANK(GA$7),NA(),GA$7),IF($B39=$B$8,IF(ISBLANK(GA$8),NA(),GA$8),IF($B39=$B$9,IF(ISBLANK(GA$9),NA(),GA$9),IF($B39=$B$10,IF(ISBLANK(GA$10),NA(),GA$10),IF($B39=$B$11,IF(ISBLANK(GA$11),NA(),GA$11),IF($B39=$B$12,IF(ISBLANK(GA$12),NA(),GA$12),0)))))))))) -> #N/A
A40: 150 | B40: Fracture | C40: {=LOOKUP(2,1/(I40:GA40<>""),I40:GA40)} -> 0.31 | D40: =D$12 -> 45 | F40: =(C40-I40)/I40 -> -0.11428571 | G40: {=(C40-IF(ISNA(INDEX(I40:GA40,D40-22)),INDEX(I40:GA40,D40-23),INDEX(I40:GA40,D40-22)))/IF(ISNA(INDEX(I40:GA40,D40-22)),INDEX(I40:GA40,D40-23),INDEX(I40:GA40,D40-22))} -> -0.03125 | I40: =IF($B40=$B$3,IF(ISBLANK(I$3),NA(),I$3),IF($B40=$B$4,IF(ISBLANK(I$4),NA(),I$4),IF($B40=$B$5,IF(ISBLANK(I$5),NA(),I$5),IF($B40=$B$6,IF(ISBLANK(I$6),NA(),I$6),IF($B40=$B$7,IF(ISBLANK(I$7),NA(),I$7),IF($B40=$B$8,IF(ISBLANK(I$8),NA(),I$8),IF($B40=$B$9,IF(ISBLANK(I$9),NA(),I$9),IF($B40=$B$10,IF(ISBLANK(I$10),NA(),I$10),IF($B40=$B$11,IF(ISBLANK(I$11),NA(),I$11),IF($B40=$B$12,IF(ISBLANK(I$12),NA(),I$12),0)))))))))) -> 0.35 | J40: =IF($B40=$B$3,IF(ISBLANK(J$3),NA(),J$3),IF($B40=$B$4,IF(ISBLANK(J$4),NA(),J$4),IF($B40=$B$5,IF(ISBLANK(J$5),NA(),J$5),IF($B40=$B$6,IF(ISBLANK(J$6),NA(),J$6),IF($B40=$B$7,IF(ISBLANK(J$7),NA(),J$7),IF($B40=$B$8,IF(ISBLANK(J$8),NA(),J$8),IF($B40=$B$9,IF(ISBLANK(J$9),NA(),J$9),IF($B40=$B$10,IF(ISBLANK(J$10),NA(),J$10),IF($B40=$B$11,IF(ISBLANK(J$11),NA(),J$11),IF($B40=$B$12,IF(ISBLANK(J$12),NA(),J$12),0)))))))))) -> 0.35 | K40: =IF($B40=$B$3,IF(ISBLANK(K$3),NA(),K$3),IF($B40=$B$4,IF(ISBLANK(K$4),NA(),K$4),IF($B40=$B$5,IF(ISBLANK(K$5),NA(),K$5),IF($B40=$B$6,IF(ISBLANK(K$6),NA(),K$6),IF($B40=$B$7,IF(ISBLANK(K$7),NA(),K$7),IF($B40=$B$8,IF(ISBLANK(K$8),NA(),K$8),IF($B40=$B$9,IF(ISBLANK(K$9),NA(),K$9),IF($B40=$B$10,IF(ISBLANK(K$10),NA(),K$10),IF($B40=$B$11,IF(ISBLANK(K$11),NA(),K$11),IF($B40=$B$12,IF(ISBLANK(K$12),NA(),K$12),0)))))))))) -> #N/A | L40: =IF($B40=$B$3,IF(ISBLANK(L$3),NA(),L$3),IF($B40=$B$4,IF(ISBLANK(L$4),NA(),L$4),IF($B40=$B$5,IF(ISBLANK(L$5),NA(),L$5),IF($B40=$B$6,IF(ISBLANK(L$6),NA(),L$6),IF($B40=$B$7,IF(ISBLANK(L$7),NA(),L$7),IF($B40=$B$8,IF(ISBLANK(L$8),NA(),L$8),IF($B40=$B$9,IF(ISBLANK(L$9),NA(),L$9),IF($B40=$B$10,IF(ISBLANK(L$10),NA(),L$10),IF($B40=$B$11,IF(ISBLANK(L$11),NA(),L$11),IF($B40=$B$12,IF(ISBLANK(L$12),NA(),L$12),0)))))))))) -> 0.35 | M40: =IF($B40=$B$3,IF(ISBLANK(M$3),NA(),M$3),IF($B40=$B$4,IF(ISBLANK(M$4),NA(),M$4),IF($B40=$B$5,IF(ISBLANK(M$5),NA(),M$5),IF($B40=$B$6,IF(ISBLANK(M$6),NA(),M$6),IF($B40=$B$7,IF(ISBLANK(M$7),NA(),M$7),IF($B40=$B$8,IF(ISBLANK(M$8),NA(),M$8),IF($B40=$B$9,IF(ISBLANK(M$9),NA(),M$9),IF($B40=$B$10,IF(ISBLANK(M$10),NA(),M$10),IF($B40=$B$11,IF(ISBLANK(M$11),NA(),M$11),IF($B40=$B$12,IF(ISBLANK(M$12),NA(),M$12),0)))))))))) -> #N/A | N40: =IF($B40=$B$3,IF(ISBLANK(N$3),NA(),N$3),IF($B40=$B$4,IF(ISBLANK(N$4),NA(),N$4),IF($B40=$B$5,IF(ISBLANK(N$5),NA(),N$5),IF($B40=$B$6,IF(ISBLANK(N$6),NA(),N$6),IF($B40=$B$7,IF(ISBLANK(N$7),NA(),N$7),IF($B40=$B$8,IF(ISBLANK(N$8),NA(),N$8),IF($B40=$B$9,IF(ISBLANK(N$9),NA(),N$9),IF($B40=$B$10,IF(ISBLANK(N$10),NA(),N$10),IF($B40=$B$11,IF(ISBLANK(N$11),NA(),N$11),IF($B40=$B$12,IF(ISBLANK(N$12),NA(),N$12),0)))))))))) -> 0.31 | O40: =IF($B40=$B$3,IF(ISBLANK(O$3),NA(),O$3),IF($B40=$B$4,IF(ISBLANK(O$4),NA(),O$4),IF($B40=$B$5,IF(ISBLANK(O$5),NA(),O$5),IF($B40=$B$6,IF(ISBLANK(O$6),NA(),O$6),IF($B40=$B$7,IF(ISBLANK(O$7),NA(),O$7),IF($B40=$B$8,IF(ISBLANK(O$8),NA(),O$8),IF($B40=$B$9,IF(ISBLANK(O$9),NA(),O$9),IF($B40=$B$10,IF(ISBLANK(O$10),NA(),O$10),IF($B40=$B$11,IF(ISBLANK(O$11),NA(),O$11),IF($B40=$B$12,IF(ISBLANK(O$12),NA(),O$12),0)))))))))) -> 0.3 | P40: =IF($B40=$B$3,IF(ISBLANK(P$3),NA(),P$3),IF($B40=$B$4,IF(ISBLANK(P$4),NA(),P$4),IF($B40=$B$5,IF(ISBLANK(P$5),NA(),P$5),IF($B40=$B$6,IF(ISBLANK(P$6),NA(),P$6),IF($B40=$B$7,IF(ISBLANK(P$7),NA(),P$7),IF($B40=$B$8,IF(ISBLANK(P$8),NA(),P$8),IF($B40=$B$9,IF(ISBLANK(P$9),NA(),P$9),IF($B40=$B$10,IF(ISBLANK(P$10),NA(),P$10),IF($B40=$B$11,IF(ISBLANK(P$11),NA(),P$11),IF($B40=$B$12,IF(ISBLANK(P$12),NA(),P$12),0)))))))))) -> 0.34 | ... GA40: =IF($B40=$B$3,IF(ISBLANK(GA$3),NA(),GA$3),IF($B40=$B$4,IF(ISBLANK(GA$4),NA(),GA$4),IF($B40=$B$5,IF(ISBLANK(GA$5),NA(),GA$5),IF($B40=$B$6,IF(ISBLANK(GA$6),NA(),GA$6),IF($B40=$B$7,IF(ISBLANK(GA$7),NA(),GA$7),IF($B40=$B$8,IF(ISBLANK(GA$8),NA(),GA$8),IF($B40=$B$9,IF(ISBLANK(GA$9),NA(),GA$9),IF($B40=$B$10,IF(ISBLANK(GA$10),NA(),GA$10),IF($B40=$B$11,IF(ISBLANK(GA$11),NA(),GA$11),IF($B40=$B$12,IF(ISBLANK(GA$12),NA(),GA$12),0)))))))))) -> #N/A
A43: Total Value Investments
I44: =I35 -> 44331 | J44: =J35 -> 44332 | K44: =K35 -> 44333 | L44: =L35 -> 44334 | M44: =M35 -> 44335 | N44: =N35 -> 44336 | O44: =O35 -> 44337 | P44: =P35 -> 44338 | ... GA44: =GA35 -> 44505
A45: =A36 -> 2000 | B45: Prisma 2 | C45: {=LOOKUP(2,1/(I45:GA45<>""),I45:GA45)} -> 140 | D45: =D$12 -> 45 | F45: =(C45-I45)/I45 -> 0.4 | G45: {=(C45-IF(ISNA(INDEX(I45:GA45,D45-22)),INDEX(I45:GA45,D45-23),INDEX(I45:GA45,D45-22)))/IF(ISNA(INDEX(I45:GA45,D45-22)),INDEX(I45:GA45,D45-23),INDEX(I45:GA45,D45-22))} -> 0 | I45: =I36*$A45 -> 100 | J45: =J36*$A45 -> 100 | K45: =K36*$A45 -> #N/A | L45: =L36*$A45 -> 100 | M45: =M36*$A45 -> #N/A | N45: =N36*$A45 -> 120 | O45: =O36*$A45 -> 120 | P45: =P36*$A45 -> 120 | ... GA45: =GA36*$A45 -> #N/A
A46: =A37 -> 1000 | B46: Danger Zone | C46: {=LOOKUP(2,1/(I46:GA46<>""),I46:GA46)} -> 80 | D46: =D$12 -> 45 | F46: =(C46-I46)/I46 -> 0.14285714 | G46: {=(C46-IF(ISNA(INDEX(I46:GA46,D46-22)),INDEX(I46:GA46,D46-23),INDEX(I46:GA46,D46-22)))/IF(ISNA(INDEX(I46:GA46,D46-22)),INDEX(I46:GA46,D46-23),INDEX(I46:GA46,D46-22))} -> 0 | I46: =I37*$A46 -> 70 | J46: =J37*$A46 -> 70 | K46: =K37*$A46 -> #N/A | L46: =L37*$A46 -> 70 | M46: =M37*$A46 -> #N/A | N46: =N37*$A46 -> 70 | O46: =O37*$A46 -> 70 | P46: =P37*$A46 -> 70 | ... GA46: =GA37*$A46 -> #N/A
A47: =A38 -> 2000 | B47: Horizon | C47: {=LOOKUP(2,1/(I47:GA47<>""),I47:GA47)} -> 240 | D47: =D$12 -> 45 | F47: =(C47-I47)/I47 -> 0.71428571 | G47: {=(C47-IF(ISNA(INDEX(I47:GA47,D47-22)),INDEX(I47:GA47,D47-23),INDEX(I47:GA47,D47-22)))/IF(ISNA(INDEX(I47:GA47,D47-22)),INDEX(I47:GA47,D47-23),INDEX(I47:GA47,D47-22))} -> 0.090909091 | I47: =I38*$A47 -> 140 | J47: =J38*$A47 -> 140 | K47: =K38*$A47 -> #N/A | L47: =L38*$A47 -> 140 | M47: =M38*$A47 -> #N/A | N47: =N38*$A47 -> 140 | O47: =O38*$A47 -> 140 | P47: =P38*$A47 -> 140 | ... GA47: =GA38*$A47 -> #N/A
A48: =A39 -> 215 | B48: CS20 | C48: {=LOOKUP(2,1/(I48:GA48<>""),I48:GA48)} -> 45.15 | D48: =D$12 -> 45 | F48: =(C48-I48)/I48 -> 1.625 | G48: {=(C48-IF(ISNA(INDEX(I48:GA48,D48-22)),INDEX(I48:GA48,D48-23),INDEX(I48:GA48,D48-22)))/IF(ISNA(INDEX(I48:GA48,D48-22)),INDEX(I48:GA48,D48-23),INDEX(I48:GA48,D48-22))} -> 0.23529412 | I48: =I39*$A48 -> 17.2 | J48: =J39*$A48 -> 17.2 | K48: =K39*$A48 -> #N/A | L48: =L39*$A48 -> 17.2 | M48: =M39*$A48 -> #N/A | N48: =N39*$A48 -> 17.2 | O48: =O39*$A48 -> 17.2 | P48: =P39*$A48 -> 17.2 | ... GA48: =GA39*$A48 -> #N/A
A49: =A40 -> 150 | B49: Fracture | C49: {=LOOKUP(2,1/(I49:GA49<>""),I49:GA49)} -> 46.5 | D49: =D$12 -> 45 | F49: =(C49-I49)/I49 -> -0.11428571 | G49: {=(C49-IF(ISNA(INDEX(I49:GA49,D49-22)),INDEX(I49:GA49,D49-23),INDEX(I49:GA49,D49-22)))/IF(ISNA(INDEX(I49:GA49,D49-22)),INDEX(I49:GA49,D49-23),INDEX(I49:GA49,D49-22))} -> -0.03125 | I49: =I40*$A49 -> 52.5 | J49: =J40*$A49 -> 52.5 | K49: =K40*$A49 -> #N/A | L49: =L40*$A49 -> 52.5 | M49: =M40*$A49 -> #N/A | N49: =N40*$A49 -> 46.5 | O49: =O40*$A49 -> 45 | P49: =P40*$A49 -> 51 | ... GA49: =GA40*$A49 -> #N/A
A52: Sale Revenue Investments on Steam Market
I53: =I44 -> 44331 | J53: =J44 -> 44332 | K53: =K44 -> 44333 | L53: =L44 -> 44334 | M53: =M44 -> 44335 | N53: =N44 -> 44336 | O53: =O44 -> 44337 | P53: =P44 -> 44338 | ... GA53: =GA44 -> 44505
...

Sheet Skin-Investments
A1: Market Values
C2: Last value | D2: Row of last value | F2: Since May 15th 2021 | G2: 14day | I2: =Cases!I2 -> 44331 | J2: =Cases!J2 -> 44332 | K2: =Cases!K2 -> 44333 | L2: =Cases!L2 -> 44334 | M2: =Cases!M2 -> 44335 | N2: =Cases!N2 -> 44336 | O2: =Cases!O2 -> 44337 | P2: =Cases!P2 -> 44338 | ... GA2: =Cases!GA2 -> 44505
B3: M4 Dark Blossom FN | C3: {=LOOKUP(2,1/(I3:GA3<>""),I3:GA3)} -> 8.8 | D3: {=SUMPRODUCT(MAX((I3:GA3<>"")*COLUMN(I3:GA3)))} -> 45 | F3: =(C3-I3)/I3 -> 1.2680412 | G3: {=(C3-IF(ISNA(INDEX(I3:GA3,D3-22)),INDEX(I3:GA3,D3-23),INDEX(I3:GA3,D3-22)))/IF(ISNA(INDEX(I3:GA3,D3-22)),INDEX(I3:GA3,D3-23),INDEX(I3:GA3,D3-22))} -> -0.079497908 | I3: 3.88 | J3: 3.68 | L3: 3.95 | N3: 4.45 | O3: 4.41 | P3: 5.99 | Q3: 5.89 | R3: 6.51 | S3: 6.53 | T3: 7.68 | U3: 8.69 | V3: 8.59 | W3: 7.72 | X3: 7.24 | Y3: 6.86 | Z3: 7.73 | AA3: 8.58 | AB3: 9.05 | AC3: 9.33 | AD3: 10.95 | AE3: 9.56 | AF3: 9.48 | AG3: 9.57 | AH3: 9.52 | AI3: 9.51 | AJ3: 9.25 | AK3: 9.7 | AL3: 9.96 | AM3: 9.7 | AO3: 9.74 | AP3: 9.59 | AQ3: 9.14 | AR3: 9.23 | AS3: 8.8
B4: M4 Dark Blossom MW | C4: {=LOOKUP(2,1/(I4:GA4<>""),I4:GA4)} -> 8.92 | D4: {=SUMPRODUCT(MAX((I4:GA4<>"")*COLUMN(I4:GA4)))} -> 45 | F4: =(C4-I4)/I4 -> 1.5632184 | G4: {=(C4-IF(ISNA(INDEX(I4:GA4,D4-22)),INDEX(I4:GA4,D4-23),INDEX(I4:GA4,D4-22)))/IF(ISNA(INDEX(I4:GA4,D4-22)),INDEX(I4:GA4,D4-23),INDEX(I4:GA4,D4-22))} -> -0.092573754 | I4: 3.48 | J4: 3.52 | L4: 3.93 | N4: 4.28 | O4: 4.5 | P4: 5.8 | Q4: 5.7 | R4: 6.3 | S4: 6.26 | T4: 7.32 | U4: 7.99 | V4: 8.44 | W4: 8.14 | X4: 7.19 | Y4: 6.37 | Z4: 6.86 | AA4: 8.05 | AB4: 8.85 | AC4: 9.02 | AD4: 9.75 | AE4: 9.83 | AF4: 8.81 | AG4: 9.03 | AH4: 9.28 | AI4: 9.13 | AJ4: 9.23 | AK4: 9.01 | AL4: 9.89 | AM4: 9.69 | AO4: 9.32 | AP4: 8.89 | AQ4: 8.89 | AR4: 9.31 | AS4: 8.92
B5: P90 Sunset Lily FN | C5: {=LOOKUP(2,1/(I5:GA5<>""),I5:GA5)} -> 9.84 | D5: {=SUMPRODUCT(MAX((I5:GA5<>"")*COLUMN(I5:GA5)))} -> 45 | F5: =(C5-I5)/I5 -> 1.8114286 | G5: {=(C5-IF(ISNA(INDEX(I5:GA5,D5-22)),INDEX(I5:GA5,D5-23),INDEX(I5:GA5,D5-22)))/IF(ISNA(INDEX(I5:GA5,D5-22)),INDEX(I5:GA5,D5-23),INDEX(I5:GA5,D5-22))} -> -0.11827957 | I5: 3.5 | J5: 3.7 | L5: 3.9 | N5: 4.2 | O5: 4.5 | P5: 6.6 | Q5: 6.41 | R5: 6.41 | S5: 6.56 | T5: 8.83 | U5: 9.61 | V5: 9.02 | W5: 8.69 | X5: 8.19 | Y5: 7.37 | Z5: 7.63 | AA5: 8.23 | AB5: 9.16 | AC5: 9.89 | AD5: 11.16 | AE5: 11.16 | AF5: 10.03 | AG5: 9.81 | AH5: 9.52 | AI5: 9.67 | AJ5: 9.61 | AK5: 11.52 | AL5: 10.94 | AM5: 10.44 | AO5: 10.72 | AP5: 10.03 | AQ5: 10.05 | AR5: 9.85 | AS5: 9.84
B6: Tec-9 Rust Leaf FN | C6: {=LOOKUP(2,1/(I6:GA6<>""),I6:GA6)} -> 9.85 | D6: {=SUMPRODUCT(MAX((I6:GA6<>"")*COLUMN(I6:GA6)))} -> 45 | F6: =(C6-I6)/I6 -> 1.8223496 | G6: {=(C6-IF(ISNA(INDEX(I6:GA6,D6-22)),INDEX(I6:GA6,D6-23),INDEX(I6:GA6,D6-22)))/IF(ISNA(INDEX(I6:GA6,D6-22)),INDEX(I6:GA6,D6-23),INDEX(I6:GA6,D6-22))} -> -0.0060544904 | I6: 3.49 | J6: 3.76 | L6: 4.03 | N6: 4.41 | O6: 4.76 | P6: 6.12 | Q6: 6.58 | R6: 6.58 | S6: 6.57 | T6: 7.69 | U6: 8.53 | V6: 8.46 | W6: 8.48 | X6: 7.97 | Y6: 7.9 | Z6: 7.89 | AA6: 8.59 | AB6: 9.37 | AC6: 11.08 | AD6: 10.94 | AE6: 9.91 | AF6: 9.39 | AG6: 9.71 | AH6: 9.38 | AI6: 9.84 | AJ6: 9.82 | AK6: 12.53 | AL6: 10.21 | AM6: 10.02 | AO6: 10.9 | AP6: 10.28 | AQ6: 10.07 | AR6: 10.02 | AS6: 9.85
B7: Tec-9 Rust Leaf MW | C7: {=LOOKUP(2,1/(I7:GA7<>""),I7:GA7)} -> 9.11 | D7: {=SUMPRODUCT(MAX((I7:GA7<>"")*COLUMN(I7:GA7)))} -> 45 | F7: =(C7-I7)/I7 -> 1.5518207 | G7: {=(C7-IF(ISNA(INDEX(I7:GA7,D7-22)),INDEX(I7:GA7,D7-23),INDEX(I7:GA7,D7-22)))/IF(ISNA(INDEX(I7:GA7,D7-22)),INDEX(I7:GA7,D7-23),INDEX(I7:GA7,D7-22))} -> -0.059855521 | I7: 3.57 | J7: 3.56 | L7: 3.84 | N7: 4.29 | O7: 4.4 | P7: 5.67 | Q7: 5.87 | R7: 6.3 | S7: 6.23 | T7: 7.42 | U7: 7.86 | V7: 8.21 | W7: 8.05 | X7: 7.96 | Y7: 7.24 | Z7: 6.93 | AA7: 7.97 | AB7: 8.89 | AC7: 9.69 | AD7: 11.46 | AE7: 9.69 | AF7: 9.33 | AG7: 9.28 | AH7: 9.34 | AI7: 9.26 | AJ7: 9.15 | AK7: 9.89 | AL7: 10.51 | AM7: 9.62 | AO7: 9.27 | AP7: 9.77 | AQ7: 9.39 | AR7: 9.01 | AS7: 9.11
B8: XM1014 Banana Leaf FN | C8: {=LOOKUP(2,1/(I8:GA8<>""),I8:GA8)} -> 10.02 | D8: {=SUMPRODUCT(MAX((I8:GA8<>"")*COLUMN(I8:GA8)))} -> 45 | F8: =(C8-I8)/I8 -> 1.4202899 | G8: {=(C8-IF(ISNA(INDEX(I8:GA8,D8-22)),INDEX(I8:GA8,D8-23),INDEX(I8:GA8,D8-22)))/IF(ISNA(INDEX(I8:GA8,D8-22)),INDEX(I8:GA8,D8-23),INDEX(I8:GA8,D8-22))} -> -0.036538462 | I8: 4.14 | J8: 3.9 | L8: 3.9 | N8: 4.72 | O8: 5.1 | P8: 5.9 | Q8: 6.56 | R8: 7.13 | S8: 7.19 | T8: 7.96 | U8: 8.54 | V8: 8.32 | W8: 8.2 | X8: 7.6 | Y8: 7.55 | Z8: 7.85 | AA8: 8.78 | AB8: 9.06 | AC8: 10.08 | AD8: 10.84 | AE8: 10.4 | AF8: 9.62 | AG8: 10.18 | AH8: 10.04 | AI8: 10.04 | AJ8: 9.82 | AK8: 12.51 | AL8: 12.26 | AM8: 11.67 | AO8: 11.12 | AP8: 10.37 | AQ8: 10.49 | AR8: 10.58 | AS8: 10.02
B9: XM1014 Banana Leaf MW | C9: {=LOOKUP(2,1/(I9:GA9<>""),I9:GA9)} -> 9.22 | D9: {=SUMPRODUCT(MAX((I9:GA9<>"")*COLUMN(I9:GA9)))} -> 45 | F9: =(C9-I9)/I9 -> 1.5971831 | G9: {=(C9-IF(ISNA(INDEX(I9:GA9,D9-22)),INDEX(I9:GA9,D9-23),INDEX(I9:GA9,D9-22)))/IF(ISNA(INDEX(I9:GA9,D9-22)),INDEX(I9:GA9,D9-23),INDEX(I9:GA9,D9-22))} -> -0.033542977 | I9: 3.55 | J9: 3.44 | L9: 3.96 | N9: 4.43 | O9: 4.51 | P9: 6.71 | Q9: 7.22 | R9: 6.07 | S9: 6.58 | T9: 7.49 | U9: 8.13 | V9: 8.51 | W9: 7.87 | X9: 7.56 | Y9: 6.94 | Z9: 7.04 | AA9: 7.9 | AB9: 9.69 | AC9: 9.72 | AD9: 11.1 | AE9: 9.54 | AF9: 9.28 | AG9: 9.11 | AH9: 9.44 | AI9: 9.55 | AJ9: 9.57 | AK9: 9.67 | AL9: 10.42 | AM9: 9.52 | AO9: 9.56 | AP9: 9.13 | AQ9: 9.27 | AR9: 9.51 | AS9: 9.22
A13: Sale Revenue Steam Market
I14: =I2 -> 44331 | J14: =J2 -> 44332 | K14: =K2 -> 44333 | L14: =L2 -> 44334 | M14: =M2 -> 44335 | N14: =N2 -> 44336 | O14: =O2 -> 44337 | P14: =P2 -> 44338 | ... GA14: =GA2 -> 44505
B15: M4 Dark Blossom FN | C15: {=LOOKUP(2,1/(I15:GA15<>""),I15:GA15)} -> 7.48 | D15: =D$9 -> 45 | F15: =(C15-I15)/I15 -> 1.2735562 | G15: {=(C15-IF(ISNA(INDEX(I15:GA15,D15-22)),INDEX(I15:GA15,D15-23),INDEX(I15:GA15,D15-22)))/IF(ISNA(INDEX(I15:GA15,D15-22)),INDEX(I15:GA15,D15-23),INDEX(I15:GA15,D15-22))} -> -0.078817734 | I15: =IF(I3=0,NA(),I3-ROUNDUP(I3*0.1,2)-ROUNDUP(I3*0.05,2)) -> 3.29 | J15: =IF(J3=0,NA(),J3-ROUNDUP(J3*0.1,2)-ROUNDUP(J3*0.05,2)) -> 3.12 | K15: =IF(K3=0,NA(),K3-ROUNDUP(K3*0.1,2)-ROUNDUP(K3*0.05,2)) -> #N/A | L15: =IF(L3=0,NA(),L3-ROUNDUP(L3*0.1,2)-ROUNDUP(L3*0.05,2)) -> 3.35 | M15: =IF(M3=0,NA(),M3-ROUNDUP(M3*0.1,2)-ROUNDUP(M3*0.05,2)) -> #N/A | N15: =IF(N3=0,NA(),N3-ROUNDUP(N3*0.1,2)-ROUNDUP(N3*0.05,2)) -> 3.77 | O15: =IF(O3=0,NA(),O3-ROUNDUP(O3*0.1,2)-ROUNDUP(O3*0.05,2)) -> 3.73 | P15: =IF(P3=0,NA(),P3-ROUNDUP(P3*0.1,2)-ROUNDUP(P3*0.05,2)) -> 5.09 | ... GA15: =IF(GA3=0,NA(),GA3-ROUNDUP(GA3*0.1,2)-ROUNDUP(GA3*0.05,2)) -> #N/A
B16: M4 Dark Blossom MW | C16: {=LOOKUP(2,1/(I16:GA16<>""),I16:GA16)} -> 7.57 | D16: =D$9 -> 45 | F16: =(C16-I16)/I16 -> 1.5661017 | G16: {=(C16-IF(ISNA(INDEX(I16:GA16,D16-22)),INDEX(I16:GA16,D16-23),INDEX(I16:GA16,D16-22)))/IF(ISNA(INDEX(I16:GA16,D16-22)),INDEX(I16:GA16,D16-23),INDEX(I16:GA16,D16-22))} -> -0.092326139 | I16: =IF(I4=0,NA(),I4-ROUNDUP(I4*0.1,2)-ROUNDUP(I4*0.05,2)) -> 2.95 | J16: =IF(J4=0,NA(),J4-ROUNDUP(J4*0.1,2)-ROUNDUP(J4*0.05,2)) -> 2.98 | K16: =IF(K4=0,NA(),K4-ROUNDUP(K4*0.1,2)-ROUNDUP(K4*0.05,2)) -> #N/A | L16: =IF(L4=0,NA(),L4-ROUNDUP(L4*0.1,2)-ROUNDUP(L4*0.05,2)) -> 3.33 | M16: =IF(M4=0,NA(),M4-ROUNDUP(M4*0.1,2)-ROUNDUP(M4*0.05,2)) -> #N/A | N16: =IF(N4=0,NA(),N4-ROUNDUP(N4*0.1,2)-ROUNDUP(N4*0.05,2)) -> 3.63 | O16: =IF(O4=0,NA(),O4-ROUNDUP(O4*0.1,2)-ROUNDUP(O4*0.05,2)) -> 3.82 | P16: =IF(P4=0,NA(),P4-ROUNDUP(P4*0.1,2)-ROUNDUP(P4*0.05,2)) -> 4.93 | ... GA16: =IF(GA4=0,NA(),GA4-ROUNDUP(GA4*0.1,2)-ROUNDUP(GA4*0.05,2)) -> #N/A
B17: P90 Sunset Lily FN | C17: {=LOOKUP(2,1/(I17:GA17<>""),I17:GA17)} -> 8.35 | D17: =D$9 -> 45 | F17: =(C17-I17)/I17 -> 1.8114478 | G17: {=(C17-IF(ISNA(INDEX(I17:GA17,D17-22)),INDEX(I17:GA17,D17-23),INDEX(I17:GA17,D17-22)))/IF(ISNA(INDEX(I17:GA17,D17-22)),INDEX(I17:GA17,D17-23),INDEX(I17:GA17,D17-22))} -> -0.11919831 | I17: =IF(I5=0,NA(),I5-ROUNDUP(I5*0.1,2)-ROUNDUP(I5*0.05,2)) -> 2.97 | J17: =IF(J5=0,NA(),J5-ROUNDUP(J5*0.1,2)-ROUNDUP(J5*0.05,2)) -> 3.14 | K17: =IF(K5=0,NA(),K5-ROUNDUP(K5*0.1,2)-ROUNDUP(K5*0.05,2)) -> #N/A | L17: =IF(L5=0,NA(),L5-ROUNDUP(L5*0.1,2)-ROUNDUP(L5*0.05,2)) -> 3.31 | M17: =IF(M5=0,NA(),M5-ROUNDUP(M5*0.1,2)-ROUNDUP(M5*0.05,2)) -> #N/A | N17: =IF(N5=0,NA(),N5-ROUNDUP(N5*0.1,2)-ROUNDUP(N5*0.05,2)) -> 3.57 | O17: =IF(O5=0,NA(),O5-ROUNDUP(O5*0.1,2)-ROUNDUP(O5*0.05,2)) -> 3.82 | P17: =IF(P5=0,NA(),P5-ROUNDUP(P5*0.1,2)-ROUNDUP(P5*0.05,2)) -> 5.61 | ... GA17: =IF(GA5=0,NA(),GA5-ROUNDUP(GA5*0.1,2)-ROUNDUP(GA5*0.05,2)) -> #N/A
B18: Tec-9 Rust Leaf FN | C18: {=LOOKUP(2,1/(I18:GA18<>""),I18:GA18)} -> 8.36 | D18: =D$9 -> 45 | F18: =(C18-I18)/I18 -> 1.8243243 | G18: {=(C18-IF(ISNA(INDEX(I18:GA18,D18-22)),INDEX(I18:GA18,D18-23),INDEX(I18:GA18,D18-22)))/IF(ISNA(INDEX(I18:GA18,D18-22)),INDEX(I18:GA18,D18-23),INDEX(I18:GA18,D18-22))} -> -0.0059453032 | I18: =IF(I6=0,NA(),I6-ROUNDUP(I6*0.1,2)-ROUNDUP(I6*0.05,2)) -> 2.96 | J18: =IF(J6=0,NA(),J6-ROUNDUP(J6*0.1,2)-ROUNDUP(J6*0.05,2)) -> 3.19 | K18: =IF(K6=0,NA(),K6-ROUNDUP(K6*0.1,2)-ROUNDUP(K6*0.05,2)) -> #N/A | L18: =IF(L6=0,NA(),L6-ROUNDUP(L6*0.1,2)-ROUNDUP(L6*0.05,2)) -> 3.41 | M18: =IF(M6=0,NA(),M6-ROUNDUP(M6*0.1,2)-ROUNDUP(M6*0.05,2)) -> #N/A | N18: =IF(N6=0,NA(),N6-ROUNDUP(N6*0.1,2)-ROUNDUP(N6*0.05,2)) -> 3.73 | O18: =IF(O6=0,NA(),O6-ROUNDUP(O6*0.1,2)-ROUNDUP(O6*0.05,2)) -> 4.04 | P18: =IF(P6=0,NA(),P6-ROUNDUP(P6*0.1,2)-ROUNDUP(P6*0.05,2)) -> 5.19 | ... GA18: =IF(GA6=0,NA(),GA6-ROUNDUP(GA6*0.1,2)-ROUNDUP(GA6*0.05,2)) -> #N/A
B19: Tec-9 Rust Leaf MW | C19: {=LOOKUP(2,1/(I19:GA19<>""),I19:GA19)} -> 7.73 | D19: =D$9 -> 45 | F19: =(C19-I19)/I19 -> 1.5511551 | G19: {=(C19-IF(ISNA(INDEX(I19:GA19,D19-22)),INDEX(I19:GA19,D19-23),INDEX(I19:GA19,D19-22)))/IF(ISNA(INDEX(I19:GA19,D19-22)),INDEX(I19:GA19,D19-23),INDEX(I19:GA19,D19-22))} -> -0.060753341 | I19: =IF(I7=0,NA(),I7-ROUNDUP(I7*0.1,2)-ROUNDUP(I7*0.05,2)) -> 3.03 | J19: =IF(J7=0,NA(),J7-ROUNDUP(J7*0.1,2)-ROUNDUP(J7*0.05,2)) -> 3.02 | K19: =IF(K7=0,NA(),K7-ROUNDUP(K7*0.1,2)-ROUNDUP(K7*0.05,2)) -> #N/A | L19: =IF(L7=0,NA(),L7-ROUNDUP(L7*0.1,2)-ROUNDUP(L7*0.05,2)) -> 3.25 | M19: =IF(M7=0,NA(),M7-ROUNDUP(M7*0.1,2)-ROUNDUP(M7*0.05,2)) -> #N/A | N19: =IF(N7=0,NA(),N7-ROUNDUP(N7*0.1,2)-ROUNDUP(N7*0.05,2)) -> 3.64 | O19: =IF(O7=0,NA(),O7-ROUNDUP(O7*0.1,2)-ROUNDUP(O7*0.05,2)) -> 3.74 | P19: =IF(P7=0,NA(),P7-ROUNDUP(P7*0.1,2)-ROUNDUP(P7*0.05,2)) -> 4.81 | ... GA19: =IF(GA7=0,NA(),GA7-ROUNDUP(GA7*0.1,2)-ROUNDUP(GA7*0.05,2)) -> #N/A
