Workbook

Sheet Graphs

Sheet Total
A1: Category | B1: =Inventory!E1 -> 44331 | C1: =Inventory!F1 -> 44332 | D1: =Inventory!G1 -> 44334 | E1: =Inventory!H1 -> 44336 | F1: =Inventory!I1 -> 44337 | G1: =Inventory!J1 -> 44338 | H1: =Inventory!K1 -> 44339 | I1: =Inventory!L1 -> 44340 | ... FR1: =Inventory!FU1 -> 44505
A2: Knife | B2: =Knives!E10 -> 1973.04 | C2: =Knives!F10 -> 1981.9 | D2: =Knives!G10 -> 2000.11 | E2: =Knives!H10 -> 2012.33 | F2: =Knives!I10 -> 2033.07 | G2: =Knives!J10 -> 1997.22 | H2: =Knives!K10 -> 2013.88 | I2: =Knives!L10 -> 2043.27 | ... W2: =Knives!Z10 -> 0
A3: AWP | B3: =AWP!E13 -> 195.47 | C3: =AWP!F13 -> 190.54 | D3: =AWP!G13 -> 199.99 | E3: =AWP!H13 -> 193.31 | F3: =AWP!I13 -> 193.19 | G3: =AWP!J13 -> 185.44 | H3: =AWP!K13 -> 198.11 | I3: =AWP!L13 -> 199.2 | ... W3: =AWP!Z13 -> 0
A4: AK-47 | B4: ='AK-47'!E12 -> 385.2 | C4: ='AK-47'!F12 -> 398.33 | D4: ='AK-47'!G12 -> 408.55 | E4: ='AK-47'!H12 -> 396.45 | F4: ='AK-47'!I12 -> 401.81 | G4: ='AK-47'!J12 -> 389.48 | H4: ='AK-47'!K12 -> 389.59 | I4: ='AK-47'!L12 -> 395.05 | ... W4: ='AK-47'!Z12 -> 0
A5: M4A4 | B5: =M4A4!E14 -> 178.95 | C5: =M4A4!F14 -> 175.29 | D5: =M4A4!G14 -> 172.94 | E5: =M4A4!H14 -> 175.82 | F5: =M4A4!I14 -> 175.51 | G5: =M4A4!J14 -> 177.33 | H5: =M4A4!K14 -> 173.11 | I5: =M4A4!L14 -> 171.3 | ... W5: =M4A4!Z14 -> 0
A6: M4A1-S | B6: ='M4A1-S'!E10 -> 76.64 | C6: ='M4A1-S'!F10 -> 74.11 | D6: ='M4A1-S'!G10 -> 72.6 | E6: ='M4A1-S'!H10 -> 70.94 | F6: ='M4A1-S'!I10 -> 74.35 | G6: ='M4A1-S'!J10 -> 72.74 | H6: ='M4A1-S'!K10 -> 70.75 | I6: ='M4A1-S'!L10 -> 72.7 | ... W6: ='M4A1-S'!Z10 -> 0
A7: SMG | B7: =SMG!E20 -> 66.95 | C7: =SMG!F20 -> 67.2 | D7: =SMG!G20 -> 63.86 | E7: =SMG!H20 -> 63.06 | F7: =SMG!I20 -> 66.27 | G7: =SMG!J20 -> 67.62 | H7: =SMG!K20 -> 66.72 | I7: =SMG!L20 -> 66.37 | ... W7: =SMG!Z20 -> 0
A8: Pistol | B8: =Pistol!E37 -> 346.62 | C8: =Pistol!F37 -> 340.68 | D8: =Pistol!G37 -> 342.52 | E8: =Pistol!H37 -> 349.93 | F8: =Pistol!I37 -> 345.59 | G8: =Pistol!J37 -> 347.57 | H8: =Pistol!K37 -> 350.87 | I8: =Pistol!L37 -> 349.74 | ... W8: =Pistol!Z37 -> 0
A9: Heavy | B9: =Heavy!E17 -> 23.47 | C9: =Heavy!F17 -> 23.17 | D9: =Heavy!G17 -> 22.01 | E9: =Heavy!H17 -> 22.6 | F9: =Heavy!I17 -> 22.22 | G9: =Heavy!J17 -> 22.89 | H9: =Heavy!K17 -> 21.77 | I9: =Heavy!L17 -> 22.73 | ... W9: =Heavy!Z17 -> 0
A10: Other Rifles | B10: ='Other Rifles'!E23 -> 0 | C10: ='Other Rifles'!F23 -> 0 | D10: ='Other Rifles'!G23 -> 0 | E10: ='Other Rifles'!H23 -> 0 | F10: ='Other Rifles'!I23 -> 0 | G10: ='Other Rifles'!J23 -> 0 | H10: ='Other Rifles'!K23 -> 102.48 | I10: ='Other Rifles'!L23 -> 98.56 | ... W10: ='Other Rifles'!Z23 -> 0
A11: Case-Investments | B11: =Cases!D48 -> 379.7 | C11: =Cases!E48 -> 379.7 | D11: =Cases!F48 -> 379.7 | E11: =Cases!G48 -> 393.7 | F11: =Cases!H48 -> 392.2 | G11: =Cases!I48 -> 398.2 | H11: =Cases!J48 -> 372.2 | I11: =Cases!K48 -> 392.2 | ... W11: =Cases!Y48 -> 576.7
A12: Skin-Investments
B19: =B1 -> 44331 | C19: =C1 -> 44332 | D19: =D1 -> 44334 | E19: =E1 -> 44336 | F19: =F1 -> 44337 | G19: =G1 -> 44338 | H19: =H1 -> 44339 | I19: =I1 -> 44340 | ... FR19: =FR1 -> 44505
A20: Knife | B20: =Knives!E27 -> 1381.11 | C20: =Knives!F27 -> 1387.32 | D20: =Knives!G27 -> 1400.07 | E20: =Knives!H27 -> 1408.61 | F20: =Knives!I27 -> 1423.13 | G20: =Knives!J27 -> 1398.04 | H20: =Knives!K27 -> 1409.7 | I20: =Knives!L27 -> 1430.27 | ... W20: =Knives!Z27 -> 0
A21: AWP | B21: =AWP!E28 -> 136.79 | C21: =AWP!F28 -> 133.34 | D21: =AWP!G28 -> 139.96 | E21: =AWP!H28 -> 135.28 | F21: =AWP!I28 -> 135.2 | G21: =AWP!J28 -> 129.78 | H21: =AWP!K28 -> 138.64 | I21: =AWP!L28 -> 139.4 | ... W21: =AWP!Z28 -> 0
A22: AK-47 | B22: ='AK-47'!E26 -> 269.6 | C22: ='AK-47'!F26 -> 278.8 | D22: ='AK-47'!G26 -> 285.96 | E22: ='AK-47'!H26 -> 277.49 | F22: ='AK-47'!I26 -> 281.24 | G22: ='AK-47'!J26 -> 272.62 | H22: ='AK-47'!K26 -> 272.69 | I22: ='AK-47'!L26 -> 276.5 | ... W22: ='AK-47'!Z26 -> 0
A23: M4A4 | B23: =M4A4!E30 -> 125.22 | C23: =M4A4!F30 -> 122.66 | D23: =M4A4!G30 -> 121.04 | E23: =M4A4!H30 -> 123.03 | F23: =M4A4!I30 -> 122.83 | G23: =M4A4!J30 -> 124.1 | H23: =M4A4!K30 -> 121.14 | I23: =M4A4!L30 -> 119.88 | ... W23: =M4A4!Z30 -> 0
A24: M4A1-S | B24: ='M4A1-S'!E23 -> 53.63 | C24: ='M4A1-S'!F23 -> 51.86 | D24: ='M4A1-S'!G23 -> 50.8 | E24: ='M4A1-S'!H23 -> 49.64 | F24: ='M4A1-S'!I23 -> 52.03 | G24: ='M4A1-S'!J23 -> 50.89 | H24: ='M4A1-S'!K23 -> 49.5 | I24: ='M4A1-S'!L23 -> 50.87 | ... W24: ='M4A1-S'!Z23 -> 0
A25: SMG | B25: =SMG!E42 -> 46.83 | C25: =SMG!F42 -> 46.96 | D25: =SMG!G42 -> 44.63 | E25: =SMG!H42 -> 44.09 | F25: =SMG!I42 -> 46.32 | G25: =SMG!J42 -> 47.25 | H25: =SMG!K42 -> 46.64 | I25: =SMG!L42 -> 46.39 | ... W25: =SMG!Z42 -> 0
A26: Pistol | B26: =Pistol!E77 -> 242.49 | C26: =Pistol!F77 -> 238.36 | D26: =Pistol!G77 -> 239.6 | E26: =Pistol!H77 -> 244.81 | F26: =Pistol!I77 -> 241.79 | G26: =Pistol!J77 -> 243.17 | H26: =Pistol!K77 -> 245.47 | I26: =Pistol!L77 -> 244.69 | ... W26: =Pistol!Z77 -> 0
A27: Heavy | B27: =Heavy!E37 -> 16.39 | C27: =Heavy!F37 -> 16.17 | D27: =Heavy!G37 -> 15.35 | E27: =Heavy!H37 -> 15.77 | F27: =Heavy!I37 -> 15.51 | G27: =Heavy!J37 -> 16 | H27: =Heavy!K37 -> 15.21 | I27: =Heavy!L37 -> 15.87 | ... W27: =Heavy!Z37 -> 0
A28: Other Rifles | B28: ='Other Rifles'!E50 -> 0 | C28: ='Other Rifles'!F50 -> 0 | D28: ='Other Rifles'!G50 -> 0 | E28: ='Other Rifles'!H50 -> 0 | F28: ='Other Rifles'!I50 -> 0 | G28: ='Other Rifles'!J50 -> 0 | H28: ='Other Rifles'!K50 -> 71.66 | I28: ='Other Rifles'!L50 -> 68.91 | ... W28: ='Other Rifles'!Z50 -> 0
A29: Case-Investments | B29: =Cases!D49 -> 213.12 | C29: =Cases!E49 -> 213.12 | D29: =Cases!F49 -> 213.12 | E29: =Cases!G49 -> 224.32 | F29: =Cases!H49 -> 224.32 | G29: =Cases!I49 -> 227.92 | H29: =Cases!J49 -> 208.32 | I29: =Cases!K49 -> 224.32 | ... W29: =Cases!Y49 -> 353
A30: Skin-Investments
B36: =B19 -> 44331 | C36: =C19 -> 44332 | D36: =D19 -> 44334 | E36: =E19 -> 44336 | F36: =F19 -> 44337 | G36: =G19 -> 44338 | H36: =H19 -> 44339 | I36: =I19 -> 44340 | ... FR36: =FR19 -> 44505
A37: Total | B37: =SUM(B2:B12) -> 3626.04 | C37: =SUM(C2:C12) -> 3630.92 | D37: =SUM(D2:D12) -> 3662.28 | E37: =SUM(E2:E12) -> 3678.14 | F37: =SUM(F2:F12) -> 3704.21 | G37: =SUM(G2:G12) -> 3658.49 | H37: =SUM(H2:H12) -> 3759.48 | I37: =SUM(I2:I12) -> 3811.12 | ... W37: =SUM(W2:W12) -> 576.7
A38: Sale-Revenue | B38: =SUM(B20:B30) -> 2485.18 | C38: =SUM(C20:C30) -> 2488.59 | D38: =SUM(D20:D30) -> 2510.53 | E38: =SUM(E20:E30) -> 2523.04 | F38: =SUM(F20:F30) -> 2542.37 | G38: =SUM(G20:G30) -> 2509.77 | H38: =SUM(H20:H30) -> 2578.97 | I38: =SUM(I20:I30) -> 2617.1 | ... W38: =SUM(W20:W30) -> 353

Sheet Cases
C3: Cases
D4: =Inventory!E1 -> 44331 | E4: =Inventory!F1 -> 44332 | F4: =Inventory!G1 -> 44334 | G4: =Inventory!H1 -> 44336 | H4: =Inventory!I1 -> 44337 | I4: =Inventory!J1 -> 44338 | J4: =Inventory!K1 -> 44339 | K4: =Inventory!L1 -> 44340 | ... FT4: =Inventory!FU1 -> 44505
C5: Prisma 2 | D5: 0.05 | E5: 0.05 | F5: 0.05 | G5: 0.06 | H5: 0.06 | I5: 0.06 | J5: 0.05 | K5: 0.06 | L5: 0.06 | M5: 0.06 | N5: 0.06 | O5: 0.06 | P5: 0.06 | Q5: 0.05 | R5: 0.06 | S5: 0.06 | T5: 0.06 | U5: 0.06 | V5: 0.07 | W5: 0.08 | X5: 0.07 | Y5: 0.08
C6: Danger Zone | D6: 0.07 | E6: 0.07 | F6: 0.07 | G6: 0.07 | H6: 0.07 | I6: 0.07 | J6: 0.07 | K6: 0.07 | L6: 0.07 | M6: 0.07 | N6: 0.07 | O6: 0.06 | P6: 0.06 | Q6: 0.07 | R6: 0.07 | S6: 0.07 | T6: 0.07 | U6: 0.07 | V6: 0.08 | W6: 0.09 | X6: 0.08 | Y6: 0.09
C7: Prisma | D7: 0.07 | E7: 0.07 | F7: 0.07 | G7: 0.07 | H7: 0.07 | I7: 0.07 | J7: 0.07 | K7: 0.07 | L7: 0.07 | M7: 0.07 | N7: 0.07 | O7: 0.07 | P7: 0.07 | Q7: 0.07 | R7: 0.07 | S7: 0.08 | T7: 0.08 | U7: 0.08 | V7: 0.09 | W7: 0.12 | X7: 0.1 | Y7: 0.1
C8: Horizon | D8: 0.07 | E8: 0.07 | F8: 0.07 | G8: 0.07 | H8: 0.07 | I8: 0.07 | J8: 0.07 | K8: 0.07 | L8: 0.07 | M8: 0.07 | N8: 0.07 | O8: 0.07 | P8: 0.07 | Q8: 0.07 | R8: 0.07 | S8: 0.07 | T8: 0.07 | U8: 0.07 | V8: 0.12 | W8: 0.14 | X8: 0.11 | Y8: 0.12
C9: CS20 | D9: 0.08 | E9: 0.08 | F9: 0.08 | G9: 0.08 | H9: 0.08 | I9: 0.08 | J9: 0.08 | K9: 0.08 | L9: 0.08 | M9: 0.08 | N9: 0.08 | O9: 0.08 | P9: 0.08 | Q9: 0.08 | R9: 0.08 | S9: 0.08 | T9: 0.08 | U9: 0.08 | V9: 0.16 | W9: 0.21 | X9: 0.17 | Y9: 0.18
C10: Fracture | D10: 0.35 | E10: 0.35 | F10: 0.35 | G10: 0.31 | H10: 0.3 | I10: 0.34 | J10: 0.3 | K10: 0.3 | L10: 0.31 | M10: 0.3 | N10: 0.31 | O10: 0.3 | P10: 0.32 | Q10: 0.32 | R10: 0.34 | S10: 0.3 | T10: 0.32 | U10: 0.3 | V10: 0.35 | W10: 0.35 | X10: 0.32 | Y10: 0.32
C11: Clutch | D11: 0.21 | E11: 0.21 | F11: 0.21 | G11: 0.21 | H11: 0.21 | I11: 0.21 | J11: 0.21 | K11: 0.21 | L11: 0.21 | M11: 0.2 | N11: 0.2 | O11: 0.21 | P11: 0.21 | Q11: 0.24 | R11: 0.24 | S11: 0.24 | T11: 0.26 | U11: 0.27 | V11: 0.34 | W11: 0.43 | X11: 0.3 | Y11: 0.31
C12: Spectrum 2 | D12: 0.17 | E12: 0.17 | F12: 0.19 | G12: 0.19 | H12: 0.17 | I12: 0.18 | J12: 0.18 | K12: 0.17 | L12: 0.17 | M12: 0.18 | N12: 0.18 | O12: 0.19 | P12: 0.2 | Q12: 0.21 | R12: 0.21 | S12: 0.24 | T12: 0.24 | U12: 0.23 | V12: 0.34 | W12: 0.39 | X12: 0.34 | Y12: 0.36
C13: Spectrum | D13: 0.59 | E13: 0.58 | F13: 0.55 | G13: 0.53 | H13: 0.6 | I13: 0.6 | J13: 0.6 | K13: 0.61 | L13: 0.58 | M13: 0.61 | N13: 0.58 | O13: 0.62 | P13: 0.65 | Q13: 0.66 | R13: 0.65 | S13: 0.66 | T13: 0.64 | U13: 0.64 | V13: 0.72 | W13: 0.86 | X13: 0.73 | Y13: 0.64
C14: Shattered Web | D14: 1.12 | E14: 1.12 | F14: 1.2 | G14: 1.24 | H14: 1.21 | I14: 1.26 | J14: 1.27 | K14: 1.31 | L14: 1.53 | M14: 1.45 | N14: 1.51 | O14: 1.49 | P14: 1.41 | Q14: 1.39 | R14: 1.31 | S14: 1.34 | T14: 1.31 | U14: 1.35 | V14: 1.35 | W14: 1.35 | X14: 1.46 | Y14: 1.46
A16: Investments
A18: Buy-value | D18: =D4 -> 44331 | E18: =E4 -> 44332 | F18: =F4 -> 44334 | G18: =G4 -> 44336 | H18: =H4 -> 44337 | I18: =I4 -> 44338 | J18: =J4 -> 44339 | K18: =K4 -> 44340 | ... FT18: =FT4 -> 44505
A19: 0.06 | C19: Prisma 2 | D19: =D5 -> 0.05 | E19: =E5 -> 0.05 | F19: =F5 -> 0.05 | G19: =G5 -> 0.06 | H19: =H5 -> 0.06 | I19: =I5 -> 0.06 | J19: =J5 -> 0.05 | K19: =K5 -> 0.06 | ... Y19: =Y5 -> 0.08
A20: 0.07 | C20: Danger Zone | D20: =D6 -> 0.07 | E20: =E6 -> 0.07 | F20: =F6 -> 0.07 | G20: =G6 -> 0.07 | H20: =H6 -> 0.07 | I20: =I6 -> 0.07 | J20: =J6 -> 0.07 | K20: =K6 -> 0.07 | ... Y20: =Y6 -> 0.09
A21: 0.1 | C21: Horizon | D21: =D8 -> 0.07 | E21: =E8 -> 0.07 | F21: =F8 -> 0.07 | G21: =G8 -> 0.07 | H21: =H8 -> 0.07 | I21: =I8 -> 0.07 | J21: =J8 -> 0.07 | K21: =K8 -> 0.07 | ... Y21: =Y8 -> 0.12
A22: 0.12 | C22: CS20 | D22: =D9 -> 0.08 | E22: =E9 -> 0.08 | F22: =F9 -> 0.08 | G22: =G9 -> 0.08 | H22: =H9 -> 0.08 | I22: =I9 -> 0.08 | J22: =J9 -> 0.08 | K22: =K9 -> 0.08 | ... Y22: =Y9 -> 0.18
A23: 0.57 | C23: Fracture Cases | D23: =D10 -> 0.35 | E23: =E10 -> 0.35 | F23: =F10 -> 0.35 | G23: =G10 -> 0.31 | H23: =H10 -> 0.3 | I23: =I10 -> 0.34 | J23: =J10 -> 0.3 | K23: =K10 -> 0.3 | ... Y23: =Y10 -> 0.32
B25: 2000 | C25: Prisma 2 | D25: =D19*$B25 -> 100 | E25: =E19*$B25 -> 100 | F25: =F19*$B25 -> 100 | G25: =G19*$B25 -> 120 | H25: =H19*$B25 -> 120 | I25: =I19*$B25 -> 120 | J25: =J19*$B25 -> 100 | K25: =K19*$B25 -> 120 | ... Y25: =Y19*$B25 -> 160
B26: 1000 | C26: Danger Zone | D26: =D20*$B26 -> 70 | E26: =E20*$B26 -> 70 | F26: =F20*$B26 -> 70 | G26: =G20*$B26 -> 70 | H26: =H20*$B26 -> 70 | I26: =I20*$B26 -> 70 | J26: =J20*$B26 -> 70 | K26: =K20*$B26 -> 70 | ... Y26: =Y20*$B26 -> 90
B27: 2000 | C27: Horizon | D27: =D21*$B27 -> 140 | E27: =E21*$B27 -> 140 | F27: =F21*$B27 -> 140 | G27: =G21*$B27 -> 140 | H27: =H21*$B27 -> 140 | I27: =I21*$B27 -> 140 | J27: =J21*$B27 -> 140 | K27: =K21*$B27 -> 140 | ... Y27: =Y21*$B27 -> 240
B28: 215 | C28: CS20 | D28: =D22*$B28 -> 17.2 | E28: =E22*$B28 -> 17.2 | F28: =F22*$B28 -> 17.2 | G28: =G22*$B28 -> 17.2 | H28: =H22*$B28 -> 17.2 | I28: =I22*$B28 -> 17.2 | J28: =J22*$B28 -> 17.2 | K28: =K22*$B28 -> 17.2 | ... Y28: =Y22*$B28 -> 38.7
B29: 150 | C29: Fracture Cases | D29: =D23*$B29 -> 52.5 | E29: =E23*$B29 -> 52.5 | F29: =F23*$B29 -> 52.5 | G29: =G23*$B29 -> 46.5 | H29: =H23*$B29 -> 45 | I29: =I23*$B29 -> 51 | J29: =J23*$B29 -> 45 | K29: =K23*$B29 -> 45 | ... Y29: =Y23*$B29 -> 48
D32: =D18 -> 44331 | E32: =E18 -> 44332 | F32: =F18 -> 44334 | G32: =G18 -> 44336 | H32: =H18 -> 44337 | I32: =I18 -> 44338 | J32: =J18 -> 44339 | K32: =K18 -> 44340 | ... FT32: =FT18 -> 44505
C33: Prisma 2 | D33: =D19-ROUNDUP(D19*0.1,2)-ROUNDUP(D19*0.05,2) -> 0.03 | E33: =E19-ROUNDUP(E19*0.1,2)-ROUNDUP(E19*0.05,2) -> 0.03 | F33: =F19-ROUNDUP(F19*0.1,2)-ROUNDUP(F19*0.05,2) -> 0.03 | G33: =G19-ROUNDUP(G19*0.1,2)-ROUNDUP(G19*0.05,2) -> 0.04 | H33: =H19-ROUNDUP(H19*0.1,2)-ROUNDUP(H19*0.05,2) -> 0.04 | I33: =I19-ROUNDUP(I19*0.1,2)-ROUNDUP(I19*0.05,2) -> 0.04 | J33: =J19-ROUNDUP(J19*0.1,2)-ROUNDUP(J19*0.05,2) -> 0.03 | K33: =K19-ROUNDUP(K19*0.1,2)-ROUNDUP(K19*0.05,2) -> 0.04 | ... Y33: =Y19-ROUNDUP(Y19*0.1,2)-ROUNDUP(Y19*0.05,2) -> 0.06
C34: Danger Zone | D34: =D20-ROUNDUP(D20*0.1,2)-ROUNDUP(D20*0.05,2) -> 0.05 | E34: =E20-ROUNDUP(E20*0.1,2)-ROUNDUP(E20*0.05,2) -> 0.05 | F34: =F20-ROUNDUP(F20*0.1,2)-ROUNDUP(F20*0.05,2) -> 0.05 | G34: =G20-ROUNDUP(G20*0.1,2)-ROUNDUP(G20*0.05,2) -> 0.05 | H34: =H20-ROUNDUP(H20*0.1,2)-ROUNDUP(H20*0.05,2) -> 0.05 | I34: =I20-ROUNDUP(I20*0.1,2)-ROUNDUP(I20*0.05,2) -> 0.05 | J34: =J20-ROUNDUP(J20*0.1,2)-ROUNDUP(J20*0.05,2) -> 0.05 | K34: =K20-ROUNDUP(K20*0.1,2)-ROUNDUP(K20*0.05,2) -> 0.05 | ... Y34: =Y20-ROUNDUP(Y20*0.1,2)-ROUNDUP(Y20*0.05,2) -> 0.07
C35: Horizon | D35: =D21-ROUNDUP(D21*0.1,2)-ROUNDUP(D21*0.05,2) -> 0.05 | E35: =E21-ROUNDUP(E21*0.1,2)-ROUNDUP(E21*0.05,2) -> 0.05 | F35: =F21-ROUNDUP(F21*0.1,2)-ROUNDUP(F21*0.05,2) -> 0.05 | G35: =G21-ROUNDUP(G21*0.1,2)-ROUNDUP(G21*0.05,2) -> 0.05 | H35: =H21-ROUNDUP(H21*0.1,2)-ROUNDUP(H21*0.05,2) -> 0.05 | I35: =I21-ROUNDUP(I21*0.1,2)-ROUNDUP(I21*0.05,2) -> 0.05 | J35: =J21-ROUNDUP(J21*0.1,2)-ROUNDUP(J21*0.05,2) -> 0.05 | K35: =K21-ROUNDUP(K21*0.1,2)-ROUNDUP(K21*0.05,2) -> 0.05 | ... Y35: =Y21-ROUNDUP(Y21*0.1,2)-ROUNDUP(Y21*0.05,2) -> 0.09
C36: CS20 | D36: =D22-ROUNDUP(D22*0.1,2)-ROUNDUP(D22*0.05,2) -> 0.06 | E36: =E22-ROUNDUP(E22*0.1,2)-ROUNDUP(E22*0.05,2) -> 0.06 | F36: =F22-ROUNDUP(F22*0.1,2)-ROUNDUP(F22*0.05,2) -> 0.06 | G36: =G22-ROUNDUP(G22*0.1,2)-ROUNDUP(G22*0.05,2) -> 0.06 | H36: =H22-ROUNDUP(H22*0.1,2)-ROUNDUP(H22*0.05,2) -> 0.06 | I36: =I22-ROUNDUP(I22*0.1,2)-ROUNDUP(I22*0.05,2) -> 0.06 | J36: =J22-ROUNDUP(J22*0.1,2)-ROUNDUP(J22*0.05,2) -> 0.06 | K36: =K22-ROUNDUP(K22*0.1,2)-ROUNDUP(K22*0.05,2) -> 0.06 | ... Y36: =Y22-ROUNDUP(Y22*0.1,2)-ROUNDUP(Y22*0.05,2) -> 0.15
C37: Fracture Cases | D37: =D23-ROUNDUP(D23*0.1,2)-ROUNDUP(D23*0.05,2) -> 0.29 | E37: =E23-ROUNDUP(E23*0.1,2)-ROUNDUP(E23*0.05,2) -> 0.29 | F37: =F23-ROUNDUP(F23*0.1,2)-ROUNDUP(F23*0.05,2) -> 0.29 | G37: =G23-ROUNDUP(G23*0.1,2)-ROUNDUP(G23*0.05,2) -> 0.25 | H37: =H23-ROUNDUP(H23*0.1,2)-ROUNDUP(H23*0.05,2) -> 0.25 | I37: =I23-ROUNDUP(I23*0.1,2)-ROUNDUP(I23*0.05,2) -> 0.28 | J37: =J23-ROUNDUP(J23*0.1,2)-ROUNDUP(J23*0.05,2) -> 0.25 | K37: =K23-ROUNDUP(K23*0.1,2)-ROUNDUP(K23*0.05,2) -> 0.25 | ... Y37: =Y23-ROUNDUP(Y23*0.1,2)-ROUNDUP(Y23*0.05,2) -> 0.26
B39: 2000 | C39: Prisma 2 | D39: =($B39*D33)*0.8 -> 48 | E39: =($B39*E33)*0.8 -> 48 | F39: =($B39*F33)*0.8 -> 48 | G39: =($B39*G33)*0.8 -> 64 | H39: =($B39*H33)*0.8 -> 64 | I39: =($B39*I33)*0.8 -> 64 | J39: =($B39*J33)*0.8 -> 48 | K39: =($B39*K33)*0.8 -> 64 | ... Y39: =($B39*Y33)*0.8 -> 96
B40: 1000 | C40: Danger Zone | D40: =($B40*D34)*0.8 -> 40 | E40: =($B40*E34)*0.8 -> 40 | F40: =($B40*F34)*0.8 -> 40 | G40: =($B40*G34)*0.8 -> 40 | H40: =($B40*H34)*0.8 -> 40 | I40: =($B40*I34)*0.8 -> 40 | J40: =($B40*J34)*0.8 -> 40 | K40: =($B40*K34)*0.8 -> 40 | ... Y40: =($B40*Y34)*0.8 -> 56
B41: 2000 | C41: Horizon | D41: =($B41*D35)*0.8 -> 80 | E41: =($B41*E35)*0.8 -> 80 | F41: =($B41*F35)*0.8 -> 80 | G41: =($B41*G35)*0.8 -> 80 | H41: =($B41*H35)*0.8 -> 80 | I41: =($B41*I35)*0.8 -> 80 | J41: =($B41*J35)*0.8 -> 80 | K41: =($B41*K35)*0.8 -> 80 | ... Y41: =($B41*Y35)*0.8 -> 144
B42: 215 | C42: CS20 | D42: =($B42*D36)*0.8 -> 10.32 | E42: =($B42*E36)*0.8 -> 10.32 | F42: =($B42*F36)*0.8 -> 10.32 | G42: =($B42*G36)*0.8 -> 10.32 | H42: =($B42*H36)*0.8 -> 10.32 | I42: =($B42*I36)*0.8 -> 10.32 | J42: =($B42*J36)*0.8 -> 10.32 | K42: =($B42*K36)*0.8 -> 10.32 | ... Y42: =($B42*Y36)*0.8 -> 25.8
B43: 150 | C43: Fracture Cases | D43: =($B43*D37)*0.8 -> 34.8 | E43: =($B43*E37)*0.8 -> 34.8 | F43: =($B43*F37)*0.8 -> 34.8 | G43: =($B43*G37)*0.8 -> 30 | H43: =($B43*H37)*0.8 -> 30 | I43: =($B43*I37)*0.8 -> 33.6 | J43: =($B43*J37)*0.8 -> 30 | K43: =($B43*K37)*0.8 -> 30 | ... Y43: =($B43*Y37)*0.8 -> 31.2
D47: =D32 -> 44331 | E47: =E32 -> 44332 | F47: =F32 -> 44334 | G47: =G32 -> 44336 | H47: =H32 -> 44337 | I47: =I32 -> 44338 | J47: =J32 -> 44339 | K47: =K32 -> 44340 | ... FT47: =FT32 -> 44505
C48: Total | D48: =SUM(D25:D29) -> 379.7 | E48: =SUM(E25:E29) -> 379.7 | F48: =SUM(F25:F29) -> 379.7 | G48: =SUM(G25:G29) -> 393.7 | H48: =SUM(H25:H29) -> 392.2 | I48: =SUM(I25:I29) -> 398.2 | J48: =SUM(J25:J29) -> 372.2 | K48: =SUM(K25:K29) -> 392.2 | ... Y48: =SUM(Y25:Y29) -> 576.7
C49: Sale-Revenue | D49: =SUM(D39:D43) -> 213.12 | E49: =SUM(E39:E43) -> 213.12 | F49: =SUM(F39:F43) -> 213.12 | G49: =SUM(G39:G43) -> 224.32 | H49: =SUM(H39:H43) -> 224.32 | I49: =SUM(I39:I43) -> 227.92 | J49: =SUM(J39:J43) -> 208.32 | K49: =SUM(K39:K43) -> 224.32 | ... Y49: =SUM(Y39:Y43) -> 353
D54: =D47 -> 44331 | E54: =E47 -> 44332 | F54: =F47 -> 44334 | G54: =G47 -> 44336 | H54: =H47 -> 44337 | I54: =I47 -> 44338 | J54: =J47 -> 44339 | K54: =K47 -> 44340 | ... FT54: =FT47 -> 44505
B55: 2000 | C55: Prisma 2 | D55: =$A19*$B39 -> 120 | E55: =$A19*$B39 -> 120 | F55: =$A19*$B39 -> 120 | G55: =$A19*$B39 -> 120 | H55: =$A19*$B39 -> 120 | I55: =$A19*$B39 -> 120 | J55: =$A19*$B39 -> 120 | K55: =$A19*$B39 -> 120 | ... FT55: =$A19*$B39 -> 120
...

Sheet Weapon-Investments

Sheet Inventory
A1: Weapon | B1: Skin | C1: Type | D1: Collection | E1: 44331 | F1: 44332 | G1: 44334 | H1: 44336 | I1: 44337 | J1: 44338 | K1: 44339 | L1: 44340 | M1: 44341 | N1: 44342 | O1: 44343 | P1: 44344 | Q1: 44345 | R1: 44346 | S1: 44347 | T1: 44348 | U1: 44349 | V1: 44350 | W1: 44351 | X1: 44352 | Y1: 44353 | Z1: 44354 | AA1: 44355 | AB1: 44356 | AC1: 44357 | AD1: 44358 | AE1: 44359 | AF1: 44360 | AG1: 44361 | AH1: 44362 | AI1: 44363 | AJ1: 44364 | AK1: 44365 | AL1: 44366 | AM1: 44367 | AN1: 44368 | AO1: 44369 | AP1: 44370 | AQ1: 44371 | AR1: 44372 | AS1: 44373 | AT1: 44374 | AU1: 44375 | AV1: 44376 | AW1: 44377 | AX1: 44378 | AY1: 44379 | AZ1: 44380 | BA1: 44381 | BB1: 44382 | BC1: 44383 | BD1: 44384 | BE1: 44385 | BF1: 44386 | BG1: 44387 | BH1: 44388 | BI1: 44389 | BJ1: 44390 | BK1: 44391 | BL1: 44392 | BM1: 44393 | BN1: 44394 | BO1: 44395 | BP1: 44396 | BQ1: 44397 | BR1: 44398 | BS1: 44399 | BT1: 44400 | BU1: 44401 | BV1: 44402 | BW1: 44403 | BX1: 44404 | BY1: 44405 | BZ1: 44406 | CA1: 44407 | CB1: 44408 | CC1: 44409 | CD1: 44410 | CE1: 44411 | CF1: 44412 | CG1: 44413 | CH1: 44414 | CI1: 44415 | CJ1: 44416 | CK1: 44417 | CL1: 44418 | CM1: 44419 | CN1: 44420 | CO1: 44421 | CP1: 44422 | CQ1: 44423 | CR1: 44424 | CS1: 44425 | CT1: 44426 | CU1: 44427 | CV1: 44428 | CW1: 44429 | CX1: 44430 | CY1: 44431 | CZ1: 44432 | DA1: 44433 | DB1: 44434 | DC1: 44435 | DD1: 44436 | DE1: 44437 | DF1: 44438 | DG1: 44439 | DH1: 44440 | DI1: 44441 | DJ1: 44442 | DK1: 44443 | DL1: 44444 | DM1: 44445 | DN1: 44446 | DO1: 44447 | DP1: 44448 | DQ1: 44449 | DR1: 44450 | DS1: 44451 | DT1: 44452 | DU1: 44453 | DV1: 44454 | DW1: 44455 | DX1: 44456 | DY1: 44457 | DZ1: 44458 | EA1: 44459 | EB1: 44460 | EC1: 44461 | ED1: 44462 | EE1: 44463 | EF1: 44464 | EG1: 44465 | EH1: 44466 | EI1: 44467 | EJ1: 44468 | EK1: 44469 | EL1: 44470 | EM1: 44471 | EN1: 44472 | EO1: 44473 | EP1: 44474 | EQ1: 44475 | ER1: 44476 | ES1: 44477 | ET1: 44478 | EU1: 44479 | EV1: 44480 | EW1: 44481 | EX1: 44482 | EY1: 44483 | EZ1: 44484 | FA1: 44485 | FB1: 44486 | FC1: 44487 | FD1: 44488 | FE1: 44489 | FF1: 44490 | FG1: 44491 | FH1: 44492 | FI1: 44493 | FJ1: 44494 | FK1: 44495 | FL1: 44496 | FM1: 44497 | FN1: 44498 | FO1: 44499 | FP1: 44500 | FQ1: 44501 | FR1: 44502 | FS1: 44503 | FT1: 44504 | FU1: 44505
A2: M4A4 | B2: StatTrak Cyber Security MW | C2: M4A4 | D2: Broken Fang | E2: 33.21 | F2: 31.65 | G2: 29.18 | H2: 31.74 | I2: 29.35 | J2: 30.3 | K2: 30.75 | L2: 28.8 | M2: 30.22 | N2: 28.81 | O2: 28.69 | P2: 27.92 | Q2: 28.87 | R2: 29.99 | S2: 28.9 | T2: 29.12 | U2: 29.62 | V2: 28.55 | W2: 29.16 | X2: 29.07 | Y2: 29.04
A3: Sawed-Off | B3: Limelight MW | C3: Heavy | D3: Gamma | E3: 0.89 | F3: 0.88 | G3: 0.96 | H3: 0.92 | I3: 0.87 | J3: 0.92 | K3: 0.86 | L3: 0.87 | M3: 0.88 | N3: 0.94 | O3: 0.93 | P3: 0.84 | Q3: 0.87 | R3: 0.86 | S3: 0.93 | T3: 0.82 | U3: 0.88 | V3: 0.77 | W3: 0.89 | X3: 0.92 | Y3: 0.85
A4: MAG-7 | B4: Popdog FN | C4: Heavy | D4: CS20 | E4: 0.3 | F4: 0.3 | G4: 0.34 | H4: 0.34 | I4: 0.32 | J4: 0.36 | K4: 0.34 | L4: 0.3 | M4: 0.34 | N4: 0.32 | O4: 0.34 | P4: 0.3 | Q4: 0.31 | R4: 0.32 | S4: 0.3 | T4: 0.32 | U4: 0.32 | V4: 0.29 | W4: 0.29 | X4: 0.29 | Y4: 0.28
A5: UMP-45 | B5: Plastique MW | C5: SMG | D5: CS20 | E5: 0.8 | F5: 0.83 | G5: 0.82 | H5: 0.76 | I5: 0.82 | J5: 0.83 | K5: 0.84 | L5: 0.84 | M5: 0.84 | N5: 0.83 | O5: 0.85 | P5: 0.85 | Q5: 0.87 | R5: 0.85 | S5: 0.83 | T5: 0.84 | U5: 0.83 | V5: 0.75 | W5: 0.81 | X5: 0.82 | Y5: 0.82
A6: PP-Bizon | B6: Fuel Rod FT | C6: SMG | D6: Revolver | E6: 1.1 | F6: 1.04 | G6: 0.98 | H6: 0.93 | I6: 0.88 | J6: 0.98 | K6: 0.94 | L6: 0.93 | M6: 0.96 | N6: 0.93 | O6: 0.98 | P6: 0.98 | Q6: 0.88 | R6: 0.87 | S6: 0.85 | T6: 0.84 | U6: 0.92 | V6: 0.86 | W6: 0.89 | X6: 0.85 | Y6: 0.86
A7: MP9 | B7: Hydra MW | C7: SMG | D7: CS20 | E7: 6.38 | F7: 5.63 | G7: 5.7 | H7: 5.94 | I7: 5.87 | J7: 6.21 | K7: 5.92 | L7: 6.18 | M7: 5.84 | N7: 5.87 | O7: 6.07 | P7: 5.77 | Q7: 5.94 | R7: 5.78 | S7: 6.27 | T7: 6.04 | U7: 6.14 | V7: 5.75 | W7: 5.92 | X7: 5.93 | Y7: 5.93
A8: MP7 | B8: Impire MW | C8: SMG | D8: Wildfire | E8: 1.46 | F8: 1.44 | G8: 1.49 | H8: 1.46 | I8: 1.53 | J8: 1.53 | K8: 1.45 | L8: 1.53 | M8: 1.46 | N8: 1.49 | O8: 1.52 | P8: 1.51 | Q8: 1.56 | R8: 1.54 | S8: 1.41 | T8: 1.51 | U8: 1.45 | V8: 1.51 | W8: 1.41 | X8: 1.46 | Y8: 1.38
A9: MAC-10 | B9: Malachite MW | C9: SMG | D9: Chroma | E9: 1.5 | F9: 1.45 | G9: 1.4 | H9: 1.39 | I9: 1.51 | J9: 1.54 | K9: 1.46 | L9: 1.55 | M9: 1.55 | N9: 1.51 | O9: 1.49 | P9: 1.5 | Q9: 1.51 | R9: 1.54 | S9: 1.54 | T9: 1.55 | U9: 1.56 | V9: 1.52 | W9: 1.46 | X9: 1.51 | Y9: 1.52
A10: SSG 08 | B10: Necropos MW | C10: Other Rifle | D10: Wildfire | K10: 0.34 | L10: 0.3 | M10: 0.32 | N10: 0.32 | O10: 0.32 | P10: 0.31 | Q10: 0.3 | R10: 0.32 | S10: 0.31 | T10: 0.31 | U10: 0.31 | V10: 0.31 | W10: 0.29 | X10: 0.3 | Y10: 0.32
A11: SG 553 | B11: Atlas FN | C11: Other Rifle | D11: Chroma 3 | K11: 0.32 | L11: 0.34 | M11: 0.32 | N11: 0.32 | O11: 0.32 | P11: 0.32 | Q11: 0.3 | R11: 0.31 | S11: 0.29 | T11: 0.29 | U11: 0.28 | V11: 0.3 | W11: 0.29 | X11: 0.28 | Y11: 0.29
A12: SCAR-20 | B12: Powercore MW | C12: Other Rifle | D12: Gamma 2 | K12: 0.5 | L12: 0.49 | M12: 0.5 | N12: 0.46 | O12: 0.47 | P12: 0.47 | Q12: 0.5 | R12: 0.51 | S12: 0.47 | T12: 0.46 | U12: 0.49 | V12: 0.5 | W12: 0.49 | X12: 0.47 | Y12: 0.49
A13: M4A1-S | B13: Flashback FN | C13: M4A1-S | D13: Glove | E13: 2.92 | F13: 3.01 | G13: 2.89 | H13: 2.81 | I13: 2.82 | J13: 2.91 | K13: 2.84 | L13: 2.78 | M13: 2.71 | N13: 2.68 | O13: 2.81 | P13: 2.54 | Q13: 2.64 | R13: 2.77 | S13: 2.5 | T13: 2.53 | U13: 2.45 | V13: 2.5 | W13: 2.45 | X13: 2.47 | Y13: 2.53
A14: Galil AR | B14: Eco FT | C14: Other Rifle | D14: Chroma 2 | K14: 3.82 | L14: 3.83 | M14: 3.77 | N14: 3.72 | O14: 3.69 | P14: 3.68 | Q14: 3.68 | R14: 3.74 | S14: 3.73 | T14: 3.64 | U14: 3.61 | V14: 3.63 | W14: 3.53 | X14: 3.58 | Y14: 3.51
A15: FAMAS | B15: Macabre MW | C15: Other Rifle | D15: Hydra | K15: 1.26 | L15: 1.27 | M15: 1.26 | N15: 1.24 | O15: 1.26 | P15: 1.26 | Q15: 1.26 | R15: 1.3 | S15: 1.33 | T15: 1.43 | U15: 1.43 | V15: 1.39 | W15: 1.43 | X15: 1.46 | Y15: 1.47
A16: USP-S | B16: Flashback MW | C16: Pistol | D16: Danger Zone | E16: 0.92 | F16: 0.85 | G16: 0.87 | H16: 0.93 | I16: 0.92 | J16: 0.93 | K16: 0.86 | L16: 0.97 | M16: 0.85 | N16: 0.94 | O16: 0.93 | P16: 0.84 | Q16: 0.86 | R16: 0.86 | S16: 0.88 | T16: 0.88 | U16: 0.87 | V16: 0.88 | W16: 0.85 | X16: 0.86 | Y16: 0.86
A17: Glock-18 | B17: Nuclear Garden FT | C17: Pistol | D17: 2018 Nuke | E17: 4.64 | F17: 4.57 | G17: 4.44 | H17: 4.05 | I17: 4.3 | J17: 4.19 | K17: 4.65 | L17: 4.22 | M17: 4.38 | N17: 4.42 | O17: 4.26 | P17: 4.31 | Q17: 4.22 | R17: 4.29 | S17: 4.33 | T17: 4.34 | U17: 4.29 | V17: 4.34 | W17: 4.1 | X17: 4.22 | Y17: 4.17
A18: Five-SeveN | B18: Hot Shot MW | C18: Pistol | D18: Cache | E18: 0.73 | F18: 0.73 | G18: 0.74 | H18: 0.82 | I18: 0.82 | J18: 0.82 | K18: 0.81 | L18: 0.8 | M18: 0.82 | N18: 0.81 | O18: 0.82 | P18: 0.82 | Q18: 0.82 | R18: 0.81 | S18: 0.84 | T18: 0.78 | U18: 0.85 | V18: 0.81 | W18: 0.84 | X18: 0.84 | Y18: 0.86
A19: Dual Berettas | B19: Emerald FN | C19: Pistol | D19: Canals | E19: 11.4 | F19: 11.35 | G19: 11.04 | H19: 12.32 | I19: 12.32 | J19: 12.34 | K19: 14.23 | L19: 18.35 | M19: 19.45 | N19: 25.73 | O19: 30.27 | P19: 24.72 | Q19: 29.14 | R19: 26.94 | S19: 26.19 | T19: 26.24 | U19: 26.29 | V19: 36.42 | W19: 38.91 | X19: 42.79 | Y19: 40.04
A20: Desert Eagle | B20: Midnight Storm MW | C20: Pistol | D20: Rising Sun | E20: 9.14 | F20: 9.04 | G20: 8.65 | H20: 9.56 | I20: 9.01 | J20: 10.08 | K20: 9.1 | L20: 9.6 | M20: 9.58 | N20: 9.48 | O20: 11.35 | P20: 12.34 | Q20: 12.21 | R20: 11.98 | S20: 12.07 | T20: 11.78 | U20: 12.2 | V20: 12.1 | W20: 13.7 | X20: 13.34 | Y20: 13.35
A21: Bayonet | B21: Rust Coat BS | C21: Knife | D21: Chroma | E21: 196.27 | F21: 201.82 | G21: 197 | H21: 196.88 | I21: 207.18 | J21: 209.46 | K21: 201.89 | L21: 202.48 | M21: 196.23 | N21: 204.01 | O21: 206.61 | P21: 209.15 | Q21: 207.58 | R21: 207.32 | S21: 202.17 | T21: 201.3 | U21: 201.79 | V21: 203.29 | W21: 201.2 | X21: 207 | Y21: 207.01
A22: R8 Revolver | B22: Canal Spray FT | C22: Pistol | D22: Canals | E22: 0.41 | F22: 0.43 | G22: 0.41 | H22: 0.41 | I22: 0.46 | J22: 0.49 | K22: 0.53 | L22: 0.54 | M22: 0.6 | N22: 0.6 | O22: 0.81 | P22: 0.78 | Q22: 0.71 | R22: 0.65 | S22: 0.61 | T22: 0.57 | U22: 0.55 | V22: 0.62 | W22: 0.64 | X22: 0.73 | Y22: 0.87
A23: FAMAS | B23: Night Borre FT | C23: Other Rifle | D23: Norse | K23: 1.09 | L23: 1.35 | M23: 1.28 | N23: 1.58 | O23: 1.67 | P23: 1.58 | Q23: 1.53 | R23: 1.47 | S23: 1.38 | T23: 1.4 | U23: 1.26 | V23: 1.49 | W23: 1.52 | X23: 1.56 | Y23: 1.69
A24: MP5-SD | B24: Bamboo Garden MW | C24: SMG | D24: St. Marc | E24: 0.52 | F24: 0.48 | G24: 0.54 | H24: 0.55 | I24: 0.53 | J24: 0.61 | K24: 0.76 | L24: 0.78 | M24: 0.83 | N24: 1.06 | O24: 1.29 | P24: 1.21 | Q24: 1.09 | R24: 1.04 | S24: 0.98 | T24: 0.93 | U24: 1.01 | V24: 1.08 | W24: 1.23 | X24: 1.41 | Y24: 1.31
A25: Galil AR | B25: Tornado BS | C25: Other Rifle | D25: Norse | K25: 1.1 | L25: 1.1 | M25: 1.1 | N25: 1.52 | O25: 1.61 | P25: 1.41 | Q25: 1.45 | R25: 1.42 | S25: 1.46 | T25: 1.46 | U25: 1.44 | V25: 1.41 | W25: 1.42 | X25: 1.44 | Y25: 1.56
A26: MAC-10 | B26: StatTrak Neon Rider MW | C26: SMG | D26: Chroma 2 | E26: 22.48 | F26: 23.47 | G26: 20.71 | H26: 19.8 | I26: 21.98 | J26: 23.47 | K26: 23.57 | L26: 22.65 | M26: 23.03 | N26: 23.07 | O26: 22.67 | P26: 22.71 | Q26: 21.96 | R26: 21.29 | S26: 22.8 | T26: 22.7 | U26: 22.81 | V26: 22.88 | W26: 21.67 | X26: 22.85 | Y26: 21.98
A27: AWP | B27: Atheris MW | C27: AWP | D27: Prisma | E27: 4.31 | F27: 4.54 | G27: 4.37 | H27: 4.41 | I27: 4.16 | J27: 4.4 | K27: 4.73 | L27: 4.69 | M27: 4.54 | N27: 4.53 | O27: 4.55 | P27: 4.22 | Q27: 4.39 | R27: 4.23 | S27: 4.06 | T27: 4.23 | U27: 4.62 | V27: 4.07 | W27: 4.3 | X27: 4.23 | Y27: 4.21
A28: Five-SeveN | B28: StatTrak Buddy MW | C28: Pistol | D28: CS20 | E28: 2.26 | F28: 2.1 | G28: 2.2 | H28: 2.25 | I28: 2.11 | J28: 2.21 | K28: 2.16 | L28: 2.22 | M28: 2.27 | N28: 2.31 | O28: 2.22 | P28: 2.24 | Q28: 2.14 | R28: 2.1 | S28: 1.97 | T28: 2.09 | U28: 2.09 | V28: 2.23 | W28: 2.19 | X28: 2.14 | Y28: 2.22
A29: AWP | B29: Neo-Noir FN | C29: AWP | D29: Danger Zone | E29: 47 | F29: 45.93 | G29: 44.54 | H29: 45.51 | I29: 46.05 | J29: 46.08 | K29: 46.57 | L29: 47.69 | M29: 44.11 | N29: 44.01 | O29: 45.22 | P29: 46.55 | Q29: 46.98 | R29: 43.94 | S29: 46.39 | T29: 46.37 | U29: 47.84 | V29: 44.88 | W29: 48.07 | X29: 48.33 | Y29: 47.69
A30: M4A1-S | B30: StatTrak Cyrex MW | C30: M4A1-S | D30: Breakout | E30: 36.2 | F30: 34.8 | G30: 33.23 | H30: 33.31 | I30: 34.51 | J30: 33.05 | K30: 31.31 | L30: 33.38 | M30: 33.38 | N30: 33.01 | O30: 30.97 | P30: 34.41 | Q30: 34.11 | R30: 41.12 | S30: 36.27 | T30: 35.09 | U30: 35.93 | V30: 33.97 | W30: 35.33 | X30: 32.56 | Y30: 31.05
A31: Glock-18 | B31: StatTrak Weasel FT | C31: Pistol | D31: Gamma 2 | E31: 1.86 | F31: 1.84 | G31: 1.65 | H31: 1.79 | I31: 1.79 | J31: 1.8 | K31: 1.72 | L31: 1.75 | M31: 1.64 | N31: 1.75 | O31: 1.67 | P31: 1.65 | Q31: 1.64 | R31: 1.55 | S31: 1.63 | T31: 1.64 | U31: 1.54 | V31: 1.62 | W31: 1.63 | X31: 1.47 | Y31: 1.61
A32: Desert Eagle | B32: Code Red MW | C32: Pistol | D32: Horizon | E32: 42.81 | F32: 40.6 | G32: 40.6 | H32: 43.52 | I32: 41.78 | J32: 40.51 | K32: 42.18 | L32: 43.36 | M32: 43.28 | N32: 42.82 | O32: 40.64 | P32: 41.72 | Q32: 39.48 | R32: 40.48 | S32: 40.97 | T32: 39.8 | U32: 43.95 | V32: 44.02 | W32: 40.28 | X32: 42 | Y32: 43.82
A33: XM1014 | B33: Souvenir VariCamo Blue FN | C33: Heavy | D33: Overpass | E33: 3.61 | F33: 3.49 | G33: 3.47 | H33: 3.92 | I33: 3.58 | J33: 3.49 | K33: 3.49 | L33: 3.49 | M33: 3.05 | N33: 3.46 | O33: 3.46 | P33: 4.21 | Q33: 3.94 | R33: 3.62 | S33: 3.86 | T33: 3.8 | U33: 3.8 | V33: 3.72 | W33: 3.1 | X33: 3.06 | Y33: 3.08
A34: UMP-45 | B34: Momentum FN | C34: SMG | D34: Danger Zone | E34: 7.79 | F34: 8.19 | G34: 7.47 | H34: 7.59 | I34: 7.85 | J34: 7.68 | K34: 7.31 | L34: 7.53 | M34: 7.43 | N34: 7.4 | O34: 7.98 | P34: 7.1 | Q34: 7.31 | R34: 7.64 | S34: 7.47 | T34: 7.42 | U34: 7.47 | V34: 7.62 | W34: 7.9 | X34: 7.95 | Y34: 7.67
A35: M4A4 | B35: The Battlestar FN | C35: M4A4 | D35: Wildfire | E35: 14.52 | F35: 13.27 | G35: 13.26 | H35: 14.11 | I35: 14.06 | J35: 14.27 | K35: 13.84 | L35: 13.34 | M35: 12.49 | N35: 12.85 | O35: 12.48 | P35: 13.5 | Q35: 13.54 | R35: 13.54 | S35: 14.22 | T35: 13.54 | U35: 13.19 | V35: 13.66 | W35: 12.69 | X35: 13.66 | Y35: 13.27
A36: Desert Eagle | B36: Hypnotic FN | C36: Pistol | D36: Arms Deal | E36: 87.76 | F36: 84.47 | G36: 88.51 | H36: 88.5 | I36: 88.5 | J36: 88.29 | K36: 91.5 | L36: 91.5 | M36: 90.9 | N36: 91.34 | O36: 85.86 | P36: 91.67 | Q36: 87.76 | R36: 91.7 | S36: 90.34 | T36: 94.85 | U36: 98.14 | V36: 95.29 | W36: 95.73 | X36: 117.46 | Y36: 117.46
A37: M4A4 | B37: Neo-Noir MW | C37: M4A4 | D37: Clutch | E37: 29.07 | F37: 29.37 | G37: 26.79 | H37: 27.5 | I37: 27.26 | J37: 28.86 | K37: 27.29 | L37: 25.83 | M37: 26.17 | N37: 25.72 | O37: 27.42 | P37: 25.94 | Q37: 26.04 | R37: 25.26 | S37: 27.4 | T37: 27.17 | U37: 26.02 | V37: 26.27 | W37: 27.83 | X37: 26.99 | Y37: 25.85
... A39: AK-47 | B39: Aquamarine Revenge MW | C39: AK-47 | D39: Falchion | E39: 47.51 | F39: 47.17 | G39: 49.37 | H39: 48.37 | I39: 46.08 | J39: 44.96 | K39: 46.07 | L39: 45.89 | M39: 44.94 | N39: 45.49 | O39: 46.09 | P39: 45.74 | Q39: 45.73 | R39: 44.74 | S39: 44.91 | T39: 46.13 | U39: 46.46 | V39: 45.58 | W39: 45.39 | X39: 43.55 | Y39: 46.01
A40: AUG | B40: StatTrak Momentum MW | C40: Other Rifle | D40: Prisma | K40: 18.91 | L40: 17.99 | M40: 20.02 | N40: 19.47 | O40: 19.44 | P40: 19.55 | Q40: 19.58 | R40: 19.96 | S40: 18.88 | T40: 19.25 | U40: 18.98 | V40: 18.92 | W40: 18.66 | X40: 19.93 | Y40: 19.72
A41: Desert Eagle | B41: Light Rail FN | C41: Pistol | D41: Prisma | E41: 3.87 | F41: 3.61 | G41: 3.62 | H41: 3.61 | I41: 3.63 | J41: 3.45 | K41: 3.74 | L41: 3.52 | M41: 3.49 | N41: 3.53 | O41: 3.64 | P41: 3.59 | Q41: 3.47 | R41: 3.56 | S41: 3.65 | T41: 3.82 | U41: 3.62 | V41: 3.6 | W41: 3.61 | X41: 3.54 | Y41: 3.73
...

Sheet Knives
A1: Knives
A3: Weapon | B3: Skin | C3: Type | D3: Collection | E3: =Inventory!E1 -> 44331 | F3: =Inventory!F1 -> 44332 | G3: =Inventory!G1 -> 44334 | H3: =Inventory!H1 -> 44336 | I3: =Inventory!I1 -> 44337 | J3: =Inventory!J1 -> 44338 | K3: =Inventory!K1 -> 44339 | L3: =Inventory!L1 -> 44340 | ... FU3: =Inventory!FU1 -> 44505
A4: {=_xlfn._xlws.FILTER(Inventory!$A$2:$FU$103, (Inventory!C2:C103="Knife"))} -> Bayonet | B4: Rust Coat BS | C4: Knife | D4: Chroma | E4: 196.27 | F4: 201.82 | G4: 197 | H4: 196.88 | I4: 207.18 | J4: 209.46 | K4: 201.89 | L4: 202.48 | M4: 196.23 | N4: 204.01 | O4: 206.61 | P4: 209.15 | Q4: 207.58 | R4: 207.32 | S4: 202.17 | T4: 201.3 | U4: 201.79 | V4: 203.29 | W4: 201.2 | X4: 207 | Y4: 207.01 | Z4: 0 | AA4: 0 | AB4: 0 | AC4: 0 | AD4: 0 | AE4: 0 | AF4: 0 | AG4: 0 | AH4: 0 | AI4: 0 | AJ4: 0 | AK4: 0 | AL4: 0 | AM4: 0 | AN4: 0 | AO4: 0 | AP4: 0 | AQ4: 0 | AR4: 0 | AS4: 0 | AT4: 0 | AU4: 0 | AV4: 0 | AW4: 0 | AX4: 0 | AY4: 0 | AZ4: 0 | BA4: 0 | BB4: 0 | BC4: 0 | BD4: 0 | BE4: 0 | BF4: 0 | BG4: 0 | BH4: 0 | BI4: 0 | BJ4: 0 | BK4: 0 | BL4: 0 | BM4: 0 | BN4: 0 | BO4: 0 | BP4: 0 | BQ4: 0 | BR4: 0 | BS4: 0 | BT4: 0 | BU4: 0 | BV4: 0 | BW4: 0 | BX4: 0 | BY4: 0 | BZ4: 0 | CA4: 0 | CB4: 0 | CC4: 0 | CD4: 0 | CE4: 0 | CF4: 0 | CG4: 0 | CH4: 0 | CI4: 0 | CJ4: 0 | CK4: 0 | CL4: 0 | CM4: 0 | CN4: 0 | CO4: 0 | CP4: 0 | CQ4: 0 | CR4: 0 | CS4: 0 | CT4: 0 | CU4: 0 | CV4: 0 | CW4: 0 | CX4: 0 | CY4: 0 | CZ4: 0 | DA4: 0 | DB4: 0 | DC4: 0 | DD4: 0 | DE4: 0 | DF4: 0 | DG4: 0 | DH4: 0 | DI4: 0 | DJ4: 0 | DK4: 0 | DL4: 0 | DM4: 0 | DN4: 0 | DO4: 0 | DP4: 0 | DQ4: 0 | DR4: 0 | DS4: 0 | DT4: 0 | DU4: 0 | DV4: 0 | DW4: 0 | DX4: 0 | DY4: 0 | DZ4: 0 | EA4: 0 | EB4: 0 | EC4: 0 | ED4: 0 | EE4: 0 | EF4: 0 | EG4: 0 | EH4: 0 | EI4: 0 | EJ4: 0 | EK4: 0 | EL4: 0 | EM4: 0 | EN4: 0 | EO4: 0 | EP4: 0 | EQ4: 0 | ER4: 0 | ES4: 0 | ET4: 0 | EU4: 0 | EV4: 0 | EW4: 0 | EX4: 0 | EY4: 0 | EZ4: 0 | FA4: 0 | FB4: 0 | FC4: 0 | FD4: 0 | FE4: 0 | FF4: 0 | FG4: 0 | FH4: 0 | FI4: 0 | FJ4: 0 | FK4: 0 | FL4: 0 | FM4: 0 | FN4: 0 | FO4: 0 | FP4: 0 | FQ4: 0 | FR4: 0 | FS4: 0 | FT4: 0 | FU4: 0
A5: Butterfly Knife | B5: Tiger Tooth FN | C5: Knife | D5: Spectrum | E5: 1201.6 | F5: 1205.46 | G5: 1261.1 | H5: 1261.06 | I5: 1261.06 | J5: 1230.57 | K5: 1294.36 | L5: 1294.36 | M5: 1290.31 | N5: 1427.45 | O5: 1391 | P5: 1383.65 | Q5: 1363.98 | R5: 1354.05 | S5: 1341.3 | T5: 1341.3 | U5: 1354.94 | V5: 1364.6 | W5: 1349.99 | X5: 1413.09 | Y5: 1484.68 | Z5: 0 | AA5: 0 | AB5: 0 | AC5: 0 | AD5: 0 | AE5: 0 | AF5: 0 | AG5: 0 | AH5: 0 | AI5: 0 | AJ5: 0 | AK5: 0 | AL5: 0 | AM5: 0 | AN5: 0 | AO5: 0 | AP5: 0 | AQ5: 0 | AR5: 0 | AS5: 0 | AT5: 0 | AU5: 0 | AV5: 0 | AW5: 0 | AX5: 0 | AY5: 0 | AZ5: 0 | BA5: 0 | BB5: 0 | BC5: 0 | BD5: 0 | BE5: 0 | BF5: 0 | BG5: 0 | BH5: 0 | BI5: 0 | BJ5: 0 | BK5: 0 | BL5: 0 | BM5: 0 | BN5: 0 | BO5: 0 | BP5: 0 | BQ5: 0 | BR5: 0 | BS5: 0 | BT5: 0 | BU5: 0 | BV5: 0 | BW5: 0 | BX5: 0 | BY5: 0 | BZ5: 0 | CA5: 0 | CB5: 0 | CC5: 0 | CD5: 0 | CE5: 0 | CF5: 0 | CG5: 0 | CH5: 0 | CI5: 0 | CJ5: 0 | CK5: 0 | CL5: 0 | CM5: 0 | CN5: 0 | CO5: 0 | CP5: 0 | CQ5: 0 | CR5: 0 | CS5: 0 | CT5: 0 | CU5: 0 | CV5: 0 | CW5: 0 | CX5: 0 | CY5: 0 | CZ5: 0 | DA5: 0 | DB5: 0 | DC5: 0 | DD5: 0 | DE5: 0 | DF5: 0 | DG5: 0 | DH5: 0 | DI5: 0 | DJ5: 0 | DK5: 0 | DL5: 0 | DM5: 0 | DN5: 0 | DO5: 0 | DP5: 0 | DQ5: 0 | DR5: 0 | DS5: 0 | DT5: 0 | DU5: 0 | DV5: 0 | DW5: 0 | DX5: 0 | DY5: 0 | DZ5: 0 | EA5: 0 | EB5: 0 | EC5: 0 | ED5: 0 | EE5: 0 | EF5: 0 | EG5: 0 | EH5: 0 | EI5: 0 | EJ5: 0 | EK5: 0 | EL5: 0 | EM5: 0 | EN5: 0 | EO5: 0 | EP5: 0 | EQ5: 0 | ER5: 0 | ES5: 0 | ET5: 0 | EU5: 0 | EV5: 0 | EW5: 0 | EX5: 0 | EY5: 0 | EZ5: 0 | FA5: 0 | FB5: 0 | FC5: 0 | FD5: 0 | FE5: 0 | FF5: 0 | FG5: 0 | FH5: 0 | FI5: 0 | FJ5: 0 | FK5: 0 | FL5: 0 | FM5: 0 | FN5: 0 | FO5: 0 | FP5: 0 | FQ5: 0 | FR5: 0 | FS5: 0 | FT5: 0 | FU5: 0
A6: Flip Knife | B6: Freehand FN | C6: Knife | D6: Gamma | E6: 194.62 | F6: 191.6 | G6: 180.11 | H6: 192.42 | I6: 192.42 | J6: 191.29 | K6: 183.02 | L6: 190.84 | M6: 183.2 | N6: 188.79 | O6: 188.98 | P6: 181.09 | Q6: 190.1 | R6: 189.75 | S6: 180.74 | T6: 189.61 | U6: 186.36 | V6: 180.21 | W6: 164.58 | X6: 169.76 | Y6: 185.28 | Z6: 0 | AA6: 0 | AB6: 0 | AC6: 0 | AD6: 0 | AE6: 0 | AF6: 0 | AG6: 0 | AH6: 0 | AI6: 0 | AJ6: 0 | AK6: 0 | AL6: 0 | AM6: 0 | AN6: 0 | AO6: 0 | AP6: 0 | AQ6: 0 | AR6: 0 | AS6: 0 | AT6: 0 | AU6: 0 | AV6: 0 | AW6: 0 | AX6: 0 | AY6: 0 | AZ6: 0 | BA6: 0 | BB6: 0 | BC6: 0 | BD6: 0 | BE6: 0 | BF6: 0 | BG6: 0 | BH6: 0 | BI6: 0 | BJ6: 0 | BK6: 0 | BL6: 0 | BM6: 0 | BN6: 0 | BO6: 0 | BP6: 0 | BQ6: 0 | BR6: 0 | BS6: 0 | BT6: 0 | BU6: 0 | BV6: 0 | BW6: 0 | BX6: 0 | BY6: 0 | BZ6: 0 | CA6: 0 | CB6: 0 | CC6: 0 | CD6: 0 | CE6: 0 | CF6: 0 | CG6: 0 | CH6: 0 | CI6: 0 | CJ6: 0 | CK6: 0 | CL6: 0 | CM6: 0 | CN6: 0 | CO6: 0 | CP6: 0 | CQ6: 0 | CR6: 0 | CS6: 0 | CT6: 0 | CU6: 0 | CV6: 0 | CW6: 0 | CX6: 0 | CY6: 0 | CZ6: 0 | DA6: 0 | DB6: 0 | DC6: 0 | DD6: 0 | DE6: 0 | DF6: 0 | DG6: 0 | DH6: 0 | DI6: 0 | DJ6: 0 | DK6: 0 | DL6: 0 | DM6: 0 | DN6: 0 | DO6: 0 | DP6: 0 | DQ6: 0 | DR6: 0 | DS6: 0 | DT6: 0 | DU6: 0 | DV6: 0 | DW6: 0 | DX6: 0 | DY6: 0 | DZ6: 0 | EA6: 0 | EB6: 0 | EC6: 0 | ED6: 0 | EE6: 0 | EF6: 0 | EG6: 0 | EH6: 0 | EI6: 0 | EJ6: 0 | EK6: 0 | EL6: 0 | EM6: 0 | EN6: 0 | EO6: 0 | EP6: 0 | EQ6: 0 | ER6: 0 | ES6: 0 | ET6: 0 | EU6: 0 | EV6: 0 | EW6: 0 | EX6: 0 | EY6: 0 | EZ6: 0 | FA6: 0 | FB6: 0 | FC6: 0 | FD6: 0 | FE6: 0 | FF6: 0 | FG6: 0 | FH6: 0 | FI6: 0 | FJ6: 0 | FK6: 0 | FL6: 0 | FM6: 0 | FN6: 0 | FO6: 0 | FP6: 0 | FQ6: 0 | FR6: 0 | FS6: 0 | FT6: 0 | FU6: 0
A7: Karmabit | B7: Ultraviolet FT | C7: Knife | D7: Original | E7: 380.55 | F7: 383.02 | G7: 361.9 | H7: 361.97 | I7: 372.41 | J7: 365.9 | K7: 334.61 | L7: 355.59 | M7: 350.79 | N7: 385.29 | O7: 391.15 | P7: 391.41 | Q7: 370.36 | R7: 386.6 | S7: 386.45 | T7: 382.76 | U7: 397.01 | V7: 406.58 | W7: 384.98 | X7: 385.96 | Y7: 424.73 | Z7: 0 | AA7: 0 | AB7: 0 | AC7: 0 | AD7: 0 | AE7: 0 | AF7: 0 | AG7: 0 | AH7: 0 | AI7: 0 | AJ7: 0 | AK7: 0 | AL7: 0 | AM7: 0 | AN7: 0 | AO7: 0 | AP7: 0 | AQ7: 0 | AR7: 0 | AS7: 0 | AT7: 0 | AU7: 0 | AV7: 0 | AW7: 0 | AX7: 0 | AY7: 0 | AZ7: 0 | BA7: 0 | BB7: 0 | BC7: 0 | BD7: 0 | BE7: 0 | BF7: 0 | BG7: 0 | BH7: 0 | BI7: 0 | BJ7: 0 | BK7: 0 | BL7: 0 | BM7: 0 | BN7: 0 | BO7: 0 | BP7: 0 | BQ7: 0 | BR7: 0 | BS7: 0 | BT7: 0 | BU7: 0 | BV7: 0 | BW7: 0 | BX7: 0 | BY7: 0 | BZ7: 0 | CA7: 0 | CB7: 0 | CC7: 0 | CD7: 0 | CE7: 0 | CF7: 0 | CG7: 0 | CH7: 0 | CI7: 0 | CJ7: 0 | CK7: 0 | CL7: 0 | CM7: 0 | CN7: 0 | CO7: 0 | CP7: 0 | CQ7: 0 | CR7: 0 | CS7: 0 | CT7: 0 | CU7: 0 | CV7: 0 | CW7: 0 | CX7: 0 | CY7: 0 | CZ7: 0 | DA7: 0 | DB7: 0 | DC7: 0 | DD7: 0 | DE7: 0 | DF7: 0 | DG7: 0 | DH7: 0 | DI7: 0 | DJ7: 0 | DK7: 0 | DL7: 0 | DM7: 0 | DN7: 0 | DO7: 0 | DP7: 0 | DQ7: 0 | DR7: 0 | DS7: 0 | DT7: 0 | DU7: 0 | DV7: 0 | DW7: 0 | DX7: 0 | DY7: 0 | DZ7: 0 | EA7: 0 | EB7: 0 | EC7: 0 | ED7: 0 | EE7: 0 | EF7: 0 | EG7: 0 | EH7: 0 | EI7: 0 | EJ7: 0 | EK7: 0 | EL7: 0 | EM7: 0 | EN7: 0 | EO7: 0 | EP7: 0 | EQ7: 0 | ER7: 0 | ES7: 0 | ET7: 0 | EU7: 0 | EV7: 0 | EW7: 0 | EX7: 0 | EY7: 0 | EZ7: 0 | FA7: 0 | FB7: 0 | FC7: 0 | FD7: 0 | FE7: 0 | FF7: 0 | FG7: 0 | FH7: 0 | FI7: 0 | FJ7: 0 | FK7: 0 | FL7: 0 | FM7: 0 | FN7: 0 | FO7: 0 | FP7: 0 | FQ7: 0 | FR7: 0 | FS7: 0 | FT7: 0 | FU7: 0
D10: Total | E10: =SUM(E4:E7) -> 1973.04 | F10: =SUM(F4:F7) -> 1981.9 | G10: =SUM(G4:G7) -> 2000.11 | H10: =SUM(H4:H7) -> 2012.33 | I10: =SUM(I4:I7) -> 2033.07 | J10: =SUM(J4:J7) -> 1997.22 | K10: =SUM(K4:K7) -> 2013.88 | L10: =SUM(L4:L7) -> 2043.27 | ... FU10: =SUM(FU4:FU7) -> 0
A20: Weapon | B20: Skin | C20: Type | D20: Collection | E20: =E3 -> 44331 | F20: =F3 -> 44332 | G20: =G3 -> 44334 | H20: =H3 -> 44336 | I20: =I3 -> 44337 | J20: =J3 -> 44338 | K20: =K3 -> 44339 | L20: =L3 -> 44340 | ... FU20: =FU3 -> 44505
A21: =A4 -> Bayonet | B21: =B4 -> Rust Coat BS | C21: =C4 -> Knife | D21: =D4 -> Chroma | E21: =E4-ROUNDUP(E4*0.3,2) -> 137.38 | F21: =F4-ROUNDUP(F4*0.3,2) -> 141.27 | G21: =G4-ROUNDUP(G4*0.3,2) -> 137.9 | H21: =H4-ROUNDUP(H4*0.3,2) -> 137.81 | I21: =I4-ROUNDUP(I4*0.3,2) -> 145.02 | J21: =J4-ROUNDUP(J4*0.3,2) -> 146.62 | K21: =K4-ROUNDUP(K4*0.3,2) -> 141.32 | L21: =L4-ROUNDUP(L4*0.3,2) -> 141.73 | ... FU21: =FU4-ROUNDUP(FU4*0.3,2) -> 0
A22: =A5 -> Butterfly Knife | B22: =B5 -> Tiger Tooth FN | C22: =C5 -> Knife | D22: =D5 -> Spectrum | E22: =E5-ROUNDUP(E5*0.3,2) -> 841.12 | F22: =F5-ROUNDUP(F5*0.3,2) -> 843.82 | G22: =G5-ROUNDUP(G5*0.3,2) -> 882.77 | H22: =H5-ROUNDUP(H5*0.3,2) -> 882.74 | I22: =I5-ROUNDUP(I5*0.3,2) -> 882.74 | J22: =J5-ROUNDUP(J5*0.3,2) -> 861.39 | K22: =K5-ROUNDUP(K5*0.3,2) -> 906.05 | L22: =L5-ROUNDUP(L5*0.3,2) -> 906.05 | ... FU22: =FU5-ROUNDUP(FU5*0.3,2) -> 0
A23: =A6 -> Flip Knife | B23: =B6 -> Freehand FN | C23: =C6 -> Knife | D23: =D6 -> Gamma | E23: =E6-ROUNDUP(E6*0.3,2) -> 136.23 | F23: =F6-ROUNDUP(F6*0.3,2) -> 134.12 | G23: =G6-ROUNDUP(G6*0.3,2) -> 126.07 | H23: =H6-ROUNDUP(H6*0.3,2) -> 134.69 | I23: =I6-ROUNDUP(I6*0.3,2) -> 134.69 | J23: =J6-ROUNDUP(J6*0.3,2) -> 133.9 | K23: =K6-ROUNDUP(K6*0.3,2) -> 128.11 | L23: =L6-ROUNDUP(L6*0.3,2) -> 133.58 | ... FU23: =FU6-ROUNDUP(FU6*0.3,2) -> 0
A24: =A7 -> Karmabit | B24: =B7 -> Ultraviolet FT | C24: =C7 -> Knife | D24: =D7 -> Original | E24: =E7-ROUNDUP(E7*0.3,2) -> 266.38 | F24: =F7-ROUNDUP(F7*0.3,2) -> 268.11 | G24: =G7-ROUNDUP(G7*0.3,2) -> 253.33 | H24: =H7-ROUNDUP(H7*0.3,2) -> 253.37 | I24: =I7-ROUNDUP(I7*0.3,2) -> 260.68 | J24: =J7-ROUNDUP(J7*0.3,2) -> 256.13 | K24: =K7-ROUNDUP(K7*0.3,2) -> 234.22 | L24: =L7-ROUNDUP(L7*0.3,2) -> 248.91 | ... FU24: =FU7-ROUNDUP(FU7*0.3,2) -> 0
D27: Total | E27: =SUM(E21:E24) -> 1381.11 | F27: =SUM(F21:F24) -> 1387.32 | G27: =SUM(G21:G24) -> 1400.07 | H27: =SUM(H21:H24) -> 1408.61 | I27: =SUM(I21:I24) -> 1423.13 | J27: =SUM(J21:J24) -> 1398.04 | K27: =SUM(K21:K24) -> 1409.7 | L27: =SUM(L21:L24) -> 1430.27 | ... FU27: =SUM(FU21:FU24) -> 0

Sheet AWP
B1: AWP
A3: Weapon | B3: Skin | C3: Type | D3: Collection | E3: =Inventory!E1 -> 44331 | F3: =Inventory!F1 -> 44332 | G3: =Inventory!G1 -> 44334 | H3: =Inventory!H1 -> 44336 | I3: =Inventory!I1 -> 44337 | J3: =Inventory!J1 -> 44338 | K3: =Inventory!K1 -> 44339 | L3: =Inventory!L1 -> 44340 | ... FU3: =Inventory!FU1 -> 44505
A4: {=_xlfn._xlws.FILTER(Inventory!$A$2:$FU$103, (Inventory!C2:C103="AWP"))} -> AWP | B4: Atheris MW | C4: AWP | D4: Prisma | E4: 4.31 | F4: 4.54 | G4: 4.37 | H4: 4.41 | I4: 4.16 | J4: 4.4 | K4: 4.73 | L4: 4.69 | M4: 4.54 | N4: 4.53 | O4: 4.55 | P4: 4.22 | Q4: 4.39 | R4: 4.23 | S4: 4.06 | T4: 4.23 | U4: 4.62 | V4: 4.07 | W4: 4.3 | X4: 4.23 | Y4: 4.21 | Z4: 0 | AA4: 0 | AB4: 0 | AC4: 0 | AD4: 0 | AE4: 0 | AF4: 0 | AG4: 0 | AH4: 0 | AI4: 0 | AJ4: 0 | AK4: 0 | AL4: 0 | AM4: 0 | AN4: 0 | AO4: 0 | AP4: 0 | AQ4: 0 | AR4: 0 | AS4: 0 | AT4: 0 | AU4: 0 | AV4: 0 | AW4: 0 | AX4: 0 | AY4: 0 | AZ4: 0 | BA4: 0 | BB4: 0 | BC4: 0 | BD4: 0 | BE4: 0 | BF4: 0 | BG4: 0 | BH4: 0 | BI4: 0 | BJ4: 0 | BK4: 0 | BL4: 0 | BM4: 0 | BN4: 0 | BO4: 0 | BP4: 0 | BQ4: 0 | BR4: 0 | BS4: 0 | BT4: 0 | BU4: 0 | BV4: 0 | BW4: 0 | BX4: 0 | BY4: 0 | BZ4: 0 | CA4: 0 | CB4: 0 | CC4: 0 | CD4: 0 | CE4: 0 | CF4: 0 | CG4: 0 | CH4: 0 | CI4: 0 | CJ4: 0 | CK4: 0 | CL4: 0 | CM4: 0 | CN4: 0 | CO4: 0 | CP4: 0 | CQ4: 0 | CR4: 0 | CS4: 0 | CT4: 0 | CU4: 0 | CV4: 0 | CW4: 0 | CX4: 0 | CY4: 0 | CZ4: 0 | DA4: 0 | DB4: 0 | DC4: 0 | DD4: 0 | DE4: 0 | DF4: 0 | DG4: 0 | DH4: 0 | DI4: 0 | DJ4: 0 | DK4: 0 | DL4: 0 | DM4: 0 | DN4: 0 | DO4: 0 | DP4: 0 | DQ4: 0 | DR4: 0 | DS4: 0 | DT4: 0 | DU4: 0 | DV4: 0 | DW4: 0 | DX4: 0 | DY4: 0 | DZ4: 0 | EA4: 0 | EB4: 0 | EC4: 0 | ED4: 0 | EE4: 0 | EF4: 0 | EG4: 0 | EH4: 0 | EI4: 0 | EJ4: 0 | EK4: 0 | EL4: 0 | EM4: 0 | EN4: 0 | EO4: 0 | EP4: 0 | EQ4: 0 | ER4: 0 | ES4: 0 | ET4: 0 | EU4: 0 | EV4: 0 | EW4: 0 | EX4: 0 | EY4: 0 | EZ4: 0 | FA4: 0 | FB4: 0 | FC4: 0 | FD4: 0 | FE4: 0 | FF4: 0 | FG4: 0 | FH4: 0 | FI4: 0 | FJ4: 0 | FK4: 0 | FL4: 0 | FM4: 0 | FN4: 0 | FO4: 0 | FP4: 0 | FQ4: 0 | FR4: 0 | FS4: 0 | FT4: 0 | FU4: 0
A5: AWP | B5: Neo-Noir FN | C5: AWP | D5: Danger Zone | E5: 47 | F5: 45.93 | G5: 44.54 | H5: 45.51 | I5: 46.05 | J5: 46.08 | K5: 46.57 | L5: 47.69 | M5: 44.11 | N5: 44.01 | O5: 45.22 | P5: 46.55 | Q5: 46.98 | R5: 43.94 | S5: 46.39 | T5: 46.37 | U5: 47.84 | V5: 44.88 | W5: 48.07 | X5: 48.33 | Y5: 47.69 | Z5: 0 | AA5: 0 | AB5: 0 | AC5: 0 | AD5: 0 | AE5: 0 | AF5: 0 | AG5: 0 | AH5: 0 | AI5: 0 | AJ5: 0 | AK5: 0 | AL5: 0 | AM5: 0 | AN5: 0 | AO5: 0 | AP5: 0 | AQ5: 0 | AR5: 0 | AS5: 0 | AT5: 0 | AU5: 0 | AV5: 0 | AW5: 0 | AX5: 0 | AY5: 0 | AZ5: 0 | BA5: 0 | BB5: 0 | BC5: 0 | BD5: 0 | BE5: 0 | BF5: 0 | BG5: 0 | BH5: 0 | BI5: 0 | BJ5: 0 | BK5: 0 | BL5: 0 | BM5: 0 | BN5: 0 | BO5: 0 | BP5: 0 | BQ5: 0 | BR5: 0 | BS5: 0 | BT5: 0 | BU5: 0 | BV5: 0 | BW5: 0 | BX5: 0 | BY5: 0 | BZ5: 0 | CA5: 0 | CB5: 0 | CC5: 0 | CD5: 0 | CE5: 0 | CF5: 0 | CG5: 0 | CH5: 0 | CI5: 0 | CJ5: 0 | CK5: 0 | CL5: 0 | CM5: 0 | CN5: 0 | CO5: 0 | CP5: 0 | CQ5: 0 | CR5: 0 | CS5: 0 | CT5: 0 | CU5: 0 | CV5: 0 | CW5: 0 | CX5: 0 | CY5: 0 | CZ5: 0 | DA5: 0 | DB5: 0 | DC5: 0 | DD5: 0 | DE5: 0 | DF5: 0 | DG5: 0 | DH5: 0 | DI5: 0 | DJ5: 0 | DK5: 0 | DL5: 0 | DM5: 0 | DN5: 0 | DO5: 0 | DP5: 0 | DQ5: 0 | DR5: 0 | DS5: 0 | DT5: 0 | DU5: 0 | DV5: 0 | DW5: 0 | DX5: 0 | DY5: 0 | DZ5: 0 | EA5: 0 | EB5: 0 | EC5: 0 | ED5: 0 | EE5: 0 | EF5: 0 | EG5: 0 | EH5: 0 | EI5: 0 | EJ5: 0 | EK5: 0 | EL5: 0 | EM5: 0 | EN5: 0 | EO5: 0 | EP5: 0 | EQ5: 0 | ER5: 0 | ES5: 0 | ET5: 0 | EU5: 0 | EV5: 0 | EW5: 0 | EX5: 0 | EY5: 0 | EZ5: 0 | FA5: 0 | FB5: 0 | FC5: 0 | FD5: 0 | FE5: 0 | FF5: 0 | FG5: 0 | FH5: 0 | FI5: 0 | FJ5: 0 | FK5: 0 | FL5: 0 | FM5: 0 | FN5: 0 | FO5: 0 | FP5: 0 | FQ5: 0 | FR5: 0 | FS5: 0 | FT5: 0 | FU5: 0
A6: AWP | B6: Boom MW | C6: AWP | D6: eSports 2013 | E6: 52.57 | F6: 50.84 | G6: 61.12 | H6: 54.92 | I6: 54.99 | J6: 52.25 | K6: 56.03 | L6: 55.57 | M6: 54.76 | N6: 54.99 | O6: 54.7 | P6: 52.32 | Q6: 54.62 | R6: 55.38 | S6: 53.77 | T6: 56.08 | U6: 56.08 | V6: 57.36 | W6: 55.4 | X6: 55.27 | Y6: 54.17 | Z6: 0 | AA6: 0 | AB6: 0 | AC6: 0 | AD6: 0 | AE6: 0 | AF6: 0 | AG6: 0 | AH6: 0 | AI6: 0 | AJ6: 0 | AK6: 0 | AL6: 0 | AM6: 0 | AN6: 0 | AO6: 0 | AP6: 0 | AQ6: 0 | AR6: 0 | AS6: 0 | AT6: 0 | AU6: 0 | AV6: 0 | AW6: 0 | AX6: 0 | AY6: 0 | AZ6: 0 | BA6: 0 | BB6: 0 | BC6: 0 | BD6: 0 | BE6: 0 | BF6: 0 | BG6: 0 | BH6: 0 | BI6: 0 | BJ6: 0 | BK6: 0 | BL6: 0 | BM6: 0 | BN6: 0 | BO6: 0 | BP6: 0 | BQ6: 0 | BR6: 0 | BS6: 0 | BT6: 0 | BU6: 0 | BV6: 0 | BW6: 0 | BX6: 0 | BY6: 0 | BZ6: 0 | CA6: 0 | CB6: 0 | CC6: 0 | CD6: 0 | CE6: 0 | CF6: 0 | CG6: 0 | CH6: 0 | CI6: 0 | CJ6: 0 | CK6: 0 | CL6: 0 | CM6: 0 | CN6: 0 | CO6: 0 | CP6: 0 | CQ6: 0 | CR6: 0 | CS6: 0 | CT6: 0 | CU6: 0 | CV6: 0 | CW6: 0 | CX6: 0 | CY6: 0 | CZ6: 0 | DA6: 0 | DB6: 0 | DC6: 0 | DD6: 0 | DE6: 0 | DF6: 0 | DG6: 0 | DH6: 0 | DI6: 0 | DJ6: 0 | DK6: 0 | DL6: 0 | DM6: 0 | DN6: 0 | DO6: 0 | DP6: 0 | DQ6: 0 | DR6: 0 | DS6: 0 | DT6: 0 | DU6: 0 | DV6: 0 | DW6: 0 | DX6: 0 | DY6: 0 | DZ6: 0 | EA6: 0 | EB6: 0 | EC6: 0 | ED6: 0 | EE6: 0 | EF6: 0 | EG6: 0 | EH6: 0 | EI6: 0 | EJ6: 0 | EK6: 0 | EL6: 0 | EM6: 0 | EN6: 0 | EO6: 0 | EP6: 0 | EQ6: 0 | ER6: 0 | ES6: 0 | ET6: 0 | EU6: 0 | EV6: 0 | EW6: 0 | EX6: 0 | EY6: 0 | EZ6: 0 | FA6: 0 | FB6: 0 | FC6: 0 | FD6: 0 | FE6: 0 | FF6: 0 | FG6: 0 | FH6: 0 | FI6: 0 | FJ6: 0 | FK6: 0 | FL6: 0 | FM6: 0 | FN6: 0 | FO6: 0 | FP6: 0 | FQ6: 0 | FR6: 0 | FS6: 0 | FT6: 0 | FU6: 0
A7: AWP | B7: Mortis MW | C7: AWP | D7: Clutch | E7: 3.23 | F7: 3.14 | G7: 3.5 | H7: 3.27 | I7: 3.28 | J7: 3.41 | K7: 3.47 | L7: 3.16 | M7: 3.26 | N7: 3.28 | O7: 3.29 | P7: 3.38 | Q7: 3.25 | R7: 3.26 | S7: 3.19 | T7: 3.39 | U7: 3.14 | V7: 3.14 | W7: 3.13 | X7: 2.92 | Y7: 3.15 | Z7: 0 | AA7: 0 | AB7: 0 | AC7: 0 | AD7: 0 | AE7: 0 | AF7: 0 | AG7: 0 | AH7: 0 | AI7: 0 | AJ7: 0 | AK7: 0 | AL7: 0 | AM7: 0 | AN7: 0 | AO7: 0 | AP7: 0 | AQ7: 0 | AR7: 0 | AS7: 0 | AT7: 0 | AU7: 0 | AV7: 0 | AW7: 0 | AX7: 0 | AY7: 0 | AZ7: 0 | BA7: 0 | BB7: 0 | BC7: 0 | BD7: 0 | BE7: 0 | BF7: 0 | BG7: 0 | BH7: 0 | BI7: 0 | BJ7: 0 | BK7: 0 | BL7: 0 | BM7: 0 | BN7: 0 | BO7: 0 | BP7: 0 | BQ7: 0 | BR7: 0 | BS7: 0 | BT7: 0 | BU7: 0 | BV7: 0 | BW7: 0 | BX7: 0 | BY7: 0 | BZ7: 0 | CA7: 0 | CB7: 0 | CC7: 0 | CD7: 0 | CE7: 0 | CF7: 0 | CG7: 0 | CH7: 0 | CI7: 0 | CJ7: 0 | CK7: 0 | CL7: 0 | CM7: 0 | CN7: 0 | CO7: 0 | CP7: 0 | CQ7: 0 | CR7: 0 | CS7: 0 | CT7: 0 | CU7: 0 | CV7: 0 | CW7: 0 | CX7: 0 | CY7: 0 | CZ7: 0 | DA7: 0 | DB7: 0 | DC7: 0 | DD7: 0 | DE7: 0 | DF7: 0 | DG7: 0 | DH7: 0 | DI7: 0 | DJ7: 0 | DK7: 0 | DL7: 0 | DM7: 0 | DN7: 0 | DO7: 0 | DP7: 0 | DQ7: 0 | DR7: 0 | DS7: 0 | DT7: 0 | DU7: 0 | DV7: 0 | DW7: 0 | DX7: 0 | DY7: 0 | DZ7: 0 | EA7: 0 | EB7: 0 | EC7: 0 | ED7: 0 | EE7: 0 | EF7: 0 | EG7: 0 | EH7: 0 | EI7: 0 | EJ7: 0 | EK7: 0 | EL7: 0 | EM7: 0 | EN7: 0 | EO7: 0 | EP7: 0 | EQ7: 0 | ER7: 0 | ES7: 0 | ET7: 0 | EU7: 0 | EV7: 0 | EW7: 0 | EX7: 0 | EY7: 0 | EZ7: 0 | FA7: 0 | FB7: 0 | FC7: 0 | FD7: 0 | FE7: 0 | FF7: 0 | FG7: 0 | FH7: 0 | FI7: 0 | FJ7: 0 | FK7: 0 | FL7: 0 | FM7: 0 | FN7: 0 | FO7: 0 | FP7: 0 | FQ7: 0 | FR7: 0 | FS7: 0 | FT7: 0 | FU7: 0
A8: AWP | B8: StatTrak Hyper Beast FT | C8: AWP | D8: Falchion | E8: 74.08 | F8: 71.31 | G8: 71.88 | H8: 71.23 | I8: 70.58 | J8: 65.36 | K8: 73.31 | L8: 73.31 | M8: 72.87 | N8: 84.58 | O8: 84.44 | P8: 75.84 | Q8: 76.16 | R8: 69.57 | S8: 74.78 | T8: 75.67 | U8: 83.34 | V8: 78.56 | W8: 78.23 | X8: 78.48 | Y8: 76.79 | Z8: 0 | AA8: 0 | AB8: 0 | AC8: 0 | AD8: 0 | AE8: 0 | AF8: 0 | AG8: 0 | AH8: 0 | AI8: 0 | AJ8: 0 | AK8: 0 | AL8: 0 | AM8: 0 | AN8: 0 | AO8: 0 | AP8: 0 | AQ8: 0 | AR8: 0 | AS8: 0 | AT8: 0 | AU8: 0 | AV8: 0 | AW8: 0 | AX8: 0 | AY8: 0 | AZ8: 0 | BA8: 0 | BB8: 0 | BC8: 0 | BD8: 0 | BE8: 0 | BF8: 0 | BG8: 0 | BH8: 0 | BI8: 0 | BJ8: 0 | BK8: 0 | BL8: 0 | BM8: 0 | BN8: 0 | BO8: 0 | BP8: 0 | BQ8: 0 | BR8: 0 | BS8: 0 | BT8: 0 | BU8: 0 | BV8: 0 | BW8: 0 | BX8: 0 | BY8: 0 | BZ8: 0 | CA8: 0 | CB8: 0 | CC8: 0 | CD8: 0 | CE8: 0 | CF8: 0 | CG8: 0 | CH8: 0 | CI8: 0 | CJ8: 0 | CK8: 0 | CL8: 0 | CM8: 0 | CN8: 0 | CO8: 0 | CP8: 0 | CQ8: 0 | CR8: 0 | CS8: 0 | CT8: 0 | CU8: 0 | CV8: 0 | CW8: 0 | CX8: 0 | CY8: 0 | CZ8: 0 | DA8: 0 | DB8: 0 | DC8: 0 | DD8: 0 | DE8: 0 | DF8: 0 | DG8: 0 | DH8: 0 | DI8: 0 | DJ8: 0 | DK8: 0 | DL8: 0 | DM8: 0 | DN8: 0 | DO8: 0 | DP8: 0 | DQ8: 0 | DR8: 0 | DS8: 0 | DT8: 0 | DU8: 0 | DV8: 0 | DW8: 0 | DX8: 0 | DY8: 0 | DZ8: 0 | EA8: 0 | EB8: 0 | EC8: 0 | ED8: 0 | EE8: 0 | EF8: 0 | EG8: 0 | EH8: 0 | EI8: 0 | EJ8: 0 | EK8: 0 | EL8: 0 | EM8: 0 | EN8: 0 | EO8: 0 | EP8: 0 | EQ8: 0 | ER8: 0 | ES8: 0 | ET8: 0 | EU8: 0 | EV8: 0 | EW8: 0 | EX8: 0 | EY8: 0 | EZ8: 0 | FA8: 0 | FB8: 0 | FC8: 0 | FD8: 0 | FE8: 0 | FF8: 0 | FG8: 0 | FH8: 0 | FI8: 0 | FJ8: 0 | FK8: 0 | FL8: 0 | FM8: 0 | FN8: 0 | FO8: 0 | FP8: 0 | FQ8: 0 | FR8: 0 | FS8: 0 | FT8: 0 | FU8: 0
A9: AWP | B9: Elite Build FT | C9: AWP | D9: Wildfire | E9: 6.81 | F9: 7.26 | G9: 7.22 | H9: 6.73 | I9: 6.71 | J9: 6.73 | K9: 6.97 | L9: 7.34 | M9: 7.18 | N9: 6.93 | O9: 6.5 | P9: 6.4 | Q9: 7.28 | R9: 7.32 | S9: 7.71 | T9: 7.27 | U9: 7.36 | V9: 7.14 | W9: 7.32 | X9: 7.2 | Y9: 7.6 | Z9: 0 | AA9: 0 | AB9: 0 | AC9: 0 | AD9: 0 | AE9: 0 | AF9: 0 | AG9: 0 | AH9: 0 | AI9: 0 | AJ9: 0 | AK9: 0 | AL9: 0 | AM9: 0 | AN9: 0 | AO9: 0 | AP9: 0 | AQ9: 0 | AR9: 0 | AS9: 0 | AT9: 0 | AU9: 0 | AV9: 0 | AW9: 0 | AX9: 0 | AY9: 0 | AZ9: 0 | BA9: 0 | BB9: 0 | BC9: 0 | BD9: 0 | BE9: 0 | BF9: 0 | BG9: 0 | BH9: 0 | BI9: 0 | BJ9: 0 | BK9: 0 | BL9: 0 | BM9: 0 | BN9: 0 | BO9: 0 | BP9: 0 | BQ9: 0 | BR9: 0 | BS9: 0 | BT9: 0 | BU9: 0 | BV9: 0 | BW9: 0 | BX9: 0 | BY9: 0 | BZ9: 0 | CA9: 0 | CB9: 0 | CC9: 0 | CD9: 0 | CE9: 0 | CF9: 0 | CG9: 0 | CH9: 0 | CI9: 0 | CJ9: 0 | CK9: 0 | CL9: 0 | CM9: 0 | CN9: 0 | CO9: 0 | CP9: 0 | CQ9: 0 | CR9: 0 | CS9: 0 | CT9: 0 | CU9: 0 | CV9: 0 | CW9: 0 | CX9: 0 | CY9: 0 | CZ9: 0 | DA9: 0 | DB9: 0 | DC9: 0 | DD9: 0 | DE9: 0 | DF9: 0 | DG9: 0 | DH9: 0 | DI9: 0 | DJ9: 0 | DK9: 0 | DL9: 0 | DM9: 0 | DN9: 0 | DO9: 0 | DP9: 0 | DQ9: 0 | DR9: 0 | DS9: 0 | DT9: 0 | DU9: 0 | DV9: 0 | DW9: 0 | DX9: 0 | DY9: 0 | DZ9: 0 | EA9: 0 | EB9: 0 | EC9: 0 | ED9: 0 | EE9: 0 | EF9: 0 | EG9: 0 | EH9: 0 | EI9: 0 | EJ9: 0 | EK9: 0 | EL9: 0 | EM9: 0 | EN9: 0 | EO9: 0 | EP9: 0 | EQ9: 0 | ER9: 0 | ES9: 0 | ET9: 0 | EU9: 0 | EV9: 0 | EW9: 0 | EX9: 0 | EY9: 0 | EZ9: 0 | FA9: 0 | FB9: 0 | FC9: 0 | FD9: 0 | FE9: 0 | FF9: 0 | FG9: 0 | FH9: 0 | FI9: 0 | FJ9: 0 | FK9: 0 | FL9: 0 | FM9: 0 | FN9: 0 | FO9: 0 | FP9: 0 | FQ9: 0 | FR9: 0 | FS9: 0 | FT9: 0 | FU9: 0
A10: AWP | B10: Fever Dream MW | C10: AWP | D10: Spectrum | E10: 7.47 | F10: 7.52 | G10: 7.36 | H10: 7.24 | I10: 7.42 | J10: 7.21 | K10: 7.03 | L10: 7.44 | M10: 7.33 | N10: 6.98 | O10: 6.95 | P10: 6.92 | Q10: 7.05 | R10: 6.62 | S10: 6.71 | T10: 7.14 | U10: 6.86 | V10: 7.3 | W10: 7.04 | X10: 6.9 | Y10: 7.02 | Z10: 0 | AA10: 0 | AB10: 0 | AC10: 0 | AD10: 0 | AE10: 0 | AF10: 0 | AG10: 0 | AH10: 0 | AI10: 0 | AJ10: 0 | AK10: 0 | AL10: 0 | AM10: 0 | AN10: 0 | AO10: 0 | AP10: 0 | AQ10: 0 | AR10: 0 | AS10: 0 | AT10: 0 | AU10: 0 | AV10: 0 | AW10: 0 | AX10: 0 | AY10: 0 | AZ10: 0 | BA10: 0 | BB10: 0 | BC10: 0 | BD10: 0 | BE10: 0 | BF10: 0 | BG10: 0 | BH10: 0 | BI10: 0 | BJ10: 0 | BK10: 0 | BL10: 0 | BM10: 0 | BN10: 0 | BO10: 0 | BP10: 0 | BQ10: 0 | BR10: 0 | BS10: 0 | BT10: 0 | BU10: 0 | BV10: 0 | BW10: 0 | BX10: 0 | BY10: 0 | BZ10: 0 | CA10: 0 | CB10: 0 | CC10: 0 | CD10: 0 | CE10: 0 | CF10: 0 | CG10: 0 | CH10: 0 | CI10: 0 | CJ10: 0 | CK10: 0 | CL10: 0 | CM10: 0 | CN10: 0 | CO10: 0 | CP10: 0 | CQ10: 0 | CR10: 0 | CS10: 0 | CT10: 0 | CU10: 0 | CV10: 0 | CW10: 0 | CX10: 0 | CY10: 0 | CZ10: 0 | DA10: 0 | DB10: 0 | DC10: 0 | DD10: 0 | DE10: 0 | DF10: 0 | DG10: 0 | DH10: 0 | DI10: 0 | DJ10: 0 | DK10: 0 | DL10: 0 | DM10: 0 | DN10: 0 | DO10: 0 | DP10: 0 | DQ10: 0 | DR10: 0 | DS10: 0 | DT10: 0 | DU10: 0 | DV10: 0 | DW10: 0 | DX10: 0 | DY10: 0 | DZ10: 0 | EA10: 0 | EB10: 0 | EC10: 0 | ED10: 0 | EE10: 0 | EF10: 0 | EG10: 0 | EH10: 0 | EI10: 0 | EJ10: 0 | EK10: 0 | EL10: 0 | EM10: 0 | EN10: 0 | EO10: 0 | EP10: 0 | EQ10: 0 | ER10: 0 | ES10: 0 | ET10: 0 | EU10: 0 | EV10: 0 | EW10: 0 | EX10: 0 | EY10: 0 | EZ10: 0 | FA10: 0 | FB10: 0 | FC10: 0 | FD10: 0 | FE10: 0 | FF10: 0 | FG10: 0 | FH10: 0 | FI10: 0 | FJ10: 0 | FK10: 0 | FL10: 0 | FM10: 0 | FN10: 0 | FO10: 0 | FP10: 0 | FQ10: 0 | FR10: 0 | FS10: 0 | FT10: 0 | FU10: 0
D13: Total | E13: =SUM(E4:E10) -> 195.47 | F13: =SUM(F4:F10) -> 190.54 | G13: =SUM(G4:G10) -> 199.99 | H13: =SUM(H4:H10) -> 193.31 | I13: =SUM(I4:I10) -> 193.19 | J13: =SUM(J4:J10) -> 185.44 | K13: =SUM(K4:K10) -> 198.11 | L13: =SUM(L4:L10) -> 199.2 | ... FU13: =SUM(FU4:FU10) -> 0
A18: =A3 -> Weapon | B18: =B3 -> Skin | C18: =C3 -> Type | D18: =D3 -> Collection | E18: =E3 -> 44331 | F18: =F3 -> 44332 | G18: =G3 -> 44334 | H18: =H3 -> 44336 | ... FU18: =FU3 -> 44505
A19: =A4 -> AWP | B19: =B4 -> Atheris MW | C19: =C4 -> AWP | D19: =D4 -> Prisma | E19: =E4-ROUNDUP(E4*0.3,2) -> 3.01 | F19: =F4-ROUNDUP(F4*0.3,2) -> 3.17 | G19: =G4-ROUNDUP(G4*0.3,2) -> 3.05 | H19: =H4-ROUNDUP(H4*0.3,2) -> 3.08 | I19: =I4-ROUNDUP(I4*0.3,2) -> 2.91 | J19: =J4-ROUNDUP(J4*0.3,2) -> 3.08 | K19: =K4-ROUNDUP(K4*0.3,2) -> 3.31 | L19: =L4-ROUNDUP(L4*0.3,2) -> 3.28 | ... FU19: =FU4-ROUNDUP(FU4*0.3,2) -> 0
A20: =A5 -> AWP | B20: =B5 -> Neo-Noir FN | C20: =C5 -> AWP | D20: =D5 -> Danger Zone | E20: =E5-ROUNDUP(E5*0.3,2) -> 32.9 | F20: =F5-ROUNDUP(F5*0.3,2) -> 32.15 | G20: =G5-ROUNDUP(G5*0.3,2) -> 31.17 | H20: =H5-ROUNDUP(H5*0.3,2) -> 31.85 | I20: =I5-ROUNDUP(I5*0.3,2) -> 32.23 | J20: =J5-ROUNDUP(J5*0.3,2) -> 32.25 | K20: =K5-ROUNDUP(K5*0.3,2) -> 32.59 | L20: =L5-ROUNDUP(L5*0.3,2) -> 33.38 | ... FU20: =FU5-ROUNDUP(FU5*0.3,2) -> 0
A21: =A6 -> AWP | B21: =B6 -> Boom MW | C21: =C6 -> AWP | D21: =D6 -> eSports 2013 | E21: =E6-ROUNDUP(E6*0.3,2) -> 36.79 | F21: =F6-ROUNDUP(F6*0.3,2) -> 35.58 | G21: =G6-ROUNDUP(G6*0.3,2) -> 42.78 | H21: =H6-ROUNDUP(H6*0.3,2) -> 38.44 | I21: =I6-ROUNDUP(I6*0.3,2) -> 38.49 | J21: =J6-ROUNDUP(J6*0.3,2) -> 36.57 | K21: =K6-ROUNDUP(K6*0.3,2) -> 39.22 | L21: =L6-ROUNDUP(L6*0.3,2) -> 38.89 | ... FU21: =FU6-ROUNDUP(FU6*0.3,2) -> 0
A22: =A7 -> AWP | B22: =B7 -> Mortis MW | C22: =C7 -> AWP | D22: =D7 -> Clutch | E22: =E7-ROUNDUP(E7*0.3,2) -> 2.26 | F22: =F7-ROUNDUP(F7*0.3,2) -> 2.19 | G22: =G7-ROUNDUP(G7*0.3,2) -> 2.45 | H22: =H7-ROUNDUP(H7*0.3,2) -> 2.28 | I22: =I7-ROUNDUP(I7*0.3,2) -> 2.29 | J22: =J7-ROUNDUP(J7*0.3,2) -> 2.38 | K22: =K7-ROUNDUP(K7*0.3,2) -> 2.42 | L22: =L7-ROUNDUP(L7*0.3,2) -> 2.21 | ... FU22: =FU7-ROUNDUP(FU7*0.3,2) -> 0
A23: =A8 -> AWP | B23: =B8 -> StatTrak Hyper Beast FT | C23: =C8 -> AWP | D23: =D8 -> Falchion | E23: =E8-ROUNDUP(E8*0.3,2) -> 51.85 | F23: =F8-ROUNDUP(F8*0.3,2) -> 49.91 | G23: =G8-ROUNDUP(G8*0.3,2) -> 50.31 | H23: =H8-ROUNDUP(H8*0.3,2) -> 49.86 | I23: =I8-ROUNDUP(I8*0.3,2) -> 49.4 | J23: =J8-ROUNDUP(J8*0.3,2) -> 45.75 | K23: =K8-ROUNDUP(K8*0.3,2) -> 51.31 | L23: =L8-ROUNDUP(L8*0.3,2) -> 51.31 | ... FU23: =FU8-ROUNDUP(FU8*0.3,2) -> 0
A24: =A9 -> AWP | B24: =B9 -> Elite Build FT | C24: =C9 -> AWP | D24: =D9 -> Wildfire | E24: =E9-ROUNDUP(E9*0.3,2) -> 4.76 | F24: =F9-ROUNDUP(F9*0.3,2) -> 5.08 | G24: =G9-ROUNDUP(G9*0.3,2) -> 5.05 | H24: =H9-ROUNDUP(H9*0.3,2) -> 4.71 | I24: =I9-ROUNDUP(I9*0.3,2) -> 4.69 | J24: =J9-ROUNDUP(J9*0.3,2) -> 4.71 | K24: =K9-ROUNDUP(K9*0.3,2) -> 4.87 | L24: =L9-ROUNDUP(L9*0.3,2) -> 5.13 | ... FU24: =FU9-ROUNDUP(FU9*0.3,2) -> 0
A25: =A10 -> AWP | B25: =B10 -> Fever Dream MW | C25: =C10 -> AWP | D25: =D10 -> Spectrum | E25: =E10-ROUNDUP(E10*0.3,2) -> 5.22 | F25: =F10-ROUNDUP(F10*0.3,2) -> 5.26 | G25: =G10-ROUNDUP(G10*0.3,2) -> 5.15 | H25: =H10-ROUNDUP(H10*0.3,2) -> 5.06 | I25: =I10-ROUNDUP(I10*0.3,2) -> 5.19 | J25: =J10-ROUNDUP(J10*0.3,2) -> 5.04 | K25: =K10-ROUNDUP(K10*0.3,2) -> 4.92 | L25: =L10-ROUNDUP(L10*0.3,2) -> 5.2 | ... FU25: =FU10-ROUNDUP(FU10*0.3,2) -> 0
D28: Total | E28: =SUM(E19:E25) -> 136.79 | F28: =SUM(F19:F25) -> 133.34 | G28: =SUM(G19:G25) -> 139.96 | H28: =SUM(H19:H25) -> 135.28 | I28: =SUM(I19:I25) -> 135.2 | J28: =SUM(J19:J25) -> 129.78 | K28: =SUM(K19:K25) -> 138.64 | L28: =SUM(L19:L25) -> 139.4 | ... FU28: =SUM(FU19:FU25) -> 0

Sheet AK-47
B1: AK-47
A3: Weapon | B3: Skin | C3: Type | D3: Collection | E3: =Inventory!E1 -> 44331 | F3: =Inventory!F1 -> 44332 | G3: =Inventory!G1 -> 44334 | H3: =Inventory!H1 -> 44336 | I3: =Inventory!I1 -> 44337 | J3: =Inventory!J1 -> 44338 | K3: =Inventory!K1 -> 44339 | L3: =Inventory!L1 -> 44340 | ... FU3: =Inventory!FU1 -> 44505
A4: {=_xlfn._xlws.FILTER(Inventory!$A$2:$FU$103, (Inventory!C2:C103="AK-47"))} -> AK-47 | B4: Aquamarine Revenge MW | C4: AK-47 | D4: Falchion | E4: 47.51 | F4: 47.17 | G4: 49.37 | H4: 48.37 | I4: 46.08 | J4: 44.96 | K4: 46.07 | L4: 45.89 | M4: 44.94 | N4: 45.49 | O4: 46.09 | P4: 45.74 | Q4: 45.73 | R4: 44.74 | S4: 44.91 | T4: 46.13 | U4: 46.46 | V4: 45.58 | W4: 45.39 | X4: 43.55 | Y4: 46.01 | Z4: 0 | AA4: 0 | AB4: 0 | AC4: 0 | AD4: 0 | AE4: 0 | AF4: 0 | AG4: 0 | AH4: 0 | AI4: 0 | AJ4: 0 | AK4: 0 | AL4: 0 | AM4: 0 | AN4: 0 | AO4: 0 | AP4: 0 | AQ4: 0 | AR4: 0 | AS4: 0 | AT4: 0 | AU4: 0 | AV4: 0 | AW4: 0 | AX4: 0 | AY4: 0 | AZ4: 0 | BA4: 0 | BB4: 0 | BC4: 0 | BD4: 0 | BE4: 0 | BF4: 0 | BG4: 0 | BH4: 0 | BI4: 0 | BJ4: 0 | BK4: 0 | BL4: 0 | BM4: 0 | BN4: 0 | BO4: 0 | BP4: 0 | BQ4: 0 | BR4: 0 | BS4: 0 | BT4: 0 | BU4: 0 | BV4: 0 | BW4: 0 | BX4: 0 | BY4: 0 | BZ4: 0 | CA4: 0 | CB4: 0 | CC4: 0 | CD4: 0 | CE4: 0 | CF4: 0 | CG4: 0 | CH4: 0 | CI4: 0 | CJ4: 0 | CK4: 0 | CL4: 0 | CM4: 0 | CN4: 0 | CO4: 0 | CP4: 0 | CQ4: 0 | CR4: 0 | CS4: 0 | CT4: 0 | CU4: 0 | CV4: 0 | CW4: 0 | CX4: 0 | CY4: 0 | CZ4: 0 | DA4: 0 | DB4: 0 | DC4: 0 | DD4: 0 | DE4: 0 | DF4: 0 | DG4: 0 | DH4: 0 | DI4: 0 | DJ4: 0 | DK4: 0 | DL4: 0 | DM4: 0 | DN4: 0 | DO4: 0 | DP4: 0 | DQ4: 0 | DR4: 0 | DS4: 0 | DT4: 0 | DU4: 0 | DV4: 0 | DW4: 0 | DX4: 0 | DY4: 0 | DZ4: 0 | EA4: 0 | EB4: 0 | EC4: 0 | ED4: 0 | EE4: 0 | EF4: 0 | EG4: 0 | EH4: 0 | EI4: 0 | EJ4: 0 | EK4: 0 | EL4: 0 | EM4: 0 | EN4: 0 | EO4: 0 | EP4: 0 | EQ4: 0 | ER4: 0 | ES4: 0 | ET4: 0 | EU4: 0 | EV4: 0 | EW4: 0 | EX4: 0 | EY4: 0 | EZ4: 0 | FA4: 0 | FB4: 0 | FC4: 0 | FD4: 0 | FE4: 0 | FF4: 0 | FG4: 0 | FH4: 0 | FI4: 0 | FJ4: 0 | FK4: 0 | FL4: 0 | FM4: 0 | FN4: 0 | FO4: 0 | FP4: 0 | FQ4: 0 | FR4: 0 | FS4: 0 | FT4: 0 | FU4: 0
